<?xml version="1.0" ?>
<robot name="mano">
  <link name="link0">
    <inertial>
      <origin xyz="0 0 0" rpy="0 0 0"/>
      <mass value="0"/>
      <inertia ixx="0" ixy="0" ixz="0" iyy="0" iyz="0" izz="0"/>
    </inertial>
  </link>
  <link name="link1">
    <inertial>
      <origin xyz="0 0 0" rpy="0 0 0"/>
      <mass value="0"/>
      <inertia ixx="0" ixy="0" ixz="0" iyy="0" iyz="0" izz="0"/>
    </inertial>
  </link>
  <joint name="joint1" type="prismatic">
    <origin xyz="0 0 0" rpy="0 0 0"/>
    <parent link="link0"/>
    <child link="link1"/>
    <axis xyz="1 0 0"/>
    <limit lower="-1000" upper="1000"/>
  </joint>
  <link name="link2">
    <inertial>
      <origin xyz="0 0 0" rpy="0 0 0"/>
      <mass value="0"/>
      <inertia ixx="0" ixy="0" ixz="0" iyy="0" iyz="0" izz="0"/>
    </inertial>
  </link>
  <joint name="joint2" type="prismatic">
    <origin xyz="0 0 0" rpy="0 0 0"/>
    <parent link="link1"/>
    <child link="link2"/>
    <axis xyz="0 1 0"/>
    <limit lower="-1000" upper="1000"/>
  </joint>
  <link name="link3">
    <inertial>
      <origin xyz="0 0 0" rpy="0 0 0"/>
      <mass value="0"/>
      <inertia ixx="0" ixy="0" ixz="0" iyy="0" iyz="0" izz="0"/>
    </inertial>
  </link>
  <joint name="joint3" type="prismatic">
    <origin xyz="0 0 0" rpy="0 0 0"/>
    <parent link="link2"/>
    <child link="link3"/>
    <axis xyz="0 0 1"/>
    <limit lower="-1000" upper="1000"/>
  </joint>
  <link name="link4">
    <inertial>
      <origin xyz="0 0 0" rpy="0 0 0"/>
      <mass value="0"/>
      <inertia ixx="0" ixy="0" ixz="0" iyy="0" iyz="0" izz="0"/>
    </inertial>
  </link>
  <joint name="joint4" type="continuous">
    <origin xyz="0 0 0" rpy="0 0 0"/>
    <parent link="link3"/>
    <child link="link4"/>
    <axis xyz="1 0 0"/>
    <limit lower="1" upper="-1"/>
  </joint>
  <link name="link5">
    <inertial>
      <origin xyz="0 0 0" rpy="0 0 0"/>
      <mass value="0"/>
      <inertia ixx="0" ixy="0" ixz="0" iyy="0" iyz="0" izz="0"/>
    </inertial>
  </link>
  <joint name="joint5" type="continuous">
    <origin xyz="0 0 0" rpy="0 0 0"/>
    <parent link="link4"/>
    <child link="link5"/>
    <axis xyz="0 1 0"/>
    <limit lower="1" upper="-1"/>
  </joint>
  <link name="link6">
    <inertial>
      <origin xyz="0 0 0" rpy="0 0 0"/>
      <mass value="0"/>
      <inertia ixx="0" ixy="0" ixz="0" iyy="0" iyz="0" izz="0"/>
    </inertial>
  </link>
  <joint name="joint6" type="continuous">
    <origin xyz="0 0 0" rpy="0 0 0"/>
    <parent link="link5"/>
    <child link="link6"/>
    <axis xyz="0 0 1"/>
    <limit lower="1" upper="-1"/>
  </joint>
  <link name="link7">
    <inertial>
      <origin xyz="0 0 0" rpy="0 0 0"/>
      <mass value="0.2000000000000000111022302462515654042363166809082031250000000000"/>
      <inertia ixx="1" ixy="0" ixz="0" iyy="1" iyz="0" izz="1"/>
    </inertial>
    <visual>
      <origin xyz="0 0 0" rpy="0 0 0"/>
      <geometry>
        <mesh filename="meshes/visual/mesh1.obj"/>
      </geometry>
    </visual>
    <collision>
      <origin xyz="0 0 0" rpy="0 0 0"/>
      <geometry>
        <mesh filename="meshes/collision/mesh1.obj"/>
      </geometry>
    </collision>
  </link>
  <joint name="joint7" type="fixed">
    <origin xyz="-0.0980623939220629653457095287194533739238977432250976562500000000 0.0061965477104050691384284910157020931364968419075012207031250000 0.0060848766582183837908770485114473558496683835983276367187500000" rpy="0 0 0"/>
    <parent link="link6"/>
    <child link="link7"/>
    <axis xyz="0 0 0"/>
    <limit lower="1" upper="-1"/>
  </joint>
  <link name="link8">
    <inertial>
      <origin xyz="0 0 0" rpy="0 0 0"/>
      <mass value="0"/>
      <inertia ixx="0" ixy="0" ixz="0" iyy="0" iyz="0" izz="0"/>
    </inertial>
  </link>
  <joint name="joint8" type="revolute">
    <origin xyz="0.0906996369414464209679493933435878716409206390380859375000000000 -0.0050750678182457237275215788940840866416692733764648437500000000 0.0193252454950966004454393498690478736534714698791503906250000000" rpy="0 0 0"/>
    <parent link="link7"/>
    <child link="link8"/>
    <axis xyz="1 0 0"/>
    <limit lower="-3.1415926535897931159979634685441851615905761718750000000000000000" upper="3.1415926535897931159979634685441851615905761718750000000000000000"/>
  </joint>
  <link name="link9">
    <inertial>
      <origin xyz="0 0 0" rpy="0 0 0"/>
      <mass value="0"/>
      <inertia ixx="0" ixy="0" ixz="0" iyy="0" iyz="0" izz="0"/>
    </inertial>
  </link>
  <joint name="joint9" type="revolute">
    <origin xyz="0 0 0" rpy="0 0 0"/>
    <parent link="link8"/>
    <child link="link9"/>
    <axis xyz="0 1 0"/>
    <limit lower="-1.5707963267948965579989817342720925807952880859375000000000000000" upper="1.5707963267948965579989817342720925807952880859375000000000000000"/>
  </joint>
  <link name="link10">
    <inertial>
      <origin xyz="0 0 0" rpy="0 0 0"/>
      <mass value="0.0200000000000000004163336342344337026588618755340576171875000000"/>
      <inertia ixx="1" ixy="0" ixz="0" iyy="1" iyz="0" izz="1"/>
    </inertial>
    <visual>
      <origin xyz="0 0 0" rpy="0 0 0"/>
      <geometry>
        <mesh filename="meshes/visual/mesh2.obj"/>
      </geometry>
    </visual>
    <collision>
      <origin xyz="0 0 0" rpy="0 0 0"/>
      <geometry>
        <mesh filename="meshes/collision/mesh2.obj"/>
      </geometry>
    </collision>
  </link>
  <joint name="joint10" type="revolute">
    <origin xyz="0 0 0" rpy="0 0 0"/>
    <parent link="link9"/>
    <child link="link10"/>
    <axis xyz="0 0 1"/>
    <limit lower="-3.1415926535897931159979634685441851615905761718750000000000000000" upper="3.1415926535897931159979634685441851615905761718750000000000000000"/>
  </joint>
  <link name="link11">
    <inertial>
      <origin xyz="0 0 0" rpy="0 0 0"/>
      <mass value="0"/>
      <inertia ixx="0" ixy="0" ixz="0" iyy="0" iyz="0" izz="0"/>
    </inertial>
  </link>
  <joint name="joint11" type="revolute">
    <origin xyz="0.0331278465288970952462577201913518365472555160522460937500000000 0.0042443394068741382985088250734406756237149238586425781250000000 0.0019356922108985132047198618465699837543070316314697265625000000" rpy="0 0 0"/>
    <parent link="link10"/>
    <child link="link11"/>
    <axis xyz="1 0 0"/>
    <limit lower="-3.1415926535897931159979634685441851615905761718750000000000000000" upper="3.1415926535897931159979634685441851615905761718750000000000000000"/>
  </joint>
  <link name="link12">
    <inertial>
      <origin xyz="0 0 0" rpy="0 0 0"/>
      <mass value="0"/>
      <inertia ixx="0" ixy="0" ixz="0" iyy="0" iyz="0" izz="0"/>
    </inertial>
  </link>
  <joint name="joint12" type="revolute">
    <origin xyz="0 0 0" rpy="0 0 0"/>
    <parent link="link11"/>
    <child link="link12"/>
    <axis xyz="0 1 0"/>
    <limit lower="-1.5707963267948965579989817342720925807952880859375000000000000000" upper="1.5707963267948965579989817342720925807952880859375000000000000000"/>
  </joint>
  <link name="link13">
    <inertial>
      <origin xyz="0 0 0" rpy="0 0 0"/>
      <mass value="0.0200000000000000004163336342344337026588618755340576171875000000"/>
      <inertia ixx="1" ixy="0" ixz="0" iyy="1" iyz="0" izz="1"/>
    </inertial>
    <visual>
      <origin xyz="0 0 0" rpy="0 0 0"/>
      <geometry>
        <mesh filename="meshes/visual/mesh3.obj"/>
      </geometry>
    </visual>
    <collision>
      <origin xyz="0 0 0" rpy="0 0 0"/>
      <geometry>
        <mesh filename="meshes/collision/mesh3.obj"/>
      </geometry>
    </collision>
  </link>
  <joint name="joint13" type="revolute">
    <origin xyz="0 0 0" rpy="0 0 0"/>
    <parent link="link12"/>
    <child link="link13"/>
    <axis xyz="0 0 1"/>
    <limit lower="-3.1415926535897931159979634685441851615905761718750000000000000000" upper="3.1415926535897931159979634685441851615905761718750000000000000000"/>
  </joint>
  <link name="link14">
    <inertial>
      <origin xyz="0 0 0" rpy="0 0 0"/>
      <mass value="0"/>
      <inertia ixx="0" ixy="0" ixz="0" iyy="0" iyz="0" izz="0"/>
    </inertial>
  </link>
  <joint name="joint14" type="revolute">
    <origin xyz="0.0224189596729397408458872575920395320281386375427246093750000000 -0.0012283115248224504151286495812200882937759160995483398437500000 -0.0002027883452755223359087466405981103889644145965576171875000000" rpy="0 0 0"/>
    <parent link="link13"/>
    <child link="link14"/>
    <axis xyz="1 0 0"/>
    <limit lower="-3.1415926535897931159979634685441851615905761718750000000000000000" upper="3.1415926535897931159979634685441851615905761718750000000000000000"/>
  </joint>
  <link name="link15">
    <inertial>
      <origin xyz="0 0 0" rpy="0 0 0"/>
      <mass value="0"/>
      <inertia ixx="0" ixy="0" ixz="0" iyy="0" iyz="0" izz="0"/>
    </inertial>
  </link>
  <joint name="joint15" type="revolute">
    <origin xyz="0 0 0" rpy="0 0 0"/>
    <parent link="link14"/>
    <child link="link15"/>
    <axis xyz="0 1 0"/>
    <limit lower="-1.5707963267948965579989817342720925807952880859375000000000000000" upper="1.5707963267948965579989817342720925807952880859375000000000000000"/>
  </joint>
  <link name="link16">
    <inertial>
      <origin xyz="0 0 0" rpy="0 0 0"/>
      <mass value="0.0200000000000000004163336342344337026588618755340576171875000000"/>
      <inertia ixx="1" ixy="0" ixz="0" iyy="1" iyz="0" izz="1"/>
    </inertial>
    <visual>
      <origin xyz="0 0 0" rpy="0 0 0"/>
      <geometry>
        <mesh filename="meshes/visual/mesh4.obj"/>
      </geometry>
    </visual>
    <collision>
      <origin xyz="0 0 0" rpy="0 0 0"/>
      <geometry>
        <mesh filename="meshes/collision/mesh4.obj"/>
      </geometry>
    </collision>
  </link>
  <joint name="joint16" type="revolute">
    <origin xyz="0 0 0" rpy="0 0 0"/>
    <parent link="link15"/>
    <child link="link16"/>
    <axis xyz="0 0 1"/>
    <limit lower="-3.1415926535897931159979634685441851615905761718750000000000000000" upper="3.1415926535897931159979634685441851615905761718750000000000000000"/>
  </joint>
  <link name="link17">
    <inertial>
      <origin xyz="0 0 0" rpy="0 0 0"/>
      <mass value="0"/>
      <inertia ixx="0" ixy="0" ixz="0" iyy="0" iyz="0" izz="0"/>
    </inertial>
  </link>
  <joint name="joint17" type="revolute">
    <origin xyz="0.0976168630331473718975132669584127143025398254394531250000000000 -0.0018678051606065030829095796605088253272697329521179199218750000 -0.0033335833430483017766898790057439327938482165336608886718750000" rpy="0 0 0"/>
    <parent link="link7"/>
    <child link="link17"/>
    <axis xyz="1 0 0"/>
    <limit lower="-3.1415926535897931159979634685441851615905761718750000000000000000" upper="3.1415926535897931159979634685441851615905761718750000000000000000"/>
  </joint>
  <link name="link18">
    <inertial>
      <origin xyz="0 0 0" rpy="0 0 0"/>
      <mass value="0"/>
      <inertia ixx="0" ixy="0" ixz="0" iyy="0" iyz="0" izz="0"/>
    </inertial>
  </link>
  <joint name="joint18" type="revolute">
    <origin xyz="0 0 0" rpy="0 0 0"/>
    <parent link="link17"/>
    <child link="link18"/>
    <axis xyz="0 1 0"/>
    <limit lower="-1.5707963267948965579989817342720925807952880859375000000000000000" upper="1.5707963267948965579989817342720925807952880859375000000000000000"/>
  </joint>
  <link name="link19">
    <inertial>
      <origin xyz="0 0 0" rpy="0 0 0"/>
      <mass value="0.0200000000000000004163336342344337026588618755340576171875000000"/>
      <inertia ixx="1" ixy="0" ixz="0" iyy="1" iyz="0" izz="1"/>
    </inertial>
    <visual>
      <origin xyz="0 0 0" rpy="0 0 0"/>
      <geometry>
        <mesh filename="meshes/visual/mesh5.obj"/>
      </geometry>
    </visual>
    <collision>
      <origin xyz="0 0 0" rpy="0 0 0"/>
      <geometry>
        <mesh filename="meshes/collision/mesh5.obj"/>
      </geometry>
    </collision>
  </link>
  <joint name="joint19" type="revolute">
    <origin xyz="0 0 0" rpy="0 0 0"/>
    <parent link="link18"/>
    <child link="link19"/>
    <axis xyz="0 0 1"/>
    <limit lower="-3.1415926535897931159979634685441851615905761718750000000000000000" upper="3.1415926535897931159979634685441851615905761718750000000000000000"/>
  </joint>
  <link name="link20">
    <inertial>
      <origin xyz="0 0 0" rpy="0 0 0"/>
      <mass value="0"/>
      <inertia ixx="0" ixy="0" ixz="0" iyy="0" iyz="0" izz="0"/>
    </inertial>
  </link>
  <joint name="joint20" type="revolute">
    <origin xyz="0.0318132753693372433145825084466196130961179733276367187500000000 0.0017704047906647452093054084798495750874280929565429687500000000 -0.0056377406573238694059702069694139936473220586776733398437500000" rpy="0 0 0"/>
    <parent link="link19"/>
    <child link="link20"/>
    <axis xyz="1 0 0"/>
    <limit lower="-3.1415926535897931159979634685441851615905761718750000000000000000" upper="3.1415926535897931159979634685441851615905761718750000000000000000"/>
  </joint>
  <link name="link21">
    <inertial>
      <origin xyz="0 0 0" rpy="0 0 0"/>
      <mass value="0"/>
      <inertia ixx="0" ixy="0" ixz="0" iyy="0" iyz="0" izz="0"/>
    </inertial>
  </link>
  <joint name="joint21" type="revolute">
    <origin xyz="0 0 0" rpy="0 0 0"/>
    <parent link="link20"/>
    <child link="link21"/>
    <axis xyz="0 1 0"/>
    <limit lower="-1.5707963267948965579989817342720925807952880859375000000000000000" upper="1.5707963267948965579989817342720925807952880859375000000000000000"/>
  </joint>
  <link name="link22">
    <inertial>
      <origin xyz="0 0 0" rpy="0 0 0"/>
      <mass value="0.0200000000000000004163336342344337026588618755340576171875000000"/>
      <inertia ixx="1" ixy="0" ixz="0" iyy="1" iyz="0" izz="1"/>
    </inertial>
    <visual>
      <origin xyz="0 0 0" rpy="0 0 0"/>
      <geometry>
        <mesh filename="meshes/visual/mesh6.obj"/>
      </geometry>
    </visual>
    <collision>
      <origin xyz="0 0 0" rpy="0 0 0"/>
      <geometry>
        <mesh filename="meshes/collision/mesh6.obj"/>
      </geometry>
    </collision>
  </link>
  <joint name="joint22" type="revolute">
    <origin xyz="0 0 0" rpy="0 0 0"/>
    <parent link="link21"/>
    <child link="link22"/>
    <axis xyz="0 0 1"/>
    <limit lower="-3.1415926535897931159979634685441851615905761718750000000000000000" upper="3.1415926535897931159979634685441851615905761718750000000000000000"/>
  </joint>
  <link name="link23">
    <inertial>
      <origin xyz="0 0 0" rpy="0 0 0"/>
      <mass value="0"/>
      <inertia ixx="0" ixy="0" ixz="0" iyy="0" iyz="0" izz="0"/>
    </inertial>
  </link>
  <joint name="joint23" type="revolute">
    <origin xyz="0.0232983031827863895646402170314104296267032623291015625000000000 -0.0012037401967921017298390751193437608890235424041748046875000000 -0.0038823890249591644883986329972458406700752675533294677734375000" rpy="0 0 0"/>
    <parent link="link22"/>
    <child link="link23"/>
    <axis xyz="1 0 0"/>
    <limit lower="-3.1415926535897931159979634685441851615905761718750000000000000000" upper="3.1415926535897931159979634685441851615905761718750000000000000000"/>
  </joint>
  <link name="link24">
    <inertial>
      <origin xyz="0 0 0" rpy="0 0 0"/>
      <mass value="0"/>
      <inertia ixx="0" ixy="0" ixz="0" iyy="0" iyz="0" izz="0"/>
    </inertial>
  </link>
  <joint name="joint24" type="revolute">
    <origin xyz="0 0 0" rpy="0 0 0"/>
    <parent link="link23"/>
    <child link="link24"/>
    <axis xyz="0 1 0"/>
    <limit lower="-1.5707963267948965579989817342720925807952880859375000000000000000" upper="1.5707963267948965579989817342720925807952880859375000000000000000"/>
  </joint>
  <link name="link25">
    <inertial>
      <origin xyz="0 0 0" rpy="0 0 0"/>
      <mass value="0.0200000000000000004163336342344337026588618755340576171875000000"/>
      <inertia ixx="1" ixy="0" ixz="0" iyy="1" iyz="0" izz="1"/>
    </inertial>
    <visual>
      <origin xyz="0 0 0" rpy="0 0 0"/>
      <geometry>
        <mesh filename="meshes/visual/mesh7.obj"/>
      </geometry>
    </visual>
    <collision>
      <origin xyz="0 0 0" rpy="0 0 0"/>
      <geometry>
        <mesh filename="meshes/collision/mesh7.obj"/>
      </geometry>
    </collision>
  </link>
  <joint name="joint25" type="revolute">
    <origin xyz="0 0 0" rpy="0 0 0"/>
    <parent link="link24"/>
    <child link="link25"/>
    <axis xyz="0 0 1"/>
    <limit lower="-3.1415926535897931159979634685441851615905761718750000000000000000" upper="3.1415926535897931159979634685441851615905761718750000000000000000"/>
  </joint>
  <link name="link26">
    <inertial>
      <origin xyz="0 0 0" rpy="0 0 0"/>
      <mass value="0"/>
      <inertia ixx="0" ixy="0" ixz="0" iyy="0" iyz="0" izz="0"/>
    </inertial>
  </link>
  <joint name="joint26" type="revolute">
    <origin xyz="0.0705229196209569836328867609154258389025926589965820312500000000 -0.0093694395399485028153030441444570897147059440612792968750000000 -0.0405877193084408574574872829998639645054936408996582031250000000" rpy="0 0 0"/>
    <parent link="link7"/>
    <child link="link26"/>
    <axis xyz="1 0 0"/>
    <limit lower="-3.1415926535897931159979634685441851615905761718750000000000000000" upper="3.1415926535897931159979634685441851615905761718750000000000000000"/>
  </joint>
  <link name="link27">
    <inertial>
      <origin xyz="0 0 0" rpy="0 0 0"/>
      <mass value="0"/>
      <inertia ixx="0" ixy="0" ixz="0" iyy="0" iyz="0" izz="0"/>
    </inertial>
  </link>
  <joint name="joint27" type="revolute">
    <origin xyz="0 0 0" rpy="0 0 0"/>
    <parent link="link26"/>
    <child link="link27"/>
    <axis xyz="0 1 0"/>
    <limit lower="-1.5707963267948965579989817342720925807952880859375000000000000000" upper="1.5707963267948965579989817342720925807952880859375000000000000000"/>
  </joint>
  <link name="link28">
    <inertial>
      <origin xyz="0 0 0" rpy="0 0 0"/>
      <mass value="0.0200000000000000004163336342344337026588618755340576171875000000"/>
      <inertia ixx="1" ixy="0" ixz="0" iyy="1" iyz="0" izz="1"/>
    </inertial>
    <visual>
      <origin xyz="0 0 0" rpy="0 0 0"/>
      <geometry>
        <mesh filename="meshes/visual/mesh8.obj"/>
      </geometry>
    </visual>
    <collision>
      <origin xyz="0 0 0" rpy="0 0 0"/>
      <geometry>
        <mesh filename="meshes/collision/mesh8.obj"/>
      </geometry>
    </collision>
  </link>
  <joint name="joint28" type="revolute">
    <origin xyz="0 0 0" rpy="0 0 0"/>
    <parent link="link27"/>
    <child link="link28"/>
    <axis xyz="0 0 1"/>
    <limit lower="-3.1415926535897931159979634685441851615905761718750000000000000000" upper="3.1415926535897931159979634685441851615905761718750000000000000000"/>
  </joint>
  <link name="link29">
    <inertial>
      <origin xyz="0 0 0" rpy="0 0 0"/>
      <mass value="0"/>
      <inertia ixx="0" ixy="0" ixz="0" iyy="0" iyz="0" izz="0"/>
    </inertial>
  </link>
  <joint name="joint29" type="revolute">
    <origin xyz="0.0177590044656027040703705210944463033229112625122070312500000000 0.0004381774958510074868822670168810873292386531829833984375000000 -0.0123536820515887865723492211600387236103415489196777343750000000" rpy="0 0 0"/>
    <parent link="link28"/>
    <child link="link29"/>
    <axis xyz="1 0 0"/>
    <limit lower="-3.1415926535897931159979634685441851615905761718750000000000000000" upper="3.1415926535897931159979634685441851615905761718750000000000000000"/>
  </joint>
  <link name="link30">
    <inertial>
      <origin xyz="0 0 0" rpy="0 0 0"/>
      <mass value="0"/>
      <inertia ixx="0" ixy="0" ixz="0" iyy="0" iyz="0" izz="0"/>
    </inertial>
  </link>
  <joint name="joint30" type="revolute">
    <origin xyz="0 0 0" rpy="0 0 0"/>
    <parent link="link29"/>
    <child link="link30"/>
    <axis xyz="0 1 0"/>
    <limit lower="-1.5707963267948965579989817342720925807952880859375000000000000000" upper="1.5707963267948965579989817342720925807952880859375000000000000000"/>
  </joint>
  <link name="link31">
    <inertial>
      <origin xyz="0 0 0" rpy="0 0 0"/>
      <mass value="0.0200000000000000004163336342344337026588618755340576171875000000"/>
      <inertia ixx="1" ixy="0" ixz="0" iyy="1" iyz="0" izz="1"/>
    </inertial>
    <visual>
      <origin xyz="0 0 0" rpy="0 0 0"/>
      <geometry>
        <mesh filename="meshes/visual/mesh9.obj"/>
      </geometry>
    </visual>
    <collision>
      <origin xyz="0 0 0" rpy="0 0 0"/>
      <geometry>
        <mesh filename="meshes/collision/mesh9.obj"/>
      </geometry>
    </collision>
  </link>
  <joint name="joint31" type="revolute">
    <origin xyz="0 0 0" rpy="0 0 0"/>
    <parent link="link30"/>
    <child link="link31"/>
    <axis xyz="0 0 1"/>
    <limit lower="-3.1415926535897931159979634685441851615905761718750000000000000000" upper="3.1415926535897931159979634685441851615905761718750000000000000000"/>
  </joint>
  <link name="link32">
    <inertial>
      <origin xyz="0 0 0" rpy="0 0 0"/>
      <mass value="0"/>
      <inertia ixx="0" ixy="0" ixz="0" iyy="0" iyz="0" izz="0"/>
    </inertial>
  </link>
  <joint name="joint32" type="revolute">
    <origin xyz="0.0164429070058856180436279714740521740168333053588867187500000000 -0.0007390835856923810669172336673682366381399333477020263671875000 -0.0104237097075063483986312462548085022717714309692382812500000000" rpy="0 0 0"/>
    <parent link="link31"/>
    <child link="link32"/>
    <axis xyz="1 0 0"/>
    <limit lower="-3.1415926535897931159979634685441851615905761718750000000000000000" upper="3.1415926535897931159979634685441851615905761718750000000000000000"/>
  </joint>
  <link name="link33">
    <inertial>
      <origin xyz="0 0 0" rpy="0 0 0"/>
      <mass value="0"/>
      <inertia ixx="0" ixy="0" ixz="0" iyy="0" iyz="0" izz="0"/>
    </inertial>
  </link>
  <joint name="joint33" type="revolute">
    <origin xyz="0 0 0" rpy="0 0 0"/>
    <parent link="link32"/>
    <child link="link33"/>
    <axis xyz="0 1 0"/>
    <limit lower="-1.5707963267948965579989817342720925807952880859375000000000000000" upper="1.5707963267948965579989817342720925807952880859375000000000000000"/>
  </joint>
  <link name="link34">
    <inertial>
      <origin xyz="0 0 0" rpy="0 0 0"/>
      <mass value="0.0200000000000000004163336342344337026588618755340576171875000000"/>
      <inertia ixx="1" ixy="0" ixz="0" iyy="1" iyz="0" izz="1"/>
    </inertial>
    <visual>
      <origin xyz="0 0 0" rpy="0 0 0"/>
      <geometry>
        <mesh filename="meshes/visual/mesh10.obj"/>
      </geometry>
    </visual>
    <collision>
      <origin xyz="0 0 0" rpy="0 0 0"/>
      <geometry>
        <mesh filename="meshes/collision/mesh10.obj"/>
      </geometry>
    </collision>
  </link>
  <joint name="joint34" type="revolute">
    <origin xyz="0 0 0" rpy="0 0 0"/>
    <parent link="link33"/>
    <child link="link34"/>
    <axis xyz="0 0 1"/>
    <limit lower="-3.1415926535897931159979634685441851615905761718750000000000000000" upper="3.1415926535897931159979634685441851615905761718750000000000000000"/>
  </joint>
  <link name="link35">
    <inertial>
      <origin xyz="0 0 0" rpy="0 0 0"/>
      <mass value="0"/>
      <inertia ixx="0" ixy="0" ixz="0" iyy="0" iyz="0" izz="0"/>
    </inertial>
  </link>
  <joint name="joint35" type="revolute">
    <origin xyz="0.0841184497636621453242611323730670846998691558837890625000000000 -0.0041775094800569380348864712004797183908522129058837890625000000 -0.0249894907332424420776106899211299605667591094970703125000000000" rpy="0 0 0"/>
    <parent link="link7"/>
    <child link="link35"/>
    <axis xyz="1 0 0"/>
    <limit lower="-3.1415926535897931159979634685441851615905761718750000000000000000" upper="3.1415926535897931159979634685441851615905761718750000000000000000"/>
  </joint>
  <link name="link36">
    <inertial>
      <origin xyz="0 0 0" rpy="0 0 0"/>
      <mass value="0"/>
      <inertia ixx="0" ixy="0" ixz="0" iyy="0" iyz="0" izz="0"/>
    </inertial>
  </link>
  <joint name="joint36" type="revolute">
    <origin xyz="0 0 0" rpy="0 0 0"/>
    <parent link="link35"/>
    <child link="link36"/>
    <axis xyz="0 1 0"/>
    <limit lower="-1.5707963267948965579989817342720925807952880859375000000000000000" upper="1.5707963267948965579989817342720925807952880859375000000000000000"/>
  </joint>
  <link name="link37">
    <inertial>
      <origin xyz="0 0 0" rpy="0 0 0"/>
      <mass value="0.0200000000000000004163336342344337026588618755340576171875000000"/>
      <inertia ixx="1" ixy="0" ixz="0" iyy="1" iyz="0" izz="1"/>
    </inertial>
    <visual>
      <origin xyz="0 0 0" rpy="0 0 0"/>
      <geometry>
        <mesh filename="meshes/visual/mesh11.obj"/>
      </geometry>
    </visual>
    <collision>
      <origin xyz="0 0 0" rpy="0 0 0"/>
      <geometry>
        <mesh filename="meshes/collision/mesh11.obj"/>
      </geometry>
    </collision>
  </link>
  <joint name="joint37" type="revolute">
    <origin xyz="0 0 0" rpy="0 0 0"/>
    <parent link="link36"/>
    <child link="link37"/>
    <axis xyz="0 0 1"/>
    <limit lower="-3.1415926535897931159979634685441851615905761718750000000000000000" upper="3.1415926535897931159979634685441851615905761718750000000000000000"/>
  </joint>
  <link name="link38">
    <inertial>
      <origin xyz="0 0 0" rpy="0 0 0"/>
      <mass value="0"/>
      <inertia ixx="0" ixy="0" ixz="0" iyy="0" iyz="0" izz="0"/>
    </inertial>
  </link>
  <joint name="joint38" type="revolute">
    <origin xyz="0.0288772428650396935367883344270012457855045795440673828125000000 0.0018232308290986867435612417409629415487870573997497558593750000 -0.0052389045217336067949975841884224792011082172393798828125000000" rpy="0 0 0"/>
    <parent link="link37"/>
    <child link="link38"/>
    <axis xyz="1 0 0"/>
    <limit lower="-3.1415926535897931159979634685441851615905761718750000000000000000" upper="3.1415926535897931159979634685441851615905761718750000000000000000"/>
  </joint>
  <link name="link39">
    <inertial>
      <origin xyz="0 0 0" rpy="0 0 0"/>
      <mass value="0"/>
      <inertia ixx="0" ixy="0" ixz="0" iyy="0" iyz="0" izz="0"/>
    </inertial>
  </link>
  <joint name="joint39" type="revolute">
    <origin xyz="0 0 0" rpy="0 0 0"/>
    <parent link="link38"/>
    <child link="link39"/>
    <axis xyz="0 1 0"/>
    <limit lower="-1.5707963267948965579989817342720925807952880859375000000000000000" upper="1.5707963267948965579989817342720925807952880859375000000000000000"/>
  </joint>
  <link name="link40">
    <inertial>
      <origin xyz="0 0 0" rpy="0 0 0"/>
      <mass value="0.0200000000000000004163336342344337026588618755340576171875000000"/>
      <inertia ixx="1" ixy="0" ixz="0" iyy="1" iyz="0" izz="1"/>
    </inertial>
    <visual>
      <origin xyz="0 0 0" rpy="0 0 0"/>
      <geometry>
        <mesh filename="meshes/visual/mesh12.obj"/>
      </geometry>
    </visual>
    <collision>
      <origin xyz="0 0 0" rpy="0 0 0"/>
      <geometry>
        <mesh filename="meshes/collision/mesh12.obj"/>
      </geometry>
    </collision>
  </link>
  <joint name="joint40" type="revolute">
    <origin xyz="0 0 0" rpy="0 0 0"/>
    <parent link="link39"/>
    <child link="link40"/>
    <axis xyz="0 0 1"/>
    <limit lower="-3.1415926535897931159979634685441851615905761718750000000000000000" upper="3.1415926535897931159979634685441851615905761718750000000000000000"/>
  </joint>
  <link name="link41">
    <inertial>
      <origin xyz="0 0 0" rpy="0 0 0"/>
      <mass value="0"/>
      <inertia ixx="0" ixy="0" ixz="0" iyy="0" iyz="0" izz="0"/>
    </inertial>
  </link>
  <joint name="joint41" type="revolute">
    <origin xyz="0.0239021697565870230861584389003837713971734046936035156250000000 -0.0016918188301130328808630221004705163068138062953948974609375000 -0.0075744796041010385712066721453084028325974941253662109375000000" rpy="0 0 0"/>
    <parent link="link40"/>
    <child link="link41"/>
    <axis xyz="1 0 0"/>
    <limit lower="-3.1415926535897931159979634685441851615905761718750000000000000000" upper="3.1415926535897931159979634685441851615905761718750000000000000000"/>
  </joint>
  <link name="link42">
    <inertial>
      <origin xyz="0 0 0" rpy="0 0 0"/>
      <mass value="0"/>
      <inertia ixx="0" ixy="0" ixz="0" iyy="0" iyz="0" izz="0"/>
    </inertial>
  </link>
  <joint name="joint42" type="revolute">
    <origin xyz="0 0 0" rpy="0 0 0"/>
    <parent link="link41"/>
    <child link="link42"/>
    <axis xyz="0 1 0"/>
    <limit lower="-1.5707963267948965579989817342720925807952880859375000000000000000" upper="1.5707963267948965579989817342720925807952880859375000000000000000"/>
  </joint>
  <link name="link43">
    <inertial>
      <origin xyz="0 0 0" rpy="0 0 0"/>
      <mass value="0.0200000000000000004163336342344337026588618755340576171875000000"/>
      <inertia ixx="1" ixy="0" ixz="0" iyy="1" iyz="0" izz="1"/>
    </inertial>
    <visual>
      <origin xyz="0 0 0" rpy="0 0 0"/>
      <geometry>
        <mesh filename="meshes/visual/mesh13.obj"/>
      </geometry>
    </visual>
    <collision>
      <origin xyz="0 0 0" rpy="0 0 0"/>
      <geometry>
        <mesh filename="meshes/collision/mesh13.obj"/>
      </geometry>
    </collision>
  </link>
  <joint name="joint43" type="revolute">
    <origin xyz="0 0 0" rpy="0 0 0"/>
    <parent link="link42"/>
    <child link="link43"/>
    <axis xyz="0 0 1"/>
    <limit lower="-3.1415926535897931159979634685441851615905761718750000000000000000" upper="3.1415926535897931159979634685441851615905761718750000000000000000"/>
  </joint>
  <link name="link44">
    <inertial>
      <origin xyz="0 0 0" rpy="0 0 0"/>
      <mass value="0"/>
      <inertia ixx="0" ixy="0" ixz="0" iyy="0" iyz="0" izz="0"/>
    </inertial>
  </link>
  <joint name="joint44" type="revolute">
    <origin xyz="0.0244369970547244214076343382657796610146760940551757812500000000 -0.0141569955012520280746013412453976343385875225067138671875000000 0.0243548444223811513809074824621347943320870399475097656250000000" rpy="0 0 0"/>
    <parent link="link7"/>
    <child link="link44"/>
    <axis xyz="1 0 0"/>
    <limit lower="-3.1415926535897931159979634685441851615905761718750000000000000000" upper="3.1415926535897931159979634685441851615905761718750000000000000000"/>
  </joint>
  <link name="link45">
    <inertial>
      <origin xyz="0 0 0" rpy="0 0 0"/>
      <mass value="0"/>
      <inertia ixx="0" ixy="0" ixz="0" iyy="0" iyz="0" izz="0"/>
    </inertial>
  </link>
  <joint name="joint45" type="revolute">
    <origin xyz="0 0 0" rpy="0 0 0"/>
    <parent link="link44"/>
    <child link="link45"/>
    <axis xyz="0 1 0"/>
    <limit lower="-1.5707963267948965579989817342720925807952880859375000000000000000" upper="1.5707963267948965579989817342720925807952880859375000000000000000"/>
  </joint>
  <link name="link46">
    <inertial>
      <origin xyz="0 0 0" rpy="0 0 0"/>
      <mass value="0.0200000000000000004163336342344337026588618755340576171875000000"/>
      <inertia ixx="1" ixy="0" ixz="0" iyy="1" iyz="0" izz="1"/>
    </inertial>
    <visual>
      <origin xyz="0 0 0" rpy="0 0 0"/>
      <geometry>
        <mesh filename="meshes/visual/mesh14.obj"/>
      </geometry>
    </visual>
    <collision>
      <origin xyz="0 0 0" rpy="0 0 0"/>
      <geometry>
        <mesh filename="meshes/collision/mesh14.obj"/>
      </geometry>
    </collision>
  </link>
  <joint name="joint46" type="revolute">
    <origin xyz="0 0 0" rpy="0 0 0"/>
    <parent link="link45"/>
    <child link="link46"/>
    <axis xyz="0 0 1"/>
    <limit lower="-3.1415926535897931159979634685441851615905761718750000000000000000" upper="3.1415926535897931159979634685441851615905761718750000000000000000"/>
  </joint>
  <link name="link47">
    <inertial>
      <origin xyz="0 0 0" rpy="0 0 0"/>
      <mass value="0"/>
      <inertia ixx="0" ixy="0" ixz="0" iyy="0" iyz="0" izz="0"/>
    </inertial>
  </link>
  <joint name="joint47" type="revolute">
    <origin xyz="0.0195614377834991415294751959663699381053447723388671875000000000 0.0002127177970820725086409375137463939609006047248840332031250000 0.0225995884779730815683507216817815788090229034423828125000000000" rpy="0 0 0"/>
    <parent link="link46"/>
    <child link="link47"/>
    <axis xyz="1 0 0"/>
    <limit lower="-3.1415926535897931159979634685441851615905761718750000000000000000" upper="3.1415926535897931159979634685441851615905761718750000000000000000"/>
  </joint>
  <link name="link48">
    <inertial>
      <origin xyz="0 0 0" rpy="0 0 0"/>
      <mass value="0"/>
      <inertia ixx="0" ixy="0" ixz="0" iyy="0" iyz="0" izz="0"/>
    </inertial>
  </link>
  <joint name="joint48" type="revolute">
    <origin xyz="0 0 0" rpy="0 0 0"/>
    <parent link="link47"/>
    <child link="link48"/>
    <axis xyz="0 1 0"/>
    <limit lower="-1.5707963267948965579989817342720925807952880859375000000000000000" upper="1.5707963267948965579989817342720925807952880859375000000000000000"/>
  </joint>
  <link name="link49">
    <inertial>
      <origin xyz="0 0 0" rpy="0 0 0"/>
      <mass value="0.0200000000000000004163336342344337026588618755340576171875000000"/>
      <inertia ixx="1" ixy="0" ixz="0" iyy="1" iyz="0" izz="1"/>
    </inertial>
    <visual>
      <origin xyz="0 0 0" rpy="0 0 0"/>
      <geometry>
        <mesh filename="meshes/visual/mesh15.obj"/>
      </geometry>
    </visual>
    <collision>
      <origin xyz="0 0 0" rpy="0 0 0"/>
      <geometry>
        <mesh filename="meshes/collision/mesh15.obj"/>
      </geometry>
    </collision>
  </link>
  <joint name="joint49" type="revolute">
    <origin xyz="0 0 0" rpy="0 0 0"/>
    <parent link="link48"/>
    <child link="link49"/>
    <axis xyz="0 0 1"/>
    <limit lower="-3.1415926535897931159979634685441851615905761718750000000000000000" upper="3.1415926535897931159979634685441851615905761718750000000000000000"/>
  </joint>
  <link name="link50">
    <inertial>
      <origin xyz="0 0 0" rpy="0 0 0"/>
      <mass value="0"/>
      <inertia ixx="0" ixy="0" ixz="0" iyy="0" iyz="0" izz="0"/>
    </inertial>
  </link>
  <joint name="joint50" type="revolute">
    <origin xyz="0.0226832046256471089873407720460818381980061531066894531250000000 -0.0053147130936835500561454814771877863677218556404113769531250000 0.0143741061673740358473061462518671760335564613342285156250000000" rpy="0 0 0"/>
    <parent link="link49"/>
    <child link="link50"/>
    <axis xyz="1 0 0"/>
    <limit lower="-3.1415926535897931159979634685441851615905761718750000000000000000" upper="3.1415926535897931159979634685441851615905761718750000000000000000"/>
  </joint>
  <link name="link51">
    <inertial>
      <origin xyz="0 0 0" rpy="0 0 0"/>
      <mass value="0"/>
      <inertia ixx="0" ixy="0" ixz="0" iyy="0" iyz="0" izz="0"/>
    </inertial>
  </link>
  <joint name="joint51" type="revolute">
    <origin xyz="0 0 0" rpy="0 0 0"/>
    <parent link="link50"/>
    <child link="link51"/>
    <axis xyz="0 1 0"/>
    <limit lower="-1.5707963267948965579989817342720925807952880859375000000000000000" upper="1.5707963267948965579989817342720925807952880859375000000000000000"/>
  </joint>
  <link name="link52">
    <inertial>
      <origin xyz="0 0 0" rpy="0 0 0"/>
      <mass value="0.0200000000000000004163336342344337026588618755340576171875000000"/>
      <inertia ixx="1" ixy="0" ixz="0" iyy="1" iyz="0" izz="1"/>
    </inertial>
    <visual>
      <origin xyz="0 0 0" rpy="0 0 0"/>
      <geometry>
        <mesh filename="meshes/visual/mesh16.obj"/>
      </geometry>
    </visual>
    <collision>
      <origin xyz="0 0 0" rpy="0 0 0"/>
      <geometry>
        <mesh filename="meshes/collision/mesh16.obj"/>
      </geometry>
    </collision>
  </link>
  <joint name="joint52" type="revolute">
    <origin xyz="0 0 0" rpy="0 0 0"/>
    <parent link="link51"/>
    <child link="link52"/>
    <axis xyz="0 0 1"/>
    <limit lower="-3.1415926535897931159979634685441851615905761718750000000000000000" upper="3.1415926535897931159979634685441851615905761718750000000000000000"/>
  </joint>
</robot>
