<?xml version="1.0" ?>
<!-- =================================================================================== -->
<!-- |    This document was autogenerated by xacro from urdf/galbot_one/galbot_one.xacro | -->
<!-- |    EDITING THIS FILE BY HAND IS NOT RECOMMENDED                                 | -->
<!-- =================================================================================== -->
<!-- 
#####################################################################################
#
# Copyright (c) 2023-2024 Galbot, Inc. All lefts Reserved.
#
# This software contains confidential and proprietary information of Galbot, Inc.
# ("Confidential Information"). You shall not disclose such Confidential Information
# and shall use it only in accordance with the terms of the license agreement you
# entered into with Galbot, Inc.
#
# UNAUTHORIZED COPYING, USE, OR DISTRIBUTION OF THIS SOFTWARE, OR ANY PORTION OR
# DERIVATIVE THEREOF, IS STRICTLY PROHIBITED. IF YOU HAVE RECEIVED THIS SOFTWARE IN
# ERROR, PLEASE NOTIFY GALBOT, INC. IMMEDIATELY AND DELETE IT FROM YOUR SYSTEM.
#
#####################################################################################
#
# Description: Xacro file for Galbot One.
# Author: Herman Ye@Galbot, Yuhao Zeng@Galbot
#
#####################################################################################
-->
<robot name="galbot_one">
    <!-- ROBOT -->
    <!-- Robot Base Link -->

    <link name="mobile_base">
        <!--        <inertial>-->
        <!--            <mass value="0"/>-->
        <!--            <inertia ixx="0" ixy="0" ixz="0" iyy="0" iyz="0" izz="0"/>-->
        <!--        </inertial>-->
    </link>
    <link name="base_link_x">
        <!--        <inertial>-->
        <!--            <mass value="0"/>-->
        <!--            <inertia ixx="0" ixy="0" ixz="0" iyy="0" iyz="0" izz="0"/>-->
        <!--        </inertial>-->
    </link>
    <link name="base_link_y">
        <!--        <inertial>-->
        <!--            <mass value="0"/>-->
        <!--            <inertia ixx="0" ixy="0" ixz="0" iyy="0" iyz="0" izz="0"/>-->
        <!--        </inertial>-->
    </link>
    <link name="base_link_z">
        <!--        <inertial>-->
        <!--            <mass value="0"/>-->
        <!--            <inertia ixx="0" ixy="0" ixz="0" iyy="0" iyz="0" izz="0"/>-->
        <!--        </inertial>-->
    </link>
    <joint name="mobile_x" type="prismatic">
        <origin rpy="0 0 0.0" xyz="0 0 0.0"/>
        <parent link="mobile_base"/>
        <child link="base_link_x"/>
        <axis xyz="1 0 0"/>
        <dynamics damping="10.0"/>
        <limit effort="80" lower="-5.0" upper="5.0" velocity="0.01"/>
    </joint>
    <joint name="mobile_y" type="prismatic">
        <origin rpy="0 0 0.0" xyz="0 0 0.0"/>
        <parent link="base_link_x"/>
        <child link="base_link_y"/>
        <axis xyz="0 1 0"/>
        <dynamics damping="10.0"/>
        <limit effort="80" lower="-5.0" upper="5.0" velocity="0.01"/>
    </joint>
    <joint name="mobile_yaw" type="revolute">
        <origin rpy="0 0 0.0" xyz="0 0 0.0"/>
        <parent link="base_link_y"/>
        <child link="base_link_z"/>
        <axis xyz="0 0 1"/>
        <dynamics damping="10.0"/>
        <limit effort="80" lower="-6.0" upper="6.0" velocity="4.50"/>
    </joint>
    <joint name="base_fixed" type="fixed">
        <origin rpy="0 0 0.0" xyz="0 0 0.0"/>
        <parent link="base_link_z"/>
        <child link="base_link"/>
        <axis xyz="0 0 0"/>
    </joint>


    <link name="base_link">
        <!--        <inertial>-->
        <!--            <mass value="0"/>-->
        <!--            <inertia ixx="0" ixy="0" ixz="0" iyy="0" iyz="0" izz="0"/>-->
        <!--        </inertial>-->
    </link>

    <joint name="omni_chassis_joint" type="fixed">
        <origin rpy="0 0 0" xyz="0 0 0"/>
        <parent link="base_link"/>
        <child link="omni_chassis_base_link"/>
    </joint>
    <link name="omni_chassis_base_link">
        <inertial>
            <origin rpy="0 0 0" xyz="0.00094269 0.00017452 0.09326"/>
            <mass value="800.7914"/>
            <inertia ixx="0.11584" ixy="-0.00011125" ixz="0.00045932" iyy="0.08221" iyz="2.8393E-06" izz="0.14295"/>
        </inertial>
        <visual>
            <origin rpy="0 0 0" xyz="0 0 0"/>
            <geometry>
                <mesh filename="meshes/chassis/omni_chassis_base_link.stl"/>
            </geometry>
            <material name="">
                <color rgba="1 1 1 1"/>
            </material>
        </visual>
        <collision>
            <origin rpy="0 0 0" xyz="0 0 0"/>
            <geometry>
                <mesh filename="meshes/chassis/omni_chassis_base_link.stl"/>
            </geometry>
        </collision>
    </link>
    <link name="omni_chassis_leg_mount_link"/>
    <joint name="omni_chassis_leg_mount_joint" type="fixed">
        <origin rpy="1.5707963267948966 0 0" xyz="0.134 -0.087 0.13"/>
        <parent link="omni_chassis_base_link"/>
        <child link="omni_chassis_leg_mount_link"/>
        <axis xyz="0 0 0"/>
    </joint>
    <joint name="leg_joint" type="fixed">
        <origin rpy="0 0 0" xyz="0 0 0"/>
        <parent link="omni_chassis_leg_mount_link"/>
        <child link="leg_base_link"/>
    </joint>
    <link name="leg_base_link">
        <inertial>
            <origin rpy="0 0 0" xyz="0.0027248 -0.094364 -0.050137"/>
            <mass value="10.91885"/>
            <inertia ixx="0.0043203" ixy="6.1508E-05" ixz="8.9569E-05" iyy="0.0039878" iyz="-0.0010684"
                     izz="0.0027984"/>
        </inertial>
        <visual>
            <origin rpy="0 0 0" xyz="0 0 0"/>
            <geometry>
                <mesh filename="meshes/leg/leg_base_link.stl"/>
            </geometry>
            <material name="">
                <color rgba="1 1 1 1"/>
            </material>
        </visual>
        <collision>
            <origin rpy="0 0 0" xyz="0 0 0"/>
            <geometry>
                <mesh filename="meshes/leg/leg_base_link.stl"/>
            </geometry>
        </collision>
    </link>
    <link name="leg_link1">
        <inertial>
            <origin rpy="0 0 0" xyz="0.23294 -0.0052987 0.0039698"/>
            <mass value="4.7692"/>
            <inertia ixx="0.019082" ixy="-0.0011116" ixz="0.00034191" iyy="0.16145" iyz="-6.2146E-05" izz="0.15826"/>
        </inertial>
        <visual>
            <origin rpy="0 0 0" xyz="0 0 0"/>
            <geometry>
                <mesh filename="meshes/leg/leg_link1.stl"/>
            </geometry>
            <material name="">
                <color rgba="1 1 1 1"/>
            </material>
        </visual>
        <collision>
            <origin rpy="0 0 0" xyz="0 0 0"/>
            <geometry>
                <mesh filename="meshes/leg/leg_link1.stl"/>
            </geometry>
        </collision>
    </link>
    <joint name="leg_joint1" type="fixed">
        <!-- <origin rpy="-3.141592653589793 0 2.756573021" xyz="0 0 -0.087"/> -->
        <origin rpy="-3.141592653589793 0 2.259573021" xyz="0 0 -0.087"/>
        <parent link="leg_base_link"/>
        <child link="leg_link1"/>
        <!-- <axis xyz="0 0 1"/>
        <limit effort="169" lower="0" upper="0.994837674" velocity="2.3"/> -->
    </joint>
    <link name="leg_link2">
        <inertial>
            <origin rpy="0 0 0" xyz="0.19637 2.4915E-06 0.0034234"/>
            <mass value="10.6233"/>
            <inertia ixx="0.0054462" ixy="-2.1435E-06" ixz="-2.9611E-05" iyy="0.066819" iyz="5.2347E-08"
                     izz="0.071791"/>
        </inertial>
        <visual>
            <origin rpy="0 0 0" xyz="0 0 0"/>
            <geometry>
                <mesh filename="meshes/leg/leg_link2.stl"/>
            </geometry>
            <material name="">
                <color rgba="1 1 1 1"/>
            </material>
        </visual>
        <collision>
            <origin rpy="0 0 0" xyz="0 0 0"/>
            <geometry>
                <mesh filename="meshes/leg/leg_link2.stl"/>
            </geometry>
        </collision>
    </link>
    <joint name="leg_joint2" type="fixed">
        <!-- <origin rpy="-3.141592653589793 0 2.756573021" xyz="0.45 0 0"/> -->
        <origin rpy="-3.141592653589793 0 1.185573021" xyz="0.45 0 0"/>
        <parent link="leg_link1"/>
        <child link="leg_link2"/>
        <!-- <axis xyz="0 0 1"/>
        <limit effort="169" lower="0" upper="3.141592654" velocity="2.3"/> -->
    </joint>
    <link name="leg_link3">
        <inertial>
            <origin rpy="0 0 0" xyz="-1.1016E-05 0.012237 0.0042074"/>
            <mass value="10.7624"/>
            <inertia ixx="0.006745" ixy="-4.1776E-07" ixz="8.7932E-07" iyy="0.0066437" iyz="9.063E-05" izz="0.0073862"/>
        </inertial>
        <visual>
            <origin rpy="0 0 0" xyz="0 0 0"/>
            <geometry>
                <mesh filename="meshes/leg/leg_link3.stl"/>
            </geometry>
            <material name="">
                <color rgba="1 1 1 1"/>
            </material>
        </visual>
        <collision>
            <origin rpy="0 0 0" xyz="0 0 0"/>
            <geometry>
                <mesh filename="meshes/leg/leg_link3.stl"/>
            </geometry>
        </collision>
    </link>
    <joint name="leg_joint3" type="fixed">
        <!-- <origin rpy="-3.141592653589793 0 -3.141592653589793" xyz="0.39 0 0"/> -->
        <origin rpy="-3.141592653589793 0 1.9635926535897932" xyz="0.39 0 0"/>
        <parent link="leg_link2"/>
        <child link="leg_link3"/>
        <axis xyz="0 0 1"/>
        <limit effort="84" lower="0" upper="2.35619449" velocity="2.83"/>
    </joint>
    <link name="leg_link4">
        <inertial>
            <origin rpy="0 0 0" xyz="5.7927E-05 -3.0701E-05 0.15111"/>
            <mass value="0.37584"/>
            <inertia ixx="10.00049514" ixy="-3.0213E-07" ixz="-3.9055E-09" iyy="0.00051468" iyz="1.3486E-09"
                     izz="0.00084078"/>
        </inertial>
        <visual>
            <origin rpy="0 0 0" xyz="0 0 0"/>
            <geometry>
                <mesh filename="meshes/leg/leg_link4.stl"/>
            </geometry>
            <material name="">
                <color rgba="1 1 1 1"/>
            </material>
        </visual>
        <collision>
            <origin rpy="0 0 0" xyz="0 0 0"/>
            <geometry>
                <mesh filename="meshes/leg/leg_link4.stl"/>
            </geometry>
        </collision>
    </link>
    <joint name="leg_joint4" type="fixed">
        <origin rpy="1.5707963267948966 0 -3.141592653589793" xyz="0 0 0"/>
        <parent link="leg_link3"/>
        <child link="leg_link4"/>
        <!-- <axis xyz="0 0 1"/>
        <limit effort="20" lower="-1.570796327" upper="1.570796327" velocity="3.56"/> -->
    </joint>
    <link name="leg_torso_mount_link"/>
    <joint name="leg_torso_mount_joint" type="fixed">
        <origin rpy="0 0 0" xyz="0 0 0"/>
        <parent link="leg_link4"/>
        <child link="leg_torso_mount_link"/>
        <axis xyz="0 0 0"/>
    </joint>
    <joint name="torso_joint" type="fixed">
        <origin rpy="0 0 0" xyz="0 0 0"/>
        <parent link="leg_torso_mount_link"/>
        <child link="torso_base_link"/>
    </joint>
    <link name="torso_base_link">
        <inertial>
            <origin rpy="0 0 0" xyz="0.009452 -0.0097068 -0.041989"/>
            <mass value="10.5697"/>
            <inertia ixx="0.018397" ixy="-6.5897E-07" ixz="0.00030036" iyy="0.013058" iyz="0.00016843" izz="0.0082332"/>
        </inertial>
        <visual>
            <origin rpy="0 0 0" xyz="0 0 0"/>
            <geometry>
                <mesh filename="meshes/torso/torso_base_link.stl"/>
            </geometry>
            <material name="">
                <color rgba="1 1 1 1"/>
            </material>
        </visual>
        <collision>
            <origin rpy="0 0 0" xyz="0 0 0"/>
            <geometry>
                <mesh filename="meshes/torso/torso_base_link.stl"/>
            </geometry>
        </collision>
    </link>
    <!-- Head Mount -->
    <link name="torso_head_mount_link"/>
    <joint name="torso_head_mount_joint" type="fixed">
        <origin rpy="0 0 0" xyz="-0.0081669 5E-05 0.51594"/>
        <parent link="torso_base_link"/>
        <child link="torso_head_mount_link"/>
        <axis xyz="0 0 0"/>
    </joint>
    <!-- Right Arm Mount -->
    <link name="torso_right_arm_mount_link"/>
    <joint name="torso_right_arm_mount_joint" type="fixed">
        <origin rpy="1.5707963267948966 0 0" xyz="0 -0.13 0.39599"/>
        <parent link="torso_base_link"/>
        <child link="torso_right_arm_mount_link"/>
        <axis xyz="0 0 0"/>
    </joint>
    <!-- Left Arm Mount -->
    <link name="torso_left_arm_mount_link"/>
    <joint name="torso_left_arm_mount_joint" type="fixed">
        <origin rpy="1.5707963267948966 0 3.141592653589793" xyz="0 0.13 0.39599"/>
        <parent link="torso_base_link"/>
        <child link="torso_left_arm_mount_link"/>
        <axis xyz="0 0 0"/>
    </joint>
    <joint name="head_joint" type="fixed">
        <origin rpy="0 0 0" xyz="0 0 0"/>
        <parent link="torso_head_mount_link"/>
        <child link="head_base_link"/>
    </joint>
    <link name="head_base_link">
        <!--        <inertial>-->
        <!--            <origin rpy="0 0 0" xyz="0.009452 -0.0097068 -0.16194"/>-->
        <!--            <mass value="1.5697"/>-->
        <!--            <inertia ixx="0.018397" ixy="-6.5897E-07" ixz="0.00030036" iyy="0.013058" iyz="0.00016843" izz="0.0082332"/>-->
        <!--        </inertial>-->
        <visual>
            <origin rpy="0 0 0" xyz="0 0 0"/>
            <geometry>
                <mesh filename="meshes/head/head_base_link.stl"/>
            </geometry>
            <material name="">
                <color rgba="1 1 1 1"/>
            </material>
        </visual>
        <collision>
            <origin rpy="0 0 0" xyz="0 0 0"/>
            <geometry>
                <mesh filename="meshes/head/head_base_link.stl"/>
            </geometry>
        </collision>
    </link>
    <link name="head_link1">
        <!--        <inertial>-->
        <!--            <origin rpy="0 0 0" xyz="0 0.020487 -0.038531"/>-->
        <!--            <mass value="0.067654"/>-->
        <!--            <inertia ixx="6.0514E-05" ixy="9.335E-21" ixz="-2.5793E-20" iyy="6.6478E-05" iyz="-1.3077E-05"-->
        <!--                     izz="2.4032E-05"/>-->
        <!--        </inertial>-->
        <visual>
            <origin rpy="0 0 0" xyz="0 0 0"/>
            <geometry>
                <mesh filename="meshes/head/head_link1.stl"/>
            </geometry>
            <material name="">
                <color rgba="1 1 1 1"/>
            </material>
        </visual>
        <collision>
            <origin rpy="0 0 0" xyz="0 0 0"/>
            <geometry>
                <mesh filename="meshes/head/head_link1.stl"/>
            </geometry>
        </collision>
    </link>
    <joint name="head_joint1" type="fixed">
        <origin rpy="0 0 0" xyz="0 0 0.068"/>
        <parent link="head_base_link"/>
        <child link="head_link1"/>
        <!-- <axis xyz="0 0 1"/>
        <limit effort="4" lower="-1.570796327" upper="1.570796327" velocity="8.38"/> -->
    </joint>
    <link name="head_link2">
        <!--        <inertial>-->
        <!--            <origin rpy="0 0 0" xyz="0.024473 -0.053558 0.0026343"/>-->
        <!--            <mass value="0.34019"/>-->
        <!--            <inertia ixx="0.0011508" ixy="-0.00026177" ixz="-4.0924E-07" iyy="0.00085046" iyz="1.4953E-08"-->
        <!--                     izz="0.0010147"/>-->
        <!--        </inertial>-->
        <visual>
            <origin rpy="0 0 0" xyz="0 0 0"/>
            <geometry>
                <mesh filename="meshes/head/head_link2.stl"/>
            </geometry>
            <material name="">
                <color rgba="1 1 1 1"/>
            </material>
        </visual>
        <collision>
            <origin rpy="0 0 0" xyz="0 0 0"/>
            <geometry>
                <mesh filename="meshes/head/head_link2.stl"/>
            </geometry>
        </collision>
    </link>
    <joint name="head_joint2" type="fixed">
        <origin rpy="-1.5707963267948966 0 0" xyz="0 0 0"/>
        <parent link="head_link1"/>
        <child link="head_link2"/>
        <!-- <axis xyz="0 0 1"/>
        <limit effort="4" lower="-0.366519143" upper="0.366519143" velocity="8.38"/> -->
    </joint>
    <joint name="right_arm_joint" type="fixed">
        <origin rpy="0 0 0" xyz="0 0 0"/>
        <parent link="torso_right_arm_mount_link"/>
        <child link="right_arm_base_link"/>
    </joint>
    <link name="right_arm_base_link">
        <!--        <inertial>-->
        <!--            <origin rpy="0 0 0" xyz="-0.000533006129660687 0.000198297061670072 -0.0301844828757755"/>-->
        <!--            <mass value="1.10147619180644"/>-->
        <!--            <inertia ixx="0.000565108607160801" ixy="3.47222948820335E-06" ixz="-1.99104558319723E-05"-->
        <!--                     iyy="0.000573095012457538" iyz="7.38740833192177E-06" izz="0.000685130221778769"/>-->
        <!--        </inertial>-->
        <visual>
            <origin rpy="0 0 0" xyz="0 0 0"/>
            <geometry>
                <mesh filename="meshes/arm/right_arm_base_link.stl"/>
            </geometry>
            <material name="">
                <color rgba="1 1 1 1"/>
            </material>
        </visual>
        <collision>
            <origin rpy="0 0 0" xyz="0 0 0"/>
            <geometry>
                <mesh filename="meshes/arm/right_arm_base_link.stl"/>
            </geometry>
        </collision>
    </link>
    <link name="right_arm_link1">
        <!--        <inertial>-->
        <!--            <origin rpy="0 0 0" xyz="3.49009164621467E-05 0.0108339687508697 -0.00355285779638756"/>-->
        <!--            <mass value="1.50298216561586"/>-->
        <!--            <inertia ixx="0.00141484199510697" ixy="1.78602050106263E-06" ixz="-8.63528107802525E-07"-->
        <!--                     iyy="0.00177403869249562" iyz="5.86035752669724E-06" izz="0.00110206097229515"/>-->
        <!--        </inertial>-->
        <visual>
            <origin rpy="0 0 0" xyz="0 0 0"/>
            <geometry>
                <mesh filename="meshes/arm/right_arm_link1.stl"/>
            </geometry>
            <material name="">
                <color rgba="1 1 1 1"/>
            </material>
        </visual>
        <collision>
            <origin rpy="0 0 0" xyz="0 0 0"/>
            <geometry>
                <mesh filename="meshes/arm/right_arm_link1.stl"/>
            </geometry>
        </collision>
    </link>
    <joint name="right_arm_joint1" type="fixed">
        <!-- <origin rpy="0 0 0" xyz="0 0 0.076"/> -->
        <origin rpy="0 0 -1.571" xyz="0 0 0.076"/>
        <parent link="right_arm_base_link"/>
        <child link="right_arm_link1"/>
        <!-- <axis xyz="0 0 1"/>
        <limit effort="60" lower="-3.141592654" upper="3.141592654" velocity="0.01"/> -->
    </joint>
    <link name="right_arm_link2">
        <!--        <inertial>-->
        <!--            <origin rpy="0 0 0" xyz="-0.0011542937189659 -0.125918427333295 0.00403909337671848"/>-->
        <!--            <mass value="1.45678998733303"/>-->
        <!--            <inertia ixx="0.00269801896410487" ixy="4.63119567548212E-05" ixz="-1.77748665814381E-05"-->
        <!--                     iyy="0.00131692955308753" iyz="-0.000382862812261171" izz="0.00264831680492027"/>-->
        <!--        </inertial>-->
        <visual>
            <origin rpy="0 0 0" xyz="0 0 0"/>
            <geometry>
                <mesh filename="meshes/arm/right_arm_link2.stl"/>
            </geometry>
            <material name="">
                <color rgba="1 1 1 1"/>
            </material>
        </visual>
        <collision>
            <origin rpy="0 0 0" xyz="0 0 0"/>
            <geometry>
                <mesh filename="meshes/arm/right_arm_link2.stl"/>
            </geometry>
        </collision>
    </link>
    <joint name="right_arm_joint2" type="fixed">
        <!-- <origin rpy="-1.5707963267948966 0 3.141592653589793" xyz="0 0 0"/> -->
        <origin rpy="1.5707963267935339 -1.5705926535881751 0" xyz="0 0 0"/>
        <parent link="right_arm_link1"/>
        <child link="right_arm_link2"/>
        <!-- <axis xyz="0 0 1"/>
        <limit effort="60" lower="-2.1" upper="1.570796327" velocity="0.01"/> -->
    </joint>
    <link name="right_arm_link3">
        <!--        <inertial>-->
        <!--            <origin rpy="0 0 0" xyz="0.000352305768300032 -0.00726519320891149 -0.0216211172275835"/>-->
        <!--            <mass value="1.19882450635199"/>-->
        <!--            <inertia ixx="0.00220937810713451" ixy="-1.39043584660172E-05" ixz="1.48996603867525E-06"-->
        <!--                     iyy="0.00236018741531392" iyz="4.46418780437893E-05" izz="0.000843927012398976"/>-->
        <!--        </inertial>-->
        <visual>
            <origin rpy="0 0 0" xyz="0 0 0"/>
            <geometry>
                <mesh filename="meshes/arm/right_arm_link3.stl"/>
            </geometry>
            <material name="">
                <color rgba="1 1 1 1"/>
            </material>
        </visual>
        <collision>
            <origin rpy="0 0 0" xyz="0 0 0"/>
            <geometry>
                <mesh filename="meshes/arm/right_arm_link3.stl"/>
            </geometry>
        </collision>
    </link>
    <joint name="right_arm_joint3" type="fixed">
        <origin rpy="1.5707963267948966 1.5707963267948966 0" xyz="0 -0.35 0"/>
        <parent link="right_arm_link2"/>
        <child link="right_arm_link3"/>
        <!-- <axis xyz="0 0 1"/>
        <limit effort="20" lower="-3.141592654" upper="3.141592654" velocity="0.01"/> -->
    </joint>
    <link name="right_arm_link4">
        <!--        <inertial>-->
        <!--            <origin rpy="0 0 0" xyz="1.5931431873728E-07 -0.084100166334916 0.0032662830921263"/>-->
        <!--            <mass value="0.867364365948374"/>-->
        <!--            <inertia ixx="0.000877887383976985" ixy="1.06944001020881E-08" ixz="-1.42122359084054E-07"-->
        <!--                     iyy="0.000585386964708275" iyz="-0.000142796694938426" izz="0.000827176121025835"/>-->
        <!--        </inertial>-->
        <visual>
            <origin rpy="0 0 0" xyz="0 0 0"/>
            <geometry>
                <mesh filename="meshes/arm/right_arm_link4.stl"/>
            </geometry>
            <material name="">
                <color rgba="1 1 1 1"/>
            </material>
        </visual>
        <collision>
            <origin rpy="0 0 0" xyz="0 0 0"/>
            <geometry>
                <mesh filename="meshes/arm/right_arm_link4.stl"/>
            </geometry>
        </collision>
    </link>
    <joint name="right_arm_joint4" type="fixed">
        <origin rpy="-1.5707963267948966 0 3.141592653589793" xyz="0 0 0"/>
        <parent link="right_arm_link3"/>
        <child link="right_arm_link4"/>
        <!-- <axis xyz="0 0 1"/>
        <limit effort="20" lower="-2.1" upper="2.1" velocity="0.01"/> -->
    </joint>
    <link name="right_arm_link5">
        <!--        <inertial>-->
        <!--            <origin rpy="0 0 0" xyz="-1.30340366499837E-06 0.0256418767190977 -0.117743286278551"/>-->
        <!--            <mass value="1.39256420094548"/>-->
        <!--            <inertia ixx="0.00316702853902255" ixy="7.21162282210242E-08" ixz="-1.52177542728743E-07"-->
        <!--                     iyy="0.00325737339135618" iyz="-0.000396176140685722" izz="0.000888812918742085"/>-->
        <!--        </inertial>-->
        <visual>
            <origin rpy="0 0 0" xyz="0 0 0"/>
            <geometry>
                <mesh filename="meshes/arm/right_arm_link5.stl"/>
            </geometry>
            <material name="">
                <color rgba="1 1 1 1"/>
            </material>
        </visual>
        <collision>
            <origin rpy="0 0 0" xyz="0 0 0"/>
            <geometry>
                <mesh filename="meshes/arm/right_arm_link5.stl"/>
            </geometry>
        </collision>
    </link>
    <joint name="right_arm_joint5" type="fixed">
        <origin rpy="1.5707963267948966 0 0" xyz="0 -0.36 0"/>
        <parent link="right_arm_link4"/>
        <child link="right_arm_link5"/>
        <!-- <axis xyz="0 0 1"/>
        <limit effort="20" lower="-3.141592654" upper="3.141592654" velocity="0.01"/> -->
    </joint>
    <link name="right_arm_link6">
        <!--        <inertial>-->
        <!--            <origin rpy="0 0 0" xyz="-2.88922358060439E-06 -0.000979379563628591 -1.95950029232006E-05"/>-->
        <!--            <mass value="0.574328152865271"/>-->
        <!--            <inertia ixx="0.000196239414479137" ixy="-4.42040670473688E-09" ixz="-2.96256099677375E-08"-->
        <!--                     iyy="0.00023336393089217" iyz="-6.88062986985096E-08" izz="0.000196560460694031"/>-->
        <!--        </inertial>-->
        <visual>
            <origin rpy="0 0 0" xyz="0 0 0"/>
            <geometry>
                <mesh filename="meshes/arm/right_arm_link6.stl"/>
            </geometry>
            <material name="">
                <color rgba="1 1 1 1"/>
            </material>
        </visual>
        <collision>
            <origin rpy="0 0 0" xyz="0 0 0"/>
            <geometry>
                <mesh filename="meshes/arm/right_arm_link6.stl"/>
            </geometry>
        </collision>
    </link>
    <joint name="right_arm_joint6" type="fixed">
        <origin rpy="-1.5707963267948966 0 3.141592653589793" xyz="0 0 0"/>
        <parent link="right_arm_link5"/>
        <child link="right_arm_link6"/>
        <!-- <axis xyz="0 0 1"/>
        <limit effort="20" lower="-1.570796327" upper="1.570796327" velocity="0.01"/> -->
    </joint>
    <link name="right_arm_link7">
        <!--        <inertial>-->
        <!--            <origin rpy="0 0 0" xyz="0.000145324653036516 0.000669639293546548 0.0517788732710871"/>-->
        <!--            <mass value="0.271983892475789"/>-->
        <!--            <inertia ixx="9.12795880546355E-05" ixy="-3.70484062161125E-07" ixz="3.02036543797804E-07"-->
        <!--                     iyy="9.01051818347072E-05" iyz="-2.27095800634144E-07" izz="0.00015076316927533"/>-->
        <!--        </inertial>-->
        <visual>
            <origin rpy="0 0 0" xyz="0 0 0"/>
            <geometry>
                <mesh filename="meshes/arm/right_arm_link7.stl"/>
            </geometry>
            <material name="">
                <color rgba="1 1 1 1"/>
            </material>
        </visual>
        <collision>
            <origin rpy="0 0 0" xyz="0 0 0"/>
            <geometry>
                <mesh filename="meshes/arm/right_arm_link7.stl"/>
            </geometry>
        </collision>
    </link>
    <joint name="right_arm_joint7" type="fixed">
        <origin rpy="-1.5707963267948966 3.141592653589793 3.141592653589793" xyz="0 0 0"/>
        <parent link="right_arm_link6"/>
        <child link="right_arm_link7"/>
        <!-- <axis xyz="0 0 1"/>
        <limit effort="20" lower="-3.141592654" upper="3.141592654" velocity="0.01"/> -->
    </joint>
    <link name="right_arm_end_effector_mount_link"/>
    <joint name="right_arm_end_effector_mount_joint" type="fixed">
        <origin rpy="0 0 0" xyz="0 0 0.0845"/>
        <parent link="right_arm_link7"/>
        <child link="right_arm_end_effector_mount_link"/>
        <axis xyz="0 0 0"/>
    </joint>
    <joint name="right_flange_joint" type="fixed">
        <origin rpy="0 0 0.523598776" xyz="0 0 0"/>
        <parent link="right_arm_end_effector_mount_link"/>
        <child link="right_flange_base_link"/>
    </joint>
    <link name="right_flange_base_link">
        <!--        <inertial>-->
        <!--            <origin rpy="0 0 0" xyz="0.052829 -0.00096484 0.013285"/>-->
        <!--            <mass value="0.25733"/>-->
        <!--            <inertia ixx="0.0002175" ixy="-2.5433E-06" ixz="4.0586E-06" iyy="5.3894E-05" iyz="-1.8533E-06"-->
        <!--                     izz="0.00025319"/>-->
        <!--        </inertial>-->
        <visual>
            <origin rpy="0 0 0" xyz="0 0 0"/>
            <geometry>
                <mesh filename="meshes/flange/flange_base_link.stl"/>
            </geometry>
            <material name="">
                <color rgba="1 1 1 1"/>
            </material>
        </visual>
        <collision>
            <origin rpy="0 0 0" xyz="0 0 0"/>
            <geometry>
                <mesh filename="meshes/flange/flange_base_link.stl"/>
            </geometry>
        </collision>
    </link>
    <link name="right_flange_mount_link"/>
    <joint name="right_flange_mount_joint" type="fixed">
        <origin rpy="0 0 0" xyz="0 0 0.006"/>
        <parent link="right_flange_base_link"/>
        <child link="right_flange_mount_link"/>
        <axis xyz="0 0 0"/>
    </joint>
    <joint name="right_arm_camera_joint" type="fixed">
        <origin rpy="3.1415926 -1.308996939 0" xyz="0.0526 -0.02 0.02054"/>
        <parent link="right_flange_base_link"/>
        <child link="right_arm_camera_flange_link"/>
    </joint>
    <link name="right_arm_camera_flange_link">
        <!--        <inertial>-->
        <!--            <origin rpy="0 0 0" xyz="0.052829 -0.00096484 0.013285"/>-->
        <!--            <mass value="0.25733"/>-->
        <!--            <inertia ixx="0.0002175" ixy="-2.5433E-06" ixz="4.0586E-06" iyy="5.3894E-05" iyz="-1.8533E-06"-->
        <!--                     izz="0.00025319"/>-->
        <!--        </inertial>-->
        <visual>
            <origin rpy="0 0 0" xyz="0 0 0"/>
            <geometry>
                <mesh filename="meshes/camera/arm_camera.stl"/>
            </geometry>
            <material name="">
                <color rgba="1 1 1 1"/>
            </material>
        </visual>
        <collision>
            <origin rpy="0 0 0" xyz="0 0 0"/>
            <geometry>
                <mesh filename="meshes/camera/arm_camera.stl"/>
            </geometry>
        </collision>
    </link>
    <joint name="right_suction_cup_joint" type="fixed">
        <origin rpy="0 0 0" xyz="0 0 0"/>
        <parent link="right_flange_mount_link"/>
        <child link="right_suction_cup_base_link"/>
    </joint>
    <link name="right_suction_cup_base_link">
        <!--        <inertial>-->
        <!--            <origin rpy="0 0 0" xyz="-4.0035E-05 -0.00015919 0.065665"/>-->
        <!--            <mass value="0.36941"/>-->
        <!--            <inertia ixx="0.00014564" ixy="3.5459E-07" ixz="-1.2386E-07" iyy="0.00016918" iyz="-4.0084E-07"-->
        <!--                     izz="0.000219"/>-->
        <!--        </inertial>-->
        <visual>
            <origin rpy="0 0 0" xyz="0 0 0"/>
            <geometry>
                <mesh filename="meshes/suction_cup/suction_cup_base_link.stl"/>
            </geometry>
            <material name="">
                <color rgba="1 1 1 1"/>
            </material>
        </visual>
        <collision>
            <origin rpy="0 0 0" xyz="0 0 0"/>
            <geometry>
                <mesh filename="meshes/suction_cup/suction_cup_base_link.stl"/>
            </geometry>
        </collision>
    </link>
    <link name="right_suction_cup_link1">
        <!--        <inertial>-->
        <!--            <origin rpy="0 0 0" xyz="0.037966 -3.0191E-05 -4.2414E-08"/>-->
        <!--            <mass value="0.063856"/>-->
        <!--            <inertia ixx="7.1717E-06" ixy="1.7711E-08" ixz="-3.6994E-11" iyy="8.0256E-06" iyz="4.7383E-09"-->
        <!--                     izz="7.78E-06"/>-->
        <!--        </inertial>-->
        <visual>
            <origin rpy="0 0 0" xyz="0 0 0"/>
            <geometry>
                <mesh filename="meshes/suction_cup/suction_cup_link1.stl"/>
            </geometry>
            <material name="">
                <color rgba="1 1 1 1"/>
            </material>
        </visual>
        <collision>
            <origin rpy="0 0 0" xyz="0 0 0"/>
            <geometry>
                <mesh filename="meshes/suction_cup/suction_cup_link1.stl"/>
            </geometry>
        </collision>
    </link>
    <joint name="right_suction_cup_joint1" type="fixed">
        <origin rpy="1.5707963267948966 0 -1.5707963267948966" xyz="0 0 0.145"/>
        <parent link="right_suction_cup_base_link"/>
        <child link="right_suction_cup_link1"/>
        <!-- <axis xyz="0 0 1"/>
        <limit effort="1" lower="0" upper="1.570796327" velocity="1.570796327"/> -->
    </joint>
    <link name="right_suction_cup_tcp_link"/>
    <joint name="right_suction_cup_tcp_joint" type="fixed">
        <origin rpy="1.5707963267948966 1.5707963267948966 3.141592653589793" xyz="0 0.079807 0"/>
        <parent link="right_suction_cup_link1"/>
        <child link="right_suction_cup_tcp_link"/>
        <axis xyz="0 0 0"/>
    </joint>
    <joint name="left_arm_joint" type="fixed">
        <origin rpy="0 0 0" xyz="0 0 0"/>
        <parent link="torso_left_arm_mount_link"/>
        <child link="left_arm_base_link"/>
    </joint>
    <link name="left_arm_base_link">
        <inertial>
            <origin rpy="0 0 0" xyz="0.00056868 -5.0139E-06 -0.030184"/>
            <mass value="20.1015"/>
            <inertia ixx="0.00056381" ixy="1.1123E-07" ixz="2.1236E-05" iyy="0.00057439" iyz="-1.685E-07"
                     izz="0.00068513"/>
        </inertial>
        <visual>
            <origin rpy="0 0 0" xyz="0 0 0"/>
            <geometry>
                <mesh filename="meshes/arm/left_arm_base_link.stl"/>
            </geometry>
            <material name="">
                <color rgba="1 1 1 1"/>
            </material>
        </visual>
        <collision>
            <origin rpy="0 0 0" xyz="0 0 0"/>
            <geometry>
                <mesh filename="meshes/arm/left_arm_base_link.stl"/>
            </geometry>
        </collision>
    </link>
    <link name="left_arm_link1">
        <inertial>
            <origin rpy="0 0 0" xyz="-3.4901E-05 -0.010834 -0.0035529"/>
            <mass value="10.503"/>
            <inertia ixx="0.0014148" ixy="1.786E-06" ixz="8.6353E-07" iyy="0.001774" iyz="-5.8604E-06" izz="0.0011021"/>
        </inertial>
        <visual>
            <origin rpy="0 0 0" xyz="0 0 0"/>
            <geometry>
                <mesh filename="meshes/arm/left_arm_link1.stl"/>
            </geometry>
            <material name="">
                <color rgba="1 1 1 1"/>
            </material>
        </visual>
        <collision>
            <origin rpy="0 0 0" xyz="0 0 0"/>
            <geometry>
                <mesh filename="meshes/arm/left_arm_link1.stl"/>
            </geometry>
        </collision>
    </link>
    <joint name="left_arm_joint1" type="revolute">
        <origin rpy="0 0 0" xyz="0 0 0.076"/>
        <parent link="left_arm_base_link"/>
        <child link="left_arm_link1"/>
        <axis xyz="0 0 1"/>
        <limit effort="60" lower="-3.141592654" upper="3.141592654" velocity="0.01"/>
    </joint>
    <link name="left_arm_link2">
        <inertial>
            <origin rpy="0 0 0" xyz="0.0011543 0.12592 0.0040391"/>
            <mass value="10.4568"/>
            <inertia ixx="0.002698" ixy="4.6312E-05" ixz="1.7775E-05" iyy="0.0013169" iyz="0.00038286" izz="0.0026483"/>
        </inertial>
        <visual>
            <origin rpy="0 0 0" xyz="0 0 0"/>
            <geometry>
                <mesh filename="meshes/arm/left_arm_link2.stl"/>
            </geometry>
            <material name="">
                <color rgba="1 1 1 1"/>
            </material>
        </visual>
        <collision>
            <origin rpy="0 0 0" xyz="0 0 0"/>
            <geometry>
                <mesh filename="meshes/arm/left_arm_link2.stl"/>
            </geometry>
        </collision>
    </link>
    <joint name="left_arm_joint2" type="revolute">
        <origin rpy="-1.5707963267948966 0 3.141592653589793" xyz="0 0 0"/>
        <parent link="left_arm_link1"/>
        <child link="left_arm_link2"/>
        <axis xyz="0 0 1"/>
        <limit effort="60" lower="-1.570796327" upper="2.1" velocity="0.01"/>
    </joint>
    <link name="left_arm_link3">
        <inertial>
            <origin rpy="0 0 0" xyz="0.00035231 -0.0072652 -0.021621"/>
            <mass value="10.1988"/>
            <inertia ixx="0.0022094" ixy="-1.3904E-05" ixz="1.4901E-06" iyy="0.0023602" iyz="4.4642E-05"
                     izz="0.00084393"/>
        </inertial>
        <visual>
            <origin rpy="0 0 0" xyz="0 0 0"/>
            <geometry>
                <mesh filename="meshes/arm/left_arm_link3.stl"/>
            </geometry>
            <material name="">
                <color rgba="1 1 1 1"/>
            </material>
        </visual>
        <collision>
            <origin rpy="0 0 0" xyz="0 0 0"/>
            <geometry>
                <mesh filename="meshes/arm/left_arm_link3.stl"/>
            </geometry>
        </collision>
    </link>
    <joint name="left_arm_joint3" type="revolute">
        <origin rpy="1.5707963267948966 -1.5707963267948966 0" xyz="0 -0.35 0"/>
        <parent link="left_arm_link2"/>
        <child link="left_arm_link3"/>
        <axis xyz="0 0 1"/>
        <limit effort="20" lower="-3.141592654" upper="3.141592654" velocity="0.01"/>
    </joint>
    <link name="left_arm_link4">
        <inertial>
            <origin rpy="0 0 0" xyz="1.6053E-07 -0.0841 0.0032663"/>
            <mass value="10.86736"/>
            <inertia ixx="0.00087789" ixy="1.0686E-08" ixz="-1.4208E-07" iyy="0.00058539" iyz="-0.0001428"
                     izz="0.00082718"/>
        </inertial>
        <visual>
            <origin rpy="0 0 0" xyz="0 0 0"/>
            <geometry>
                <mesh filename="meshes/arm/left_arm_link4.stl"/>
            </geometry>
            <material name="">
                <color rgba="1 1 1 1"/>
            </material>
        </visual>
        <collision>
            <origin rpy="0 0 0" xyz="0 0 0"/>
            <geometry>
                <mesh filename="meshes/arm/left_arm_link4.stl"/>
            </geometry>
        </collision>
    </link>
    <joint name="left_arm_joint4" type="revolute">
        <origin rpy="-1.5707963267948966 0 3.141592653589793" xyz="0 0 0"/>
        <parent link="left_arm_link3"/>
        <child link="left_arm_link4"/>
        <axis xyz="0 0 1"/>
        <limit effort="20" lower="-2.1" upper="2.1" velocity="0.01"/>
    </joint>
    <link name="left_arm_link5">
        <inertial>
            <origin rpy="0 0 0" xyz="1.5971E-06 -0.025642 -0.11774"/>
            <mass value="3.3926"/>
            <inertia ixx="0.003167" ixy="8.3315E-08" ixz="1.4879E-07" iyy="0.0032574" iyz="0.00039617"
                     izz="0.00088879"/>
        </inertial>
        <visual>
            <origin rpy="0 0 0" xyz="0 0 0"/>
            <geometry>
                <mesh filename="meshes/arm/left_arm_link5.stl"/>
            </geometry>
            <material name="">
                <color rgba="1 1 1 1"/>
            </material>
        </visual>
        <collision>
            <origin rpy="0 0 0" xyz="0 0 0"/>
            <geometry>
                <mesh filename="meshes/arm/left_arm_link5.stl"/>
            </geometry>
        </collision>
    </link>
    <joint name="left_arm_joint5" type="revolute">
        <origin rpy="1.5707963267948966 0 0" xyz="0 -0.36 0"/>
        <parent link="left_arm_link4"/>
        <child link="left_arm_link5"/>
        <axis xyz="0 0 1"/>
        <limit effort="20" lower="-3.141592654" upper="3.141592654" velocity="0.01"/>
    </joint>
    <link name="left_arm_link6">
        <inertial>
            <origin rpy="0 0 0" xyz="-2.8892E-06 -0.00097938 -1.9595E-05"/>
            <mass value="0.57433"/>
            <inertia ixx="0.00019624" ixy="-4.4204E-09" ixz="-2.9626E-08" iyy="0.00023336" iyz="-6.8806E-08"
                     izz="0.00019656"/>
        </inertial>
        <visual>
            <origin rpy="0 0 0" xyz="0 0 0"/>
            <geometry>
                <mesh filename="meshes/arm/left_arm_link6.stl"/>
            </geometry>
            <material name="">
                <color rgba="1 1 1 1"/>
            </material>
        </visual>
        <collision>
            <origin rpy="0 0 0" xyz="0 0 0"/>
            <geometry>
                <mesh filename="meshes/arm/left_arm_link6.stl"/>
            </geometry>
        </collision>
    </link>
    <joint name="left_arm_joint6" type="revolute">
        <origin rpy="-1.5707963267948966 0 3.141592653589793" xyz="0 0 0"/>
        <parent link="left_arm_link5"/>
        <child link="left_arm_link6"/>
        <axis xyz="0 0 1"/>
        <limit effort="20" lower="-1.570796327" upper="1.570796327" velocity="0.01"/>
    </joint>
    <link name="left_arm_link7">
        <inertial>
            <origin rpy="0 0 0" xyz="0.00014532 0.00066964 0.051779"/>
            <mass value="2.27198"/>
            <inertia ixx="9.128E-05" ixy="-3.7048E-07" ixz="3.0204E-07" iyy="9.0105E-05" iyz="-2.2709E-07"
                     izz="0.00015076"/>
        </inertial>
        <visual>
            <origin rpy="0 0 0" xyz="0 0 0"/>
            <geometry>
                <mesh filename="meshes/arm/left_arm_link7.stl"/>
            </geometry>
            <material name="">
                <color rgba="1 1 1 1"/>
            </material>
        </visual>
        <collision>
            <origin rpy="0 0 0" xyz="0 0 0"/>
            <geometry>
                <mesh filename="meshes/arm/left_arm_link7.stl"/>
            </geometry>
        </collision>
    </link>
    <joint name="left_arm_joint7" type="revolute">
        <origin rpy="1.5707963267948966 0 0" xyz="0 0 0"/>
        <parent link="left_arm_link6"/>
        <child link="left_arm_link7"/>
        <axis xyz="0 0 1"/>
        <limit effort="20" lower="-3.141592654" upper="3.141592654" velocity="0.01"/>
    </joint>
    <link name="left_arm_end_effector_mount_link"/>
    <joint name="left_arm_end_effector_mount_joint" type="fixed">
        <origin rpy="0 0 0" xyz="0 0 0.0845"/>
        <parent link="left_arm_link7"/>
        <child link="left_arm_end_effector_mount_link"/>
        <axis xyz="0 0 0"/>
    </joint>
    <joint name="left_flange_joint" type="fixed">
        <origin rpy="0 0 2.617993878" xyz="0 0 0"/>
        <parent link="left_arm_end_effector_mount_link"/>
        <child link="left_flange_base_link"/>
    </joint>
    <link name="left_flange_base_link">
        <inertial>
            <origin rpy="0 0 0" xyz="0.052829 -0.00096484 0.013285"/>
            <mass value="1.25733"/>
            <inertia ixx="0.0002175" ixy="-2.5433E-06" ixz="4.0586E-06" iyy="5.3894E-05" iyz="-1.8533E-06"
                     izz="0.00025319"/>
        </inertial>
        <visual>
            <origin rpy="0 0 0" xyz="0 0 0"/>
            <geometry>
                <mesh filename="meshes/flange/flange_base_link.stl"/>
            </geometry>
            <material name="">
                <color rgba="1 1 1 1"/>
            </material>
        </visual>
        <collision>
            <origin rpy="0 0 0" xyz="0 0 0"/>
            <geometry>
                <mesh filename="meshes/flange/flange_base_link.stl"/>
            </geometry>
        </collision>
    </link>
    <link name="left_flange_mount_link"/>
    <joint name="left_flange_mount_joint" type="fixed">
        <origin rpy="0 0 0" xyz="0 0 0.006"/>
        <parent link="left_flange_base_link"/>
        <child link="left_flange_mount_link"/>
        <axis xyz="0 0 0"/>
    </joint>
    <joint name="left_arm_camera_joint" type="fixed">
        <origin rpy="3.1415926 -1.308996939 0" xyz="0.0526 -0.02 0.02054"/>
        <parent link="left_flange_base_link"/>
        <child link="left_arm_camera_flange_link"/>
    </joint>
    <link name="left_arm_camera_flange_link">
        <inertial>
            <origin rpy="0 0 0" xyz="0.052829 -0.00096484 0.013285"/>
            <mass value="0.25733"/>
            <inertia ixx="0.0002175" ixy="-2.5433E-06" ixz="4.0586E-06" iyy="5.3894E-05" iyz="-1.8533E-06"
                     izz="0.00025319"/>
        </inertial>
        <visual>
            <origin rpy="0 0 0" xyz="0 0 0"/>
            <geometry>
                <mesh filename="meshes/camera/arm_camera.stl"/>
            </geometry>
            <material name="">
                <color rgba="1 1 1 1"/>
            </material>
        </visual>
        <collision>
            <origin rpy="0 0 0" xyz="0 0 0"/>
            <geometry>
                <mesh filename="meshes/camera/arm_camera.stl"/>
            </geometry>
        </collision>
    </link>
    <joint name="left_gripper_joint" type="fixed">
        <origin rpy="0 0 0" xyz="0 0 0"/>
        <parent link="left_flange_mount_link"/>
        <child link="left_gripper_base_link"/>
    </joint>
    <link name="left_gripper_base_link">
        <inertial>
            <origin rpy="0 0 0" xyz="0.0875969515032359 -0.000593766922509439 -0.000273353044587243"/>
            <mass value="0.229646651659589"/>
            <inertia ixx="8.60029243295527E-05" ixy="2.00063024143341E-06" ixz="2.85398505671959E-06"
                     iyy="7.73254340691918E-05" iyz="-1.0856442426917E-07" izz="9.78281466602487E-05"/>
        </inertial>
        <visual>
            <origin rpy="0 0 0" xyz="0 0 0.07"/>
            <!--      <geometry>-->
            <!--        <mesh filename="meshes/gripper/gripper_hitbot_base_link.stl"/>-->
            <!--      </geometry>-->
            <geometry>
                <box size="0.043 0.05 0.14"/>
            </geometry>
            <material name="">
                <color rgba="1 1 1 1"/>
            </material>
        </visual>
        <collision>
            <origin rpy="0 0 0" xyz="0 0 0.07"/>
            <!--      <geometry>-->
            <!--        <mesh filename="meshes/gripper/gripper_hitbot_base_link.stl"/>-->
            <!--      </geometry>-->
            <geometry>
                <box size="0.043 0.05 0.14"/>
            </geometry>
        </collision>
    </link>
    <link name="left_gripper_left_link">
        <inertial>
            <origin rpy="0 0 0" xyz="-0.0231481638496937 -4.90112376816481E-07 -0.000267991935875532"/>
            <mass value="0.00675449578859124"/>
            <inertia ixx="3.19945619554153E-07" ixy="-7.76829664652689E-12" ixz="-3.91342467850705E-07"
                     iyy="1.5976052028241E-06" iyz="2.16781299849398E-11" izz="1.50158040800935E-06"/>
        </inertial>
        <visual>
            <origin rpy="0 0 0" xyz="0 0 0"/>
            <geometry>
                <mesh filename="meshes/gripper/gripper_hitbot_left_link.stl"/>
            </geometry>
            <material name="">
                <color rgba="1 1 1 1"/>
            </material>
        </visual>
        <collision>
            <origin rpy="0 0 0" xyz="0 0 0"/>
            <geometry>
                <mesh filename="meshes/gripper/gripper_hitbot_left_link.stl"/>
            </geometry>
        </collision>
    </link>
    <joint name="left_gripper_left_joint" type="prismatic">
        <origin rpy="1.5707963267948966 0 3.141592653589793" xyz="0 0 0.21579"/>
        <parent link="left_gripper_base_link"/>
        <child link="left_gripper_left_link"/>
        <axis xyz="0 0 1"/>
        <limit effort="2" lower="0.005" upper="0.05" velocity="0.045"/>
    </joint>
    <link name="left_gripper_right_link">
        <inertial>
            <origin rpy="0 0 0" xyz="-0.0231481638496943 -4.90112376734401E-07 -0.000267991935824489"/>
            <mass value="0.00675449578859123"/>
            <inertia ixx="3.19945619552427E-07" ixy="-7.76829655500751E-12" ixz="-3.91342467848098E-07"
                     iyy="1.5976052028241E-06" iyz="2.16781300075729E-11" izz="1.50158040801108E-06"/>
        </inertial>
        <visual>
            <origin rpy="0 0 0" xyz="0 0 0"/>
            <geometry>
                <mesh filename="meshes/gripper/gripper_hitbot_right_link.stl"/>
            </geometry>
            <material name="">
                <color rgba="1 1 1 1"/>
            </material>
        </visual>
        <collision>
            <origin rpy="0 0 0" xyz="0 0 0"/>
            <geometry>
                <mesh filename="meshes/gripper/gripper_hitbot_right_link.stl"/>
            </geometry>
        </collision>
    </link>
    <joint name="left_gripper_right_joint" type="prismatic">
        <origin rpy="-1.5707963267948966 0 -3.141592653589793" xyz="0 0 0.21579"/>
        <parent link="left_gripper_base_link"/>
        <child link="left_gripper_right_link"/>
        <axis xyz="0 0 1"/>
        <limit effort="2" lower="0.005" upper="0.05" velocity="0.045"/>
        <!-- mimic not supported in isaac sim 2023.1.0-hotfix  -->
        <!-- <mimic joint="${name}_left_joint" multiplier="-1" offset="0" /> -->
    </joint>
    <!-- Tool Center Point -->
    <link name="left_gripper_tcp_link"/>
    <joint name="tcp_joint" type="fixed">
        <origin rpy="0 0 0" xyz="0 0 0.21579"/>
        <parent link="left_gripper_base_link"/>
        <child link="left_gripper_tcp_link"/>
        <axis xyz="0 0 0"/>
    </joint>
</robot>
