<?xml version="1.0" ?>
<robot name="mano">
  <link name="link0">
    <inertial>
      <origin xyz="0 0 0" rpy="0 0 0"/>
      <mass value="0"/>
      <inertia ixx="0" ixy="0" ixz="0" iyy="0" iyz="0" izz="0"/>
    </inertial>
  </link>
  <link name="link1">
    <inertial>
      <origin xyz="0 0 0" rpy="0 0 0"/>
      <mass value="0"/>
      <inertia ixx="0" ixy="0" ixz="0" iyy="0" iyz="0" izz="0"/>
    </inertial>
  </link>
  <joint name="joint1" type="prismatic">
    <origin xyz="0 0 0" rpy="0 0 0"/>
    <parent link="link0"/>
    <child link="link1"/>
    <axis xyz="1 0 0"/>
    <limit lower="-1000" upper="1000"/>
  </joint>
  <link name="link2">
    <inertial>
      <origin xyz="0 0 0" rpy="0 0 0"/>
      <mass value="0"/>
      <inertia ixx="0" ixy="0" ixz="0" iyy="0" iyz="0" izz="0"/>
    </inertial>
  </link>
  <joint name="joint2" type="prismatic">
    <origin xyz="0 0 0" rpy="0 0 0"/>
    <parent link="link1"/>
    <child link="link2"/>
    <axis xyz="0 1 0"/>
    <limit lower="-1000" upper="1000"/>
  </joint>
  <link name="link3">
    <inertial>
      <origin xyz="0 0 0" rpy="0 0 0"/>
      <mass value="0"/>
      <inertia ixx="0" ixy="0" ixz="0" iyy="0" iyz="0" izz="0"/>
    </inertial>
  </link>
  <joint name="joint3" type="prismatic">
    <origin xyz="0 0 0" rpy="0 0 0"/>
    <parent link="link2"/>
    <child link="link3"/>
    <axis xyz="0 0 1"/>
    <limit lower="-1000" upper="1000"/>
  </joint>
  <link name="link4">
    <inertial>
      <origin xyz="0 0 0" rpy="0 0 0"/>
      <mass value="0"/>
      <inertia ixx="0" ixy="0" ixz="0" iyy="0" iyz="0" izz="0"/>
    </inertial>
  </link>
  <joint name="joint4" type="continuous">
    <origin xyz="0 0 0" rpy="0 0 0"/>
    <parent link="link3"/>
    <child link="link4"/>
    <axis xyz="1 0 0"/>
    <limit lower="1" upper="-1"/>
  </joint>
  <link name="link5">
    <inertial>
      <origin xyz="0 0 0" rpy="0 0 0"/>
      <mass value="0"/>
      <inertia ixx="0" ixy="0" ixz="0" iyy="0" iyz="0" izz="0"/>
    </inertial>
  </link>
  <joint name="joint5" type="continuous">
    <origin xyz="0 0 0" rpy="0 0 0"/>
    <parent link="link4"/>
    <child link="link5"/>
    <axis xyz="0 1 0"/>
    <limit lower="1" upper="-1"/>
  </joint>
  <link name="link6">
    <inertial>
      <origin xyz="0 0 0" rpy="0 0 0"/>
      <mass value="0"/>
      <inertia ixx="0" ixy="0" ixz="0" iyy="0" iyz="0" izz="0"/>
    </inertial>
  </link>
  <joint name="joint6" type="continuous">
    <origin xyz="0 0 0" rpy="0 0 0"/>
    <parent link="link5"/>
    <child link="link6"/>
    <axis xyz="0 0 1"/>
    <limit lower="1" upper="-1"/>
  </joint>
  <link name="link7">
    <inertial>
      <origin xyz="0 0 0" rpy="0 0 0"/>
      <mass value="0.2000000000000000111022302462515654042363166809082031250000000000"/>
      <inertia ixx="1" ixy="0" ixz="0" iyy="1" iyz="0" izz="1"/>
    </inertial>
    <visual>
      <origin xyz="0 0 0" rpy="0 0 0"/>
      <geometry>
        <mesh filename="meshes/visual/mesh1.obj"/>
      </geometry>
    </visual>
    <collision>
      <origin xyz="0 0 0" rpy="0 0 0"/>
      <geometry>
        <mesh filename="meshes/collision/mesh1.obj"/>
      </geometry>
    </collision>
  </link>
  <joint name="joint7" type="fixed">
    <origin xyz="-0.0940731081959874787523645522924198303371667861938476562500000000 0.0065395377294541895407675724527507554739713668823242187500000000 0.0063707012234389967866854398437226336682215332984924316406250000" rpy="0 0 0"/>
    <parent link="link6"/>
    <child link="link7"/>
    <axis xyz="0 0 0"/>
    <limit lower="1" upper="-1"/>
  </joint>
  <link name="link8">
    <inertial>
      <origin xyz="0 0 0" rpy="0 0 0"/>
      <mass value="0"/>
      <inertia ixx="0" ixy="0" ixz="0" iyy="0" iyz="0" izz="0"/>
    </inertial>
  </link>
  <joint name="joint8" type="revolute">
    <origin xyz="0.0868444943164443788896633691365423146635293960571289062500000000 -0.0050038235330932892552802115915255853906273841857910156250000000 0.0208866886957570635496850286472181323915719985961914062500000000" rpy="0 0 0"/>
    <parent link="link7"/>
    <child link="link8"/>
    <axis xyz="1 0 0"/>
    <limit lower="-3.1415926535897931159979634685441851615905761718750000000000000000" upper="3.1415926535897931159979634685441851615905761718750000000000000000"/>
  </joint>
  <link name="link9">
    <inertial>
      <origin xyz="0 0 0" rpy="0 0 0"/>
      <mass value="0"/>
      <inertia ixx="0" ixy="0" ixz="0" iyy="0" iyz="0" izz="0"/>
    </inertial>
  </link>
  <joint name="joint9" type="revolute">
    <origin xyz="0 0 0" rpy="0 0 0"/>
    <parent link="link8"/>
    <child link="link9"/>
    <axis xyz="0 1 0"/>
    <limit lower="-1.5707963267948965579989817342720925807952880859375000000000000000" upper="1.5707963267948965579989817342720925807952880859375000000000000000"/>
  </joint>
  <link name="link10">
    <inertial>
      <origin xyz="0 0 0" rpy="0 0 0"/>
      <mass value="0.0200000000000000004163336342344337026588618755340576171875000000"/>
      <inertia ixx="1" ixy="0" ixz="0" iyy="1" iyz="0" izz="1"/>
    </inertial>
    <visual>
      <origin xyz="0 0 0" rpy="0 0 0"/>
      <geometry>
        <mesh filename="meshes/visual/mesh2.obj"/>
      </geometry>
    </visual>
    <collision>
      <origin xyz="0 0 0" rpy="0 0 0"/>
      <geometry>
        <mesh filename="meshes/collision/mesh2.obj"/>
      </geometry>
    </collision>
  </link>
  <joint name="joint10" type="revolute">
    <origin xyz="0 0 0" rpy="0 0 0"/>
    <parent link="link9"/>
    <child link="link10"/>
    <axis xyz="0 0 1"/>
    <limit lower="-3.1415926535897931159979634685441851615905761718750000000000000000" upper="3.1415926535897931159979634685441851615905761718750000000000000000"/>
  </joint>
  <link name="link11">
    <inertial>
      <origin xyz="0 0 0" rpy="0 0 0"/>
      <mass value="0"/>
      <inertia ixx="0" ixy="0" ixz="0" iyy="0" iyz="0" izz="0"/>
    </inertial>
  </link>
  <joint name="joint11" type="revolute">
    <origin xyz="0.0319050109255960626097881061014049919322133064270019531250000000 0.0043636400876347694599566295892145717516541481018066406250000000 0.0022980659349003638991515430234358063898980617523193359375000000" rpy="0 0 0"/>
    <parent link="link10"/>
    <child link="link11"/>
    <axis xyz="1 0 0"/>
    <limit lower="-3.1415926535897931159979634685441851615905761718750000000000000000" upper="3.1415926535897931159979634685441851615905761718750000000000000000"/>
  </joint>
  <link name="link12">
    <inertial>
      <origin xyz="0 0 0" rpy="0 0 0"/>
      <mass value="0"/>
      <inertia ixx="0" ixy="0" ixz="0" iyy="0" iyz="0" izz="0"/>
    </inertial>
  </link>
  <joint name="joint12" type="revolute">
    <origin xyz="0 0 0" rpy="0 0 0"/>
    <parent link="link11"/>
    <child link="link12"/>
    <axis xyz="0 1 0"/>
    <limit lower="-1.5707963267948965579989817342720925807952880859375000000000000000" upper="1.5707963267948965579989817342720925807952880859375000000000000000"/>
  </joint>
  <link name="link13">
    <inertial>
      <origin xyz="0 0 0" rpy="0 0 0"/>
      <mass value="0.0200000000000000004163336342344337026588618755340576171875000000"/>
      <inertia ixx="1" ixy="0" ixz="0" iyy="1" iyz="0" izz="1"/>
    </inertial>
    <visual>
      <origin xyz="0 0 0" rpy="0 0 0"/>
      <geometry>
        <mesh filename="meshes/visual/mesh3.obj"/>
      </geometry>
    </visual>
    <collision>
      <origin xyz="0 0 0" rpy="0 0 0"/>
      <geometry>
        <mesh filename="meshes/collision/mesh3.obj"/>
      </geometry>
    </collision>
  </link>
  <joint name="joint13" type="revolute">
    <origin xyz="0 0 0" rpy="0 0 0"/>
    <parent link="link12"/>
    <child link="link13"/>
    <axis xyz="0 0 1"/>
    <limit lower="-3.1415926535897931159979634685441851615905761718750000000000000000" upper="3.1415926535897931159979634685441851615905761718750000000000000000"/>
  </joint>
  <link name="link14">
    <inertial>
      <origin xyz="0 0 0" rpy="0 0 0"/>
      <mass value="0"/>
      <inertia ixx="0" ixy="0" ixz="0" iyy="0" iyz="0" izz="0"/>
    </inertial>
  </link>
  <joint name="joint14" type="revolute">
    <origin xyz="0.0215780730393594702420934083875181386247277259826660156250000000 -0.0012727503908109543545590369717501744162291288375854492187500000 -0.0003135185941994939051724600176385138183832168579101562500000000" rpy="0 0 0"/>
    <parent link="link13"/>
    <child link="link14"/>
    <axis xyz="1 0 0"/>
    <limit lower="-3.1415926535897931159979634685441851615905761718750000000000000000" upper="3.1415926535897931159979634685441851615905761718750000000000000000"/>
  </joint>
  <link name="link15">
    <inertial>
      <origin xyz="0 0 0" rpy="0 0 0"/>
      <mass value="0"/>
      <inertia ixx="0" ixy="0" ixz="0" iyy="0" iyz="0" izz="0"/>
    </inertial>
  </link>
  <joint name="joint15" type="revolute">
    <origin xyz="0 0 0" rpy="0 0 0"/>
    <parent link="link14"/>
    <child link="link15"/>
    <axis xyz="0 1 0"/>
    <limit lower="-1.5707963267948965579989817342720925807952880859375000000000000000" upper="1.5707963267948965579989817342720925807952880859375000000000000000"/>
  </joint>
  <link name="link16">
    <inertial>
      <origin xyz="0 0 0" rpy="0 0 0"/>
      <mass value="0.0200000000000000004163336342344337026588618755340576171875000000"/>
      <inertia ixx="1" ixy="0" ixz="0" iyy="1" iyz="0" izz="1"/>
    </inertial>
    <visual>
      <origin xyz="0 0 0" rpy="0 0 0"/>
      <geometry>
        <mesh filename="meshes/visual/mesh4.obj"/>
      </geometry>
    </visual>
    <collision>
      <origin xyz="0 0 0" rpy="0 0 0"/>
      <geometry>
        <mesh filename="meshes/collision/mesh4.obj"/>
      </geometry>
    </collision>
  </link>
  <joint name="joint16" type="revolute">
    <origin xyz="0 0 0" rpy="0 0 0"/>
    <parent link="link15"/>
    <child link="link16"/>
    <axis xyz="0 0 1"/>
    <limit lower="-3.1415926535897931159979634685441851615905761718750000000000000000" upper="3.1415926535897931159979634685441851615905761718750000000000000000"/>
  </joint>
  <link name="link17">
    <inertial>
      <origin xyz="0 0 0" rpy="0 0 0"/>
      <mass value="0"/>
      <inertia ixx="0" ixy="0" ixz="0" iyy="0" iyz="0" izz="0"/>
    </inertial>
  </link>
  <joint name="joint17" type="revolute">
    <origin xyz="0.0933518163453578714294778251314710360020399093627929687500000000 -0.0015676365008049060814632191807049821363762021064758300781250000 -0.0033447384421480385457980943897382530849426984786987304687500000" rpy="0 0 0"/>
    <parent link="link7"/>
    <child link="link17"/>
    <axis xyz="1 0 0"/>
    <limit lower="-3.1415926535897931159979634685441851615905761718750000000000000000" upper="3.1415926535897931159979634685441851615905761718750000000000000000"/>
  </joint>
  <link name="link18">
    <inertial>
      <origin xyz="0 0 0" rpy="0 0 0"/>
      <mass value="0"/>
      <inertia ixx="0" ixy="0" ixz="0" iyy="0" iyz="0" izz="0"/>
    </inertial>
  </link>
  <joint name="joint18" type="revolute">
    <origin xyz="0 0 0" rpy="0 0 0"/>
    <parent link="link17"/>
    <child link="link18"/>
    <axis xyz="0 1 0"/>
    <limit lower="-1.5707963267948965579989817342720925807952880859375000000000000000" upper="1.5707963267948965579989817342720925807952880859375000000000000000"/>
  </joint>
  <link name="link19">
    <inertial>
      <origin xyz="0 0 0" rpy="0 0 0"/>
      <mass value="0.0200000000000000004163336342344337026588618755340576171875000000"/>
      <inertia ixx="1" ixy="0" ixz="0" iyy="1" iyz="0" izz="1"/>
    </inertial>
    <visual>
      <origin xyz="0 0 0" rpy="0 0 0"/>
      <geometry>
        <mesh filename="meshes/visual/mesh5.obj"/>
      </geometry>
    </visual>
    <collision>
      <origin xyz="0 0 0" rpy="0 0 0"/>
      <geometry>
        <mesh filename="meshes/collision/mesh5.obj"/>
      </geometry>
    </collision>
  </link>
  <joint name="joint19" type="revolute">
    <origin xyz="0 0 0" rpy="0 0 0"/>
    <parent link="link18"/>
    <child link="link19"/>
    <axis xyz="0 0 1"/>
    <limit lower="-3.1415926535897931159979634685441851615905761718750000000000000000" upper="3.1415926535897931159979634685441851615905761718750000000000000000"/>
  </joint>
  <link name="link20">
    <inertial>
      <origin xyz="0 0 0" rpy="0 0 0"/>
      <mass value="0"/>
      <inertia ixx="0" ixy="0" ixz="0" iyy="0" iyz="0" izz="0"/>
    </inertial>
  </link>
  <joint name="joint20" type="revolute">
    <origin xyz="0.0304236576899646962712786546489951433613896369934082031250000000 0.0018592221705754771385321610921437240904197096824645996093750000 -0.0059811434069332106155947315073717618361115455627441406250000000" rpy="0 0 0"/>
    <parent link="link19"/>
    <child link="link20"/>
    <axis xyz="1 0 0"/>
    <limit lower="-3.1415926535897931159979634685441851615905761718750000000000000000" upper="3.1415926535897931159979634685441851615905761718750000000000000000"/>
  </joint>
  <link name="link21">
    <inertial>
      <origin xyz="0 0 0" rpy="0 0 0"/>
      <mass value="0"/>
      <inertia ixx="0" ixy="0" ixz="0" iyy="0" iyz="0" izz="0"/>
    </inertial>
  </link>
  <joint name="joint21" type="revolute">
    <origin xyz="0 0 0" rpy="0 0 0"/>
    <parent link="link20"/>
    <child link="link21"/>
    <axis xyz="0 1 0"/>
    <limit lower="-1.5707963267948965579989817342720925807952880859375000000000000000" upper="1.5707963267948965579989817342720925807952880859375000000000000000"/>
  </joint>
  <link name="link22">
    <inertial>
      <origin xyz="0 0 0" rpy="0 0 0"/>
      <mass value="0.0200000000000000004163336342344337026588618755340576171875000000"/>
      <inertia ixx="1" ixy="0" ixz="0" iyy="1" iyz="0" izz="1"/>
    </inertial>
    <visual>
      <origin xyz="0 0 0" rpy="0 0 0"/>
      <geometry>
        <mesh filename="meshes/visual/mesh6.obj"/>
      </geometry>
    </visual>
    <collision>
      <origin xyz="0 0 0" rpy="0 0 0"/>
      <geometry>
        <mesh filename="meshes/collision/mesh6.obj"/>
      </geometry>
    </collision>
  </link>
  <joint name="joint22" type="revolute">
    <origin xyz="0 0 0" rpy="0 0 0"/>
    <parent link="link21"/>
    <child link="link22"/>
    <axis xyz="0 0 1"/>
    <limit lower="-3.1415926535897931159979634685441851615905761718750000000000000000" upper="3.1415926535897931159979634685441851615905761718750000000000000000"/>
  </joint>
  <link name="link23">
    <inertial>
      <origin xyz="0 0 0" rpy="0 0 0"/>
      <mass value="0"/>
      <inertia ixx="0" ixy="0" ixz="0" iyy="0" iyz="0" izz="0"/>
    </inertial>
  </link>
  <joint name="joint23" type="revolute">
    <origin xyz="0.0223863166108440488077935270894158747978508472442626953125000000 -0.0012460204866201682327719879594951635226607322692871093750000000 -0.0041806739248683374987614058682083850726485252380371093750000000" rpy="0 0 0"/>
    <parent link="link22"/>
    <child link="link23"/>
    <axis xyz="1 0 0"/>
    <limit lower="-3.1415926535897931159979634685441851615905761718750000000000000000" upper="3.1415926535897931159979634685441851615905761718750000000000000000"/>
  </joint>
  <link name="link24">
    <inertial>
      <origin xyz="0 0 0" rpy="0 0 0"/>
      <mass value="0"/>
      <inertia ixx="0" ixy="0" ixz="0" iyy="0" iyz="0" izz="0"/>
    </inertial>
  </link>
  <joint name="joint24" type="revolute">
    <origin xyz="0 0 0" rpy="0 0 0"/>
    <parent link="link23"/>
    <child link="link24"/>
    <axis xyz="0 1 0"/>
    <limit lower="-1.5707963267948965579989817342720925807952880859375000000000000000" upper="1.5707963267948965579989817342720925807952880859375000000000000000"/>
  </joint>
  <link name="link25">
    <inertial>
      <origin xyz="0 0 0" rpy="0 0 0"/>
      <mass value="0.0200000000000000004163336342344337026588618755340576171875000000"/>
      <inertia ixx="1" ixy="0" ixz="0" iyy="1" iyz="0" izz="1"/>
    </inertial>
    <visual>
      <origin xyz="0 0 0" rpy="0 0 0"/>
      <geometry>
        <mesh filename="meshes/visual/mesh7.obj"/>
      </geometry>
    </visual>
    <collision>
      <origin xyz="0 0 0" rpy="0 0 0"/>
      <geometry>
        <mesh filename="meshes/collision/mesh7.obj"/>
      </geometry>
    </collision>
  </link>
  <joint name="joint25" type="revolute">
    <origin xyz="0 0 0" rpy="0 0 0"/>
    <parent link="link24"/>
    <child link="link25"/>
    <axis xyz="0 0 1"/>
    <limit lower="-3.1415926535897931159979634685441851615905761718750000000000000000" upper="3.1415926535897931159979634685441851615905761718750000000000000000"/>
  </joint>
  <link name="link26">
    <inertial>
      <origin xyz="0 0 0" rpy="0 0 0"/>
      <mass value="0"/>
      <inertia ixx="0" ixy="0" ixz="0" iyy="0" iyz="0" izz="0"/>
    </inertial>
  </link>
  <joint name="joint26" type="revolute">
    <origin xyz="0.0678818638664469981014448762834945227950811386108398437500000000 -0.0101055819480794922826660808823362458497285842895507812500000000 -0.0431269025270708400432440043914539273828268051147460937500000000" rpy="0 0 0"/>
    <parent link="link7"/>
    <child link="link26"/>
    <axis xyz="1 0 0"/>
    <limit lower="-3.1415926535897931159979634685441851615905761718750000000000000000" upper="3.1415926535897931159979634685441851615905761718750000000000000000"/>
  </joint>
  <link name="link27">
    <inertial>
      <origin xyz="0 0 0" rpy="0 0 0"/>
      <mass value="0"/>
      <inertia ixx="0" ixy="0" ixz="0" iyy="0" iyz="0" izz="0"/>
    </inertial>
  </link>
  <joint name="joint27" type="revolute">
    <origin xyz="0 0 0" rpy="0 0 0"/>
    <parent link="link26"/>
    <child link="link27"/>
    <axis xyz="0 1 0"/>
    <limit lower="-1.5707963267948965579989817342720925807952880859375000000000000000" upper="1.5707963267948965579989817342720925807952880859375000000000000000"/>
  </joint>
  <link name="link28">
    <inertial>
      <origin xyz="0 0 0" rpy="0 0 0"/>
      <mass value="0.0200000000000000004163336342344337026588618755340576171875000000"/>
      <inertia ixx="1" ixy="0" ixz="0" iyy="1" iyz="0" izz="1"/>
    </inertial>
    <visual>
      <origin xyz="0 0 0" rpy="0 0 0"/>
      <geometry>
        <mesh filename="meshes/visual/mesh8.obj"/>
      </geometry>
    </visual>
    <collision>
      <origin xyz="0 0 0" rpy="0 0 0"/>
      <geometry>
        <mesh filename="meshes/collision/mesh8.obj"/>
      </geometry>
    </collision>
  </link>
  <joint name="joint28" type="revolute">
    <origin xyz="0 0 0" rpy="0 0 0"/>
    <parent link="link27"/>
    <child link="link28"/>
    <axis xyz="0 0 1"/>
    <limit lower="-3.1415926535897931159979634685441851615905761718750000000000000000" upper="3.1415926535897931159979634685441851615905761718750000000000000000"/>
  </joint>
  <link name="link29">
    <inertial>
      <origin xyz="0 0 0" rpy="0 0 0"/>
      <mass value="0"/>
      <inertia ixx="0" ixy="0" ixz="0" iyy="0" iyz="0" izz="0"/>
    </inertial>
  </link>
  <joint name="joint29" type="revolute">
    <origin xyz="0.0169244333167226160274942969863332109525799751281738281250000000 0.0003032112881401136106340743481268873438239097595214843750000000 -0.0126634290979962677026193773599516134709119796752929687500000000" rpy="0 0 0"/>
    <parent link="link28"/>
    <child link="link29"/>
    <axis xyz="1 0 0"/>
    <limit lower="-3.1415926535897931159979634685441851615905761718750000000000000000" upper="3.1415926535897931159979634685441851615905761718750000000000000000"/>
  </joint>
  <link name="link30">
    <inertial>
      <origin xyz="0 0 0" rpy="0 0 0"/>
      <mass value="0"/>
      <inertia ixx="0" ixy="0" ixz="0" iyy="0" iyz="0" izz="0"/>
    </inertial>
  </link>
  <joint name="joint30" type="revolute">
    <origin xyz="0 0 0" rpy="0 0 0"/>
    <parent link="link29"/>
    <child link="link30"/>
    <axis xyz="0 1 0"/>
    <limit lower="-1.5707963267948965579989817342720925807952880859375000000000000000" upper="1.5707963267948965579989817342720925807952880859375000000000000000"/>
  </joint>
  <link name="link31">
    <inertial>
      <origin xyz="0 0 0" rpy="0 0 0"/>
      <mass value="0.0200000000000000004163336342344337026588618755340576171875000000"/>
      <inertia ixx="1" ixy="0" ixz="0" iyy="1" iyz="0" izz="1"/>
    </inertial>
    <visual>
      <origin xyz="0 0 0" rpy="0 0 0"/>
      <geometry>
        <mesh filename="meshes/visual/mesh9.obj"/>
      </geometry>
    </visual>
    <collision>
      <origin xyz="0 0 0" rpy="0 0 0"/>
      <geometry>
        <mesh filename="meshes/collision/mesh9.obj"/>
      </geometry>
    </collision>
  </link>
  <joint name="joint31" type="revolute">
    <origin xyz="0 0 0" rpy="0 0 0"/>
    <parent link="link30"/>
    <child link="link31"/>
    <axis xyz="0 0 1"/>
    <limit lower="-3.1415926535897931159979634685441851615905761718750000000000000000" upper="3.1415926535897931159979634685441851615905761718750000000000000000"/>
  </joint>
  <link name="link32">
    <inertial>
      <origin xyz="0 0 0" rpy="0 0 0"/>
      <mass value="0"/>
      <inertia ixx="0" ixy="0" ixz="0" iyy="0" iyz="0" izz="0"/>
    </inertial>
  </link>
  <joint name="joint32" type="revolute">
    <origin xyz="0.0156853882417684331596063884717295877635478973388671875000000000 -0.0007347294205002985814645377615761390188708901405334472656250000 -0.0107159226247268909992804708508629119023680686950683593750000000" rpy="0 0 0"/>
    <parent link="link31"/>
    <child link="link32"/>
    <axis xyz="1 0 0"/>
    <limit lower="-3.1415926535897931159979634685441851615905761718750000000000000000" upper="3.1415926535897931159979634685441851615905761718750000000000000000"/>
  </joint>
  <link name="link33">
    <inertial>
      <origin xyz="0 0 0" rpy="0 0 0"/>
      <mass value="0"/>
      <inertia ixx="0" ixy="0" ixz="0" iyy="0" iyz="0" izz="0"/>
    </inertial>
  </link>
  <joint name="joint33" type="revolute">
    <origin xyz="0 0 0" rpy="0 0 0"/>
    <parent link="link32"/>
    <child link="link33"/>
    <axis xyz="0 1 0"/>
    <limit lower="-1.5707963267948965579989817342720925807952880859375000000000000000" upper="1.5707963267948965579989817342720925807952880859375000000000000000"/>
  </joint>
  <link name="link34">
    <inertial>
      <origin xyz="0 0 0" rpy="0 0 0"/>
      <mass value="0.0200000000000000004163336342344337026588618755340576171875000000"/>
      <inertia ixx="1" ixy="0" ixz="0" iyy="1" iyz="0" izz="1"/>
    </inertial>
    <visual>
      <origin xyz="0 0 0" rpy="0 0 0"/>
      <geometry>
        <mesh filename="meshes/visual/mesh10.obj"/>
      </geometry>
    </visual>
    <collision>
      <origin xyz="0 0 0" rpy="0 0 0"/>
      <geometry>
        <mesh filename="meshes/collision/mesh10.obj"/>
      </geometry>
    </collision>
  </link>
  <joint name="joint34" type="revolute">
    <origin xyz="0 0 0" rpy="0 0 0"/>
    <parent link="link33"/>
    <child link="link34"/>
    <axis xyz="0 0 1"/>
    <limit lower="-3.1415926535897931159979634685441851615905761718750000000000000000" upper="3.1415926535897931159979634685441851615905761718750000000000000000"/>
  </joint>
  <link name="link35">
    <inertial>
      <origin xyz="0 0 0" rpy="0 0 0"/>
      <mass value="0"/>
      <inertia ixx="0" ixy="0" ixz="0" iyy="0" iyz="0" izz="0"/>
    </inertial>
  </link>
  <joint name="joint35" type="revolute">
    <origin xyz="0.0807135451864298553159571270043670665472745895385742187500000000 -0.0043156504707751756552691624335693632019683718681335449218750000 -0.0266280902263236786409184020385509938932955265045166015625000000" rpy="0 0 0"/>
    <parent link="link7"/>
    <child link="link35"/>
    <axis xyz="1 0 0"/>
    <limit lower="-3.1415926535897931159979634685441851615905761718750000000000000000" upper="3.1415926535897931159979634685441851615905761718750000000000000000"/>
  </joint>
  <link name="link36">
    <inertial>
      <origin xyz="0 0 0" rpy="0 0 0"/>
      <mass value="0"/>
      <inertia ixx="0" ixy="0" ixz="0" iyy="0" iyz="0" izz="0"/>
    </inertial>
  </link>
  <joint name="joint36" type="revolute">
    <origin xyz="0 0 0" rpy="0 0 0"/>
    <parent link="link35"/>
    <child link="link36"/>
    <axis xyz="0 1 0"/>
    <limit lower="-1.5707963267948965579989817342720925807952880859375000000000000000" upper="1.5707963267948965579989817342720925807952880859375000000000000000"/>
  </joint>
  <link name="link37">
    <inertial>
      <origin xyz="0 0 0" rpy="0 0 0"/>
      <mass value="0.0200000000000000004163336342344337026588618755340576171875000000"/>
      <inertia ixx="1" ixy="0" ixz="0" iyy="1" iyz="0" izz="1"/>
    </inertial>
    <visual>
      <origin xyz="0 0 0" rpy="0 0 0"/>
      <geometry>
        <mesh filename="meshes/visual/mesh11.obj"/>
      </geometry>
    </visual>
    <collision>
      <origin xyz="0 0 0" rpy="0 0 0"/>
      <geometry>
        <mesh filename="meshes/collision/mesh11.obj"/>
      </geometry>
    </collision>
  </link>
  <joint name="joint37" type="revolute">
    <origin xyz="0 0 0" rpy="0 0 0"/>
    <parent link="link36"/>
    <child link="link37"/>
    <axis xyz="0 0 1"/>
    <limit lower="-3.1415926535897931159979634685441851615905761718750000000000000000" upper="3.1415926535897931159979634685441851615905761718750000000000000000"/>
  </joint>
  <link name="link38">
    <inertial>
      <origin xyz="0 0 0" rpy="0 0 0"/>
      <mass value="0"/>
      <inertia ixx="0" ixy="0" ixz="0" iyy="0" iyz="0" izz="0"/>
    </inertial>
  </link>
  <joint name="joint38" type="revolute">
    <origin xyz="0.0274844927811400546735498551242926623672246932983398437500000000 0.0019928869544558365511921493862246279604732990264892578125000000 -0.0057250006817996454411279216856200946494936943054199218750000000" rpy="0 0 0"/>
    <parent link="link37"/>
    <child link="link38"/>
    <axis xyz="1 0 0"/>
    <limit lower="-3.1415926535897931159979634685441851615905761718750000000000000000" upper="3.1415926535897931159979634685441851615905761718750000000000000000"/>
  </joint>
  <link name="link39">
    <inertial>
      <origin xyz="0 0 0" rpy="0 0 0"/>
      <mass value="0"/>
      <inertia ixx="0" ixy="0" ixz="0" iyy="0" iyz="0" izz="0"/>
    </inertial>
  </link>
  <joint name="joint39" type="revolute">
    <origin xyz="0 0 0" rpy="0 0 0"/>
    <parent link="link38"/>
    <child link="link39"/>
    <axis xyz="0 1 0"/>
    <limit lower="-1.5707963267948965579989817342720925807952880859375000000000000000" upper="1.5707963267948965579989817342720925807952880859375000000000000000"/>
  </joint>
  <link name="link40">
    <inertial>
      <origin xyz="0 0 0" rpy="0 0 0"/>
      <mass value="0.0200000000000000004163336342344337026588618755340576171875000000"/>
      <inertia ixx="1" ixy="0" ixz="0" iyy="1" iyz="0" izz="1"/>
    </inertial>
    <visual>
      <origin xyz="0 0 0" rpy="0 0 0"/>
      <geometry>
        <mesh filename="meshes/visual/mesh12.obj"/>
      </geometry>
    </visual>
    <collision>
      <origin xyz="0 0 0" rpy="0 0 0"/>
      <geometry>
        <mesh filename="meshes/collision/mesh12.obj"/>
      </geometry>
    </collision>
  </link>
  <joint name="joint40" type="revolute">
    <origin xyz="0 0 0" rpy="0 0 0"/>
    <parent link="link39"/>
    <child link="link40"/>
    <axis xyz="0 0 1"/>
    <limit lower="-3.1415926535897931159979634685441851615905761718750000000000000000" upper="3.1415926535897931159979634685441851615905761718750000000000000000"/>
  </joint>
  <link name="link41">
    <inertial>
      <origin xyz="0 0 0" rpy="0 0 0"/>
      <mass value="0"/>
      <inertia ixx="0" ixy="0" ixz="0" iyy="0" iyz="0" izz="0"/>
    </inertial>
  </link>
  <joint name="joint41" type="revolute">
    <origin xyz="0.0227829462043761046818879378861311124637722969055175781250000000 -0.0020271312764649565552055321404623100534081459045410156250000000 -0.0080318642500197302835918122809744090773165225982666015625000000" rpy="0 0 0"/>
    <parent link="link40"/>
    <child link="link41"/>
    <axis xyz="1 0 0"/>
    <limit lower="-3.1415926535897931159979634685441851615905761718750000000000000000" upper="3.1415926535897931159979634685441851615905761718750000000000000000"/>
  </joint>
  <link name="link42">
    <inertial>
      <origin xyz="0 0 0" rpy="0 0 0"/>
      <mass value="0"/>
      <inertia ixx="0" ixy="0" ixz="0" iyy="0" iyz="0" izz="0"/>
    </inertial>
  </link>
  <joint name="joint42" type="revolute">
    <origin xyz="0 0 0" rpy="0 0 0"/>
    <parent link="link41"/>
    <child link="link42"/>
    <axis xyz="0 1 0"/>
    <limit lower="-1.5707963267948965579989817342720925807952880859375000000000000000" upper="1.5707963267948965579989817342720925807952880859375000000000000000"/>
  </joint>
  <link name="link43">
    <inertial>
      <origin xyz="0 0 0" rpy="0 0 0"/>
      <mass value="0.0200000000000000004163336342344337026588618755340576171875000000"/>
      <inertia ixx="1" ixy="0" ixz="0" iyy="1" iyz="0" izz="1"/>
    </inertial>
    <visual>
      <origin xyz="0 0 0" rpy="0 0 0"/>
      <geometry>
        <mesh filename="meshes/visual/mesh13.obj"/>
      </geometry>
    </visual>
    <collision>
      <origin xyz="0 0 0" rpy="0 0 0"/>
      <geometry>
        <mesh filename="meshes/collision/mesh13.obj"/>
      </geometry>
    </collision>
  </link>
  <joint name="joint43" type="revolute">
    <origin xyz="0 0 0" rpy="0 0 0"/>
    <parent link="link42"/>
    <child link="link43"/>
    <axis xyz="0 0 1"/>
    <limit lower="-3.1415926535897931159979634685441851615905761718750000000000000000" upper="3.1415926535897931159979634685441851615905761718750000000000000000"/>
  </joint>
  <link name="link44">
    <inertial>
      <origin xyz="0 0 0" rpy="0 0 0"/>
      <mass value="0"/>
      <inertia ixx="0" ixy="0" ixz="0" iyy="0" iyz="0" izz="0"/>
    </inertial>
  </link>
  <joint name="joint44" type="revolute">
    <origin xyz="0.0235614408867510505274367460515350103378295898437500000000000000 -0.0156643714894258850867103660675638820976018905639648437500000000 0.0257184579411515248925645948929741280153393745422363281250000000" rpy="0 0 0"/>
    <parent link="link7"/>
    <child link="link44"/>
    <axis xyz="1 0 0"/>
    <limit lower="-3.1415926535897931159979634685441851615905761718750000000000000000" upper="3.1415926535897931159979634685441851615905761718750000000000000000"/>
  </joint>
  <link name="link45">
    <inertial>
      <origin xyz="0 0 0" rpy="0 0 0"/>
      <mass value="0"/>
      <inertia ixx="0" ixy="0" ixz="0" iyy="0" iyz="0" izz="0"/>
    </inertial>
  </link>
  <joint name="joint45" type="revolute">
    <origin xyz="0 0 0" rpy="0 0 0"/>
    <parent link="link44"/>
    <child link="link45"/>
    <axis xyz="0 1 0"/>
    <limit lower="-1.5707963267948965579989817342720925807952880859375000000000000000" upper="1.5707963267948965579989817342720925807952880859375000000000000000"/>
  </joint>
  <link name="link46">
    <inertial>
      <origin xyz="0 0 0" rpy="0 0 0"/>
      <mass value="0.0200000000000000004163336342344337026588618755340576171875000000"/>
      <inertia ixx="1" ixy="0" ixz="0" iyy="1" iyz="0" izz="1"/>
    </inertial>
    <visual>
      <origin xyz="0 0 0" rpy="0 0 0"/>
      <geometry>
        <mesh filename="meshes/visual/mesh14.obj"/>
      </geometry>
    </visual>
    <collision>
      <origin xyz="0 0 0" rpy="0 0 0"/>
      <geometry>
        <mesh filename="meshes/collision/mesh14.obj"/>
      </geometry>
    </collision>
  </link>
  <joint name="joint46" type="revolute">
    <origin xyz="0 0 0" rpy="0 0 0"/>
    <parent link="link45"/>
    <child link="link46"/>
    <axis xyz="0 0 1"/>
    <limit lower="-3.1415926535897931159979634685441851615905761718750000000000000000" upper="3.1415926535897931159979634685441851615905761718750000000000000000"/>
  </joint>
  <link name="link47">
    <inertial>
      <origin xyz="0 0 0" rpy="0 0 0"/>
      <mass value="0"/>
      <inertia ixx="0" ixy="0" ixz="0" iyy="0" iyz="0" izz="0"/>
    </inertial>
  </link>
  <joint name="joint47" type="revolute">
    <origin xyz="0.0192641303409058634033002022079017478972673416137695312500000000 0.0007397891128288480722119402344105765223503112792968750000000000 0.0240389540638029503005768106049799825996160507202148437500000000" rpy="0 0 0"/>
    <parent link="link46"/>
    <child link="link47"/>
    <axis xyz="1 0 0"/>
    <limit lower="-3.1415926535897931159979634685441851615905761718750000000000000000" upper="3.1415926535897931159979634685441851615905761718750000000000000000"/>
  </joint>
  <link name="link48">
    <inertial>
      <origin xyz="0 0 0" rpy="0 0 0"/>
      <mass value="0"/>
      <inertia ixx="0" ixy="0" ixz="0" iyy="0" iyz="0" izz="0"/>
    </inertial>
  </link>
  <joint name="joint48" type="revolute">
    <origin xyz="0 0 0" rpy="0 0 0"/>
    <parent link="link47"/>
    <child link="link48"/>
    <axis xyz="0 1 0"/>
    <limit lower="-1.5707963267948965579989817342720925807952880859375000000000000000" upper="1.5707963267948965579989817342720925807952880859375000000000000000"/>
  </joint>
  <link name="link49">
    <inertial>
      <origin xyz="0 0 0" rpy="0 0 0"/>
      <mass value="0.0200000000000000004163336342344337026588618755340576171875000000"/>
      <inertia ixx="1" ixy="0" ixz="0" iyy="1" iyz="0" izz="1"/>
    </inertial>
    <visual>
      <origin xyz="0 0 0" rpy="0 0 0"/>
      <geometry>
        <mesh filename="meshes/visual/mesh15.obj"/>
      </geometry>
    </visual>
    <collision>
      <origin xyz="0 0 0" rpy="0 0 0"/>
      <geometry>
        <mesh filename="meshes/collision/mesh15.obj"/>
      </geometry>
    </collision>
  </link>
  <joint name="joint49" type="revolute">
    <origin xyz="0 0 0" rpy="0 0 0"/>
    <parent link="link48"/>
    <child link="link49"/>
    <axis xyz="0 0 1"/>
    <limit lower="-3.1415926535897931159979634685441851615905761718750000000000000000" upper="3.1415926535897931159979634685441851615905761718750000000000000000"/>
  </joint>
  <link name="link50">
    <inertial>
      <origin xyz="0 0 0" rpy="0 0 0"/>
      <mass value="0"/>
      <inertia ixx="0" ixy="0" ixz="0" iyy="0" iyz="0" izz="0"/>
    </inertial>
  </link>
  <joint name="joint50" type="revolute">
    <origin xyz="0.0218790519960177995417716090287285624071955680847167968750000000 -0.0058661922094563785645693343440143507905304431915283203125000000 0.0148257060200065252097978429901559138670563697814941406250000000" rpy="0 0 0"/>
    <parent link="link49"/>
    <child link="link50"/>
    <axis xyz="1 0 0"/>
    <limit lower="-3.1415926535897931159979634685441851615905761718750000000000000000" upper="3.1415926535897931159979634685441851615905761718750000000000000000"/>
  </joint>
  <link name="link51">
    <inertial>
      <origin xyz="0 0 0" rpy="0 0 0"/>
      <mass value="0"/>
      <inertia ixx="0" ixy="0" ixz="0" iyy="0" iyz="0" izz="0"/>
    </inertial>
  </link>
  <joint name="joint51" type="revolute">
    <origin xyz="0 0 0" rpy="0 0 0"/>
    <parent link="link50"/>
    <child link="link51"/>
    <axis xyz="0 1 0"/>
    <limit lower="-1.5707963267948965579989817342720925807952880859375000000000000000" upper="1.5707963267948965579989817342720925807952880859375000000000000000"/>
  </joint>
  <link name="link52">
    <inertial>
      <origin xyz="0 0 0" rpy="0 0 0"/>
      <mass value="0.0200000000000000004163336342344337026588618755340576171875000000"/>
      <inertia ixx="1" ixy="0" ixz="0" iyy="1" iyz="0" izz="1"/>
    </inertial>
    <visual>
      <origin xyz="0 0 0" rpy="0 0 0"/>
      <geometry>
        <mesh filename="meshes/visual/mesh16.obj"/>
      </geometry>
    </visual>
    <collision>
      <origin xyz="0 0 0" rpy="0 0 0"/>
      <geometry>
        <mesh filename="meshes/collision/mesh16.obj"/>
      </geometry>
    </collision>
  </link>
  <joint name="joint52" type="revolute">
    <origin xyz="0 0 0" rpy="0 0 0"/>
    <parent link="link51"/>
    <child link="link52"/>
    <axis xyz="0 0 1"/>
    <limit lower="-3.1415926535897931159979634685441851615905761718750000000000000000" upper="3.1415926535897931159979634685441851615905761718750000000000000000"/>
  </joint>
</robot>
