<?xml version="1.0" ?>
<!-- =================================================================================== -->
<!-- |    This document was autogenerated by xacro from galbot_zero_left_arm.xacro     | -->
<!-- |    EDITING THIS FILE BY HAND IS NOT RECOMMENDED                                 | -->
<!-- =================================================================================== -->
<!-- #####################################################################################
#
# Copyright (c) 2023 Galbot, Inc. All Rights Reserved.
#
# This software contains confidential and proprietary information of Galbot, Inc.
# ("Confidential Information"). You shall not disclose such Confidential Information
# and shall use it only in accordance with the terms of the license agreement you
# entered into with Galbot, Inc.
#
# UNAUTHORIZED COPYING, USE, OR DISTRIBUTION OF THIS SOFTWARE, OR ANY PORTION OR
# DERIVATIVE THEREOF, IS STRICTLY PROHIBITED. IF YOU HAVE RECEIVED THIS SOFTWARE IN
# ERROR, PLEASE NOTIFY GALBOT, INC. IMMEDIATELY AND DELETE IT FROM YOUR SYSTEM.
#
#####################################################################################
#
# Description: Xacro file for Galbot Zero left arm, specified in the sapien
# Version: 1.2
# Date: 2023-10-23
# Author: Herman Ye@Galbot
# Warning: Do not use this file if you are not using Sapien.
#
##################################################################################### -->
<robot name="galbot_zero">
  <material name="aluminum">
    <color rgba="0.5 0.5 0.5 1"/>
  </material>
  <material name="plastic">
    <color rgba="0.1 0.1 0.1 1"/>
  </material>
  <!-- Links and joints -->
  <!-- Base Link -->
  <link name="base_link"/>
  <joint name="body_torsor_joint" type="fixed">
    <origin rpy="-1.5707963267948966 0 0" xyz="0 0 0"/>
    <parent link="base_link"/>
    <child link="body_torsor_link"/>
  </joint>
  <link name="body_torsor_link">
    <inertial>
      <origin rpy="0 0 0" xyz="-3.2856E-16 -0.25 1.9205E-16"/>
      <mass value="2.3843"/>
      <inertia ixx="0.051451" ixy="-3.3965E-18" ixz="-1.0893E-18" iyy="0.0035563" iyz="3.1593E-17" izz="0.051451"/>
    </inertial>
    <visual>
      <origin rpy="0 0 0" xyz="0 0 0"/>
      <geometry>
        <mesh filename="package://galbot_description/meshes/body/torsor.stl"/>
      </geometry>
      <material name="">
        <color rgba="0.89804 0.91765 0.92941 1"/>
      </material>
    </visual>
    <collision>
      <origin rpy="0 0 0" xyz="0 0 0"/>
      <geometry>
        <mesh filename="package://galbot_description/meshes/body/torsor.stl"/>
      </geometry>
    </collision>
  </link>
  <joint name="left_arm_base_flange_joint" type="fixed">
    <origin rpy="1.5707963267948966 0 -3.141592653589793" xyz="0 -0.25 0.05"/>
    <parent link="body_torsor_link"/>
    <child link="left_arm_base_flange_link"/>
  </joint>
  <link name="left_arm_base_flange_link">
    <inertial>
      <origin rpy="0 0 0" xyz="-7.3881E-16 -0.0050299 5.553E-05"/>
      <mass value="0.23875"/>
      <inertia ixx="0.00045751" ixy="4.3311E-20" ixz="-8.3752E-20" iyy="0.00078066" iyz="-3.9686E-10" izz="0.00032714"/>
    </inertial>
    <visual>
      <origin rpy="0 0 0" xyz="0 0 0"/>
      <geometry>
        <mesh filename="package://galbot_description/meshes/adapter/arm_base_flange.stl"/>
      </geometry>
      <material name="">
        <color rgba="0.89804 0.91765 0.92941 1"/>
      </material>
    </visual>
    <collision>
      <origin rpy="0 0 0" xyz="0 0 0"/>
      <geometry>
        <mesh filename="package://galbot_description/meshes/adapter/arm_base_flange.stl"/>
      </geometry>
    </collision>
  </link>
  <joint name="left_arm_joint" type="fixed">
    <origin rpy="-1.5707963267948966 -1.5707963267948966 0" xyz="0.0 0.0 0.0"/>
    <parent link="left_arm_base_flange_link"/>
    <child link="left_arm_base_link"/>
  </joint>
  <link name="left_arm_base_link">
    <inertial>
      <origin rpy="0 0 0" xyz="-0.000433277303987328 -3.54664423471128E-05 0.0599427668933796"/>
      <mass value="0.841070778135659"/>
      <inertia ixx="0.0017261110801622" ixy="2.52746264980217E-06" ixz="-3.67690303614961E-05" iyy="0.00170987405835604" iyz="1.67996364994424E-06" izz="0.000904023422915791"/>
    </inertial>
    <visual>
      <origin rpy="0 0 0" xyz="0 0 0"/>
      <geometry>
        <mesh filename="package://galbot_description/meshes/arm/realman_rm65_base_link.stl"/>
      </geometry>
      <material name="">
        <color rgba="1 1 1 1"/>
      </material>
    </visual>
    <collision>
      <origin rpy="0 0 0" xyz="0 0 0"/>
      <geometry>
        <mesh filename="package://galbot_description/meshes/arm/realman_rm65_base_link.stl"/>
      </geometry>
    </collision>
  </link>
  <link name="left_arm_link1">
    <inertial>
      <origin rpy="0 0 0" xyz="1.2226305431569E-08 0.0211079974844683 -0.0251854220842269"/>
      <mass value="0.593563443690403"/>
      <inertia ixx="0.00126614120341847" ixy="-1.294980943835E-08" ixz="-9.80120923066996E-09" iyy="0.00118168178300364" iyz="-0.00021121727444415" izz="0.00056135241627747"/>
    </inertial>
    <visual>
      <origin rpy="0 0 0" xyz="0 0 0"/>
      <geometry>
        <mesh filename="package://galbot_description/meshes/arm/realman_rm65_link1.stl"/>
      </geometry>
      <material name="">
        <color rgba="1 1 1 1"/>
      </material>
    </visual>
    <collision>
      <origin rpy="0 0 0" xyz="0 0 0"/>
      <geometry>
        <mesh filename="package://galbot_description/meshes/arm/realman_rm65_link1.stl"/>
      </geometry>
    </collision>
  </link>
  <joint name="left_arm_joint1" type="revolute">
    <origin rpy="0 0 0" xyz="0 0 0.2405"/>
    <parent link="left_arm_base_link"/>
    <child link="left_arm_link1"/>
    <axis xyz="0 0 1"/>
    <limit effort="60" lower="-3.1" upper="3.1" velocity="3.14"/>
    <dynamics damping="0.5" friction="0"/>
  </joint>
  <link name="left_arm_link2">
    <inertial>
      <origin rpy="0 0 0" xyz="0.152256463426163 4.75383656106654E-07 -0.00620260383607792"/>
      <mass value="0.864175046869043"/>
      <inertia ixx="0.00089150298478414" ixy="-2.23268489334765E-08" ixz="0.00156246461035015" iyy="0.00733754343083901" iyz="6.28110889329165E-09" izz="0.00697869103915473"/>
    </inertial>
    <visual>
      <origin rpy="0 0 0" xyz="0 0 0"/>
      <geometry>
        <mesh filename="package://galbot_description/meshes/arm/realman_rm65_link2.stl"/>
      </geometry>
      <material name="">
        <color rgba="1 1 1 1"/>
      </material>
    </visual>
    <collision>
      <origin rpy="0 0 0" xyz="0 0 0"/>
      <geometry>
        <mesh filename="package://galbot_description/meshes/arm/realman_rm65_link2.stl"/>
      </geometry>
    </collision>
  </link>
  <joint name="left_arm_joint2" type="revolute">
    <origin rpy="1.5708 -1.5708 0" xyz="0 0 0"/>
    <parent link="left_arm_link1"/>
    <child link="left_arm_link2"/>
    <axis xyz="0 0 1"/>
    <limit effort="60" lower="-2.268" upper="2.268" velocity="3.14"/>
    <dynamics damping="0.5" friction="0"/>
  </joint>
  <link name="left_arm_link3">
    <inertial>
      <origin rpy="0 0 0" xyz="5.05312670989961E-06 -0.0595925663694732 0.010569069212336"/>
      <mass value="0.289633681624654"/>
      <inertia ixx="0.00063737100450158" ixy="-7.05261293649751E-08" ixz="-3.86643272239426E-08" iyy="0.00015648388095025" iyz="-0.00014461035994916" izz="0.000614178164773085"/>
    </inertial>
    <visual>
      <origin rpy="0 0 0" xyz="0 0 0"/>
      <geometry>
        <mesh filename="package://galbot_description/meshes/arm/realman_rm65_link3.stl"/>
      </geometry>
      <material name="">
        <color rgba="1 1 1 1"/>
      </material>
    </visual>
    <collision>
      <origin rpy="0 0 0" xyz="0 0 0"/>
      <geometry>
        <mesh filename="package://galbot_description/meshes/arm/realman_rm65_link3.stl"/>
      </geometry>
    </collision>
  </link>
  <joint name="left_arm_joint3" type="revolute">
    <origin rpy="0 0 1.5708" xyz="0.256 0 0"/>
    <parent link="left_arm_link2"/>
    <child link="left_arm_link3"/>
    <axis xyz="0 0 1"/>
    <limit effort="30" lower="-2.355" upper="2.355" velocity="3.92"/>
    <dynamics damping="0.5" friction="0"/>
  </joint>
  <link name="left_arm_link4">
    <inertial>
      <origin rpy="0 0 0" xyz="1.15516617405898E-06 -0.0180424468598241 -0.0215394748352687"/>
      <mass value="0.239419768320061"/>
      <inertia ixx="0.000285938919722783" ixy="3.07101359163101E-09" ixz="-2.21994118981953E-09" iyy="0.000262727540304212" iyz="4.4236583260078E-05" izz="0.000119888082791859"/>
    </inertial>
    <visual>
      <origin rpy="0 0 0" xyz="0 0 0"/>
      <geometry>
        <mesh filename="package://galbot_description/meshes/arm/realman_rm65_link4.stl"/>
      </geometry>
      <material name="">
        <color rgba="1 1 1 1"/>
      </material>
    </visual>
    <collision>
      <origin rpy="0 0 0" xyz="0 0 0"/>
      <geometry>
        <mesh filename="package://galbot_description/meshes/arm/realman_rm65_link4.stl"/>
      </geometry>
    </collision>
  </link>
  <joint name="left_arm_joint4" type="revolute">
    <origin rpy="1.5708 0 0" xyz="0 -0.21 0"/>
    <parent link="left_arm_link3"/>
    <child link="left_arm_link4"/>
    <axis xyz="0 0 1"/>
    <limit effort="10" lower="-3.1" upper="3.1" velocity="3.92"/>
    <dynamics damping="0.5" friction="0"/>
  </joint>
  <link name="left_arm_link5">
    <inertial>
      <origin rpy="0 0 0" xyz="3.19794786262152E-06 -0.0593808368101458 0.00736804250989326"/>
      <mass value="0.218799761431678"/>
      <inertia ixx="0.000350540363914072" ixy="-3.41781619975602E-08" ixz="-1.77056457224373E-08" iyy="0.000104927867487581" iyz="-7.82431228461971E-05" izz="0.000334482418423629"/>
    </inertial>
    <visual>
      <origin rpy="0 0 0" xyz="0 0 0"/>
      <geometry>
        <mesh filename="package://galbot_description/meshes/arm/realman_rm65_link5.stl"/>
      </geometry>
      <material name="">
        <color rgba="1 1 1 1"/>
      </material>
    </visual>
    <collision>
      <origin rpy="0 0 0" xyz="0 0 0"/>
      <geometry>
        <mesh filename="package://galbot_description/meshes/arm/realman_rm65_link5.stl"/>
      </geometry>
    </collision>
  </link>
  <joint name="left_arm_joint5" type="revolute">
    <origin rpy="-1.5708 0 0" xyz="0 0 0"/>
    <parent link="left_arm_link4"/>
    <child link="left_arm_link5"/>
    <axis xyz="0 0 1"/>
    <limit effort="10" lower="-2.233" upper="2.233" velocity="3.92"/>
    <dynamics damping="0.5" friction="0"/>
  </joint>
  <link name="left_arm_link6">
    <inertial>
      <origin rpy="0 0 0" xyz="0.000714234511756999 -0.000396718732824521 -0.0126723660946126"/>
      <mass value="0.0649018034311231"/>
      <inertia ixx="2.02766547502765E-05" ixy="-1.32505200276849E-06" ixz="-2.5845091522508E-08" iyy="1.87986725225022E-05" iyz="3.39471452125439E-09" izz="3.17885459163081E-05"/>
    </inertial>
    <visual>
      <origin rpy="0 0 0" xyz="0 0 0"/>
      <geometry>
        <mesh filename="package://galbot_description/meshes/arm/realman_rm65_link6.stl"/>
      </geometry>
      <material name="">
        <color rgba="1 1 1 1"/>
      </material>
    </visual>
    <collision>
      <origin rpy="0 0 0" xyz="0 0 0"/>
      <geometry>
        <mesh filename="package://galbot_description/meshes/arm/realman_rm65_link6.stl"/>
      </geometry>
    </collision>
  </link>
  <joint name="left_arm_joint6" type="revolute">
    <origin rpy="1.5708 0 0" xyz="0 -0.144 0"/>
    <parent link="left_arm_link5"/>
    <child link="left_arm_link6"/>
    <axis xyz="0 0 1"/>
    <limit effort="10" lower="-6.28" upper="6.28" velocity="3.92"/>
    <dynamics damping="0.5" friction="0"/>
  </joint>
  <joint name="left_arm_end_effector_flange_joint" type="fixed">
    <origin rpy="1.5707963267948966 0 0" xyz="0 0 0"/>
    <parent link="left_arm_link6"/>
    <child link="left_arm_end_effector_flange_link"/>
  </joint>
  <link name="left_arm_end_effector_flange_link">
    <inertial>
      <origin rpy="0 0 0" xyz="4.16209483160246E-18 0.00278869455734304 1.10989195509399E-18"/>
      <mass value="0.0493002920412636"/>
      <inertia ixx="1.86857135099964E-05" ixy="-1.08650432728053E-22" ixz="6.86973902622073E-21" iyy="2.81507409466306E-05" iyz="5.96925628265955E-23" izz="9.79608865148053E-06"/>
    </inertial>
    <visual>
      <origin rpy="0 0 0" xyz="0 0 0"/>
      <geometry>
        <mesh filename="package://galbot_description/meshes/adapter/arm_end_effector_flange.stl"/>
      </geometry>
      <material name="">
        <color rgba="0.898039215686275 0.917647058823529 0.929411764705882 1"/>
      </material>
    </visual>
    <collision>
      <origin rpy="0 0 0" xyz="0 0 0"/>
      <geometry>
        <mesh filename="package://galbot_description/meshes/adapter/arm_end_effector_flange.stl"/>
      </geometry>
    </collision>
  </link>
  <joint name="left_arm_camera_d415_flange_joint" type="fixed">
    <origin rpy="0 0 0" xyz="0 0 0"/>
    <parent link="left_arm_end_effector_flange_link"/>
    <child link="left_arm_camera_d415_flange_link"/>
  </joint>
  <link name="left_arm_camera_d415_flange_link">
    <inertial>
      <origin rpy="0 0 0" xyz="0.0592822351376299 -0.00148955992172333 -1.22797983111768E-18"/>
      <mass value="0.0176545384826988"/>
      <inertia ixx="7.7882126527069E-06" ixy="9.59349299176604E-09" ixz="6.26265028189193E-22" iyy="2.12052757044674E-05" iyz="1.57916543683687E-22" izz="1.34435410109635E-05"/>
    </inertial>
    <visual>
      <origin rpy="0 0 0" xyz="0 0 0"/>
      <geometry>
        <mesh filename="package://galbot_description/meshes/adapter/camera_d415_flange.stl"/>
      </geometry>
      <material name="">
        <color rgba="0.898039215686275 0.917647058823529 0.929411764705882 1"/>
      </material>
    </visual>
    <collision>
      <origin rpy="0 0 0" xyz="0 0 0"/>
      <geometry>
        <mesh filename="package://galbot_description/meshes/adapter/camera_d415_flange.stl"/>
      </geometry>
    </collision>
  </link>
  <!-- camera body, with origin at bottom screw mount -->
  <joint name="left_arm_camera_joint" type="fixed">
    <origin rpy="-1.5707963267948966 0 1.5707963267948966" xyz="-0.0935 0.01 0"/>
    <parent link="left_arm_end_effector_flange_link"/>
    <child link="left_arm_camera_bottom_screw_frame"/>
  </joint>
  <link name="left_arm_camera_bottom_screw_frame"/>
  <joint name="left_arm_camera_link_joint" type="fixed">
    <origin rpy="0 0 0" xyz="0 0.02 0.0115"/>
    <parent link="left_arm_camera_bottom_screw_frame"/>
    <child link="left_arm_camera_link"/>
  </joint>
  <link name="left_arm_camera_link">
    <visual>
      <origin rpy="1.5707963267948966 0 1.5707963267948966" xyz="0.00987 -0.02 0"/>
      <geometry>
        <mesh filename="package://galbot_description/meshes/camera/camera_d415.stl"/>
      </geometry>
      <material name="aluminum"/>
    </visual>
    <collision>
      <origin rpy="0 0 0" xyz="0 -0.02 0"/>
      <geometry>
        <box size="0.02005 0.099 0.023"/>
      </geometry>
    </collision>
    <inertial>
      <mass value="0.072"/>
      <!-- The following are not reliable values, and should not be used for modeling -->
      <origin xyz="0 0 0"/>
      <inertia ixx="0.003881243" ixy="0.0" ixz="0.0" iyy="0.000498940" iyz="0.0" izz="0.003879257"/>
    </inertial>
  </link>
  <joint name="left_arm_camera_usb_plug_joint" type="fixed">
    <origin rpy="0 0 0" xyz="-0.005999999999999998 -0.0558 0"/>
    <parent link="left_arm_camera_link"/>
    <child link="left_arm_camera_usb_plug_link"/>
  </joint>
  <link name="left_arm_camera_usb_plug_link">
    <visual>
      <!-- 0.044850 0.008000 0.018500 -->
      <origin rpy="0 0 1.5707963267948966" xyz="0. -0.022425 0."/>
      <geometry>
        <!--box
          size="0.044850 0.008 0.0185" /-->
        <mesh filename="package://galbot_description/meshes/camera/camera_d415_plug.stl"/>
      </geometry>
      <material name="plastic"/>
    </visual>
    <collision>
      <origin rpy="0 0 1.5707963267948966" xyz="0. -0.022425 0."/>
      <geometry>
        <!--box
          size="0.044850 0.008 0.0185" /-->
        <mesh filename="package://galbot_description/meshes/camera/camera_d415_plug_collision.stl"/>
      </geometry>
    </collision>
  </link>
  <joint name="gripper_inspire_flange_joint" type="fixed">
    <origin rpy="0 0 0" xyz="0 0 0"/>
    <parent link="left_arm_end_effector_flange_link"/>
    <child link="gripper_inspire_flange_link"/>
  </joint>
  <link name="gripper_inspire_flange_link">
    <inertial>
      <origin rpy="0 0 0" xyz="4.66209947996709E-18 0.00877518164309892 -3.1251302459899E-18"/>
      <mass value="0.0383576184712739"/>
      <inertia ixx="1.61354132282382E-05" ixy="-1.487729570353E-22" ixz="-4.39698194360219E-21" iyy="2.14391936917384E-05" iyz="4.44711891564739E-23" izz="5.57165635757638E-06"/>
    </inertial>
    <visual>
      <origin rpy="0 0 0" xyz="0 0 0"/>
      <geometry>
        <mesh filename="package://galbot_description/meshes/adapter/gripper_inspire_flange.stl"/>
      </geometry>
      <material name="">
        <color rgba="0.898039215686275 0.917647058823529 0.929411764705882 1"/>
      </material>
    </visual>
    <collision>
      <origin rpy="0 0 0" xyz="0 0 0"/>
      <geometry>
        <mesh filename="package://galbot_description/meshes/adapter/gripper_inspire_flange.stl"/>
      </geometry>
    </collision>
  </link>
  <joint name="gripper_inspire_joint" type="fixed">
    <origin rpy="-1.5707963267948966 -1.5707963267948966 0" xyz="0 0.012 0"/>
    <parent link="gripper_inspire_flange_link"/>
    <child link="gripper_inspire_body_link"/>
  </joint>
  <link name="gripper_inspire_body_link">
    <inertial>
      <origin rpy="0 0 0" xyz="1.5645E-05 -4.1843E-06 0.038"/>
      <mass value="0.072633"/>
      <inertia ixx="5.095E-05" ixy="-4.256E-14" ixz="2.0229E-08" iyy="6.0883E-05" iyz="-4.5583E-09" izz="1.933E-05"/>
    </inertial>
    <visual>
      <origin rpy="0 0 0" xyz="0 0 0"/>
      <geometry>
        <mesh filename="package://galbot_description/meshes/gripper/gripper_inspire_body_link.stl"/>
      </geometry>
      <material name="">
        <color rgba="1 1 1 1"/>
      </material>
    </visual>
    <collision>
      <origin rpy="0 0 0" xyz="0 0 0"/>
      <geometry>
        <mesh filename="package://galbot_description/meshes/gripper/gripper_inspire_body_link.stl"/>
      </geometry>
    </collision>
  </link>
  <link name="gripper_inspire_left_link_1">
    <inertial>
      <origin rpy="0 0 0" xyz="-0.018807 -0.0090021 -0.0046901"/>
      <mass value="0.010721"/>
      <inertia ixx="5.1508E-07" ixy="1.2231E-10" ixz="2.8973E-07" iyy="1.5709E-06" iyz="7.2401E-11" izz="1.6904E-06"/>
    </inertial>
    <visual>
      <origin rpy="0 0 0" xyz="0 0 0"/>
      <geometry>
        <mesh filename="package://galbot_description/meshes/gripper/gripper_inspire_left_link_1.stl"/>
      </geometry>
      <material name="">
        <color rgba="0.79216 0.81961 0.93333 1"/>
      </material>
    </visual>
    <collision>
      <origin rpy="0 0 0" xyz="0 0 0"/>
      <geometry>
        <mesh filename="package://galbot_description/meshes/gripper/gripper_inspire_left_link_1.stl"/>
      </geometry>
    </collision>
  </link>
  <joint name="gripper_inspire_left_joint_1" type="prismatic">
    <origin rpy="3.141592653589793 -1.5707963267948966 0" xyz="-0.034907 -0.009 0.12953"/>
    <parent link="gripper_inspire_body_link"/>
    <child link="gripper_inspire_left_link_1"/>
    <axis xyz="-0.00597 0 -0.99998"/>
    <limit effort="0" lower="-0.035" upper="0" velocity="0"/>
  </joint>
  <link name="gripper_inspire_right_link_1">
    <inertial>
      <origin rpy="0 0 0" xyz="-0.018807 0.0089979 -0.0046901"/>
      <mass value="0.010721"/>
      <inertia ixx="5.1508E-07" ixy="1.2231E-10" ixz="2.8973E-07" iyy="1.5709E-06" iyz="7.2401E-11" izz="1.6904E-06"/>
    </inertial>
    <visual>
      <origin rpy="0 0 0" xyz="0 0 0"/>
      <geometry>
        <mesh filename="package://galbot_description/meshes/gripper/gripper_inspire_right_link_1.stl"/>
      </geometry>
      <material name="">
        <color rgba="0.79216 0.81961 0.93333 1"/>
      </material>
    </visual>
    <collision>
      <origin rpy="0 0 0" xyz="0 0 0"/>
      <geometry>
        <mesh filename="package://galbot_description/meshes/gripper/gripper_inspire_right_link_1.stl"/>
      </geometry>
    </collision>
  </link>
  <joint name="gripper_inspire_right_joint_1" type="prismatic">
    <origin rpy="3.141592653589793 -1.5707963267948966 3.141592653589793" xyz="0.034907 -0.009 0.12953"/>
    <parent link="gripper_inspire_body_link"/>
    <child link="gripper_inspire_right_link_1"/>
    <axis xyz="0.00597 0 0.99998"/>
    <limit effort="0" lower="0" upper="0.035" velocity="0"/>
    <mimic joint="gripper_inspire_left_joint_1" multiplier="-1" offset="0"/>
  </joint>
  <!-- Tool Center Point -->
  <link name="gripper_inspire_tcp_frame"/>
  <joint name="tcp_joint" type="fixed">
    <origin rpy="-1.5707963267948966 -1.5707963267948966 0" xyz="0 0 0.13751"/>
    <parent link="gripper_inspire_body_link"/>
    <child link="gripper_inspire_tcp_frame"/>
    <axis xyz="0 0 0"/>
  </joint>
</robot>
