<?xml version="1.0"?>
<!-- #####################################################################################
#
# Copyright (c) 2023 Galbot, Inc. All Rights Reserved.
#
# This software contains confidential and proprietary information of Galbot, Inc.
# ("Confidential Information"). You shall not disclose such Confidential Information
# and shall use it only in accordance with the terms of the license agreement you
# entered into with Galbot, Inc.
#
# UNAUTHORIZED COPYING, USE, OR DISTRIBUTION OF THIS SOFTWARE, OR ANY PORTION OR
# DERIVATIVE THEREOF, IS STRICTLY PROHIBITED. IF YOU HAVE RECEIVED THIS SOFTWARE IN
# ERROR, PLEASE NOTIFY GALBOT, INC. IMMEDIATELY AND DELETE IT FROM YOUR SYSTEM.
#
#####################################################################################
#
# Description: Xacro file for realman rm75-6f arm
# Version: 1.0
# Date: 2023-12-21
# Author: Herman Ye@Galbot
# Notes: This is a modified version of the original file from Realman
#
#####################################################################################
# Revision History:
#
# Date       Version  Author       Description
# 2023-12-21 1.0      Herman Ye    Created.
# 2023-12-22 1.1      Herman Ye    Limit the joint range of joint 7 to [-2pi, 2pi].
#####################################################################################-->

<robot name="realman_rm75_6f" xmlns:xacro="http://www.ros.org/wiki/xacro">

  <!-- links and joints -->
  <xacro:macro name="realman_rm75_6f" params="parent *origin  name:=realman_rm75_6f">
    <xacro:property name="M_PI" value="3.1415926535897931" />

    <joint name="${name}_joint" type="fixed">
      <xacro:insert_block name="origin" />
      <parent link="${parent}" />
      <child link="${name}_base_link" />
    </joint>

    <link name="${name}_base_link">
      <inertial>
        <origin rpy="0 0 0" xyz="0.00043296 3.5291E-05 0.059942" />
        <mass value="0.84105" />
        <inertia ixx="0.0017261" ixy="2.5275E-06" ixz="3.6769E-05" iyy="0.0017099" iyz="-1.68E-06"
          izz="0.00090402" />
      </inertial>
      <visual>
        <origin rpy="0 0 0" xyz="0 0 0" />
        <geometry>
          <mesh filename="package://galbot_description/meshes/arm/realman_rm75_6f_base_link.stl" />
        </geometry>
        <material name="">
          <color rgba="1 1 1 1" />
        </material>
      </visual>
      <collision>
        <origin rpy="0 0 0" xyz="0 0 0" />
        <geometry>
          <mesh filename="package://galbot_description/meshes/arm/realman_rm75_6f_base_link.stl" />
        </geometry>
      </collision>
    </link>
    <link name="${name}_link1">
      <inertial>
        <origin rpy="0 0 0" xyz="-2.1376E-07 0.025186 -0.021108" />
        <mass value="0.59356" />
        <inertia ixx="0.0012661" ixy="-9.8019E-09" ixz="-1.2951E-08" iyy="0.00056135"
          iyz="-0.00021122" izz="0.0011817" />
      </inertial>
      <visual>
        <origin rpy="0 0 0" xyz="0 0 0" />
        <geometry>
          <mesh filename="package://galbot_description/meshes/arm/realman_rm75_6f_link1.stl" />
        </geometry>
        <material name="">
          <color rgba="1 1 1 1" />
        </material>
      </visual>
      <collision>
        <origin rpy="0 0 0" xyz="0 0 0" />
        <geometry>
          <mesh filename="package://galbot_description/meshes/arm/realman_rm75_6f_link1.stl" />
        </geometry>
      </collision>
    </link>
    <joint name="${name}_joint1" type="revolute">
      <origin rpy="-1.5708 0 0" xyz="0 0 0.2405" />
      <parent link="${name}_base_link" />
      <child link="${name}_link1" />
      <axis xyz="0 -1 0" />
      <limit effort="100" lower="-3.107" upper="3.107" velocity="1" />
    </joint>
    <link name="${name}_link2">
      <inertial>
        <origin rpy="0 0 0" xyz="4.1111E-07 0.011078 0.076129" />
        <mass value="0.43285" />
        <inertia ixx="0.0012584" ixy="5.6315E-09" ixz="1.3348E-09" iyy="0.0012225" iyz="0.000279"
          izz="0.00031747" />
      </inertial>
      <visual>
        <origin rpy="0 0 0" xyz="0 0 0" />
        <geometry>
          <mesh filename="package://galbot_description/meshes/arm/realman_rm75_6f_link2.stl" />
        </geometry>
        <material name="">
          <color rgba="1 1 1 1" />
        </material>
      </visual>
      <collision>
        <origin rpy="0 0 0" xyz="0 0 0" />
        <geometry>
          <mesh filename="package://galbot_description/meshes/arm/realman_rm75_6f_link2.stl" />
        </geometry>
      </collision>
    </link>
    <joint name="${name}_joint2" type="revolute">
      <origin rpy="1.5708 0 0" xyz="0 0 0" />
      <parent link="${name}_link1" />
      <child link="${name}_link2" />
      <axis xyz="0 1 0" />
      <limit effort="100" lower="-2.269" upper="2.269" velocity="1" />
    </joint>
    <link name="${name}_link3">
      <inertial>
        <origin rpy="0 0 0" xyz="-4.7932E-07 0.027347 -0.023544" />
        <mass value="0.43132" />
        <inertia ixx="0.00079433" ixy="1.0334E-08" ixz="-2.329E-09" iyy="0.00031507"
          iyz="-0.00014262" izz="0.00073037" />
      </inertial>
      <visual>
        <origin rpy="0 0 0" xyz="0 0 0" />
        <geometry>
          <mesh filename="package://galbot_description/meshes/arm/realman_rm75_6f_link3.stl" />
        </geometry>
        <material name="">
          <color rgba="1 1 1 1" />
        </material>
      </visual>
      <collision>
        <origin rpy="0 0 0" xyz="0 0 0" />
        <geometry>
          <mesh filename="package://galbot_description/meshes/arm/realman_rm75_6f_link3.stl" />
        </geometry>
      </collision>
    </link>
    <joint name="${name}_joint3" type="revolute">
      <origin rpy="-1.5708 0 0" xyz="0 0 0.256" />
      <parent link="${name}_link2" />
      <child link="${name}_link3" />
      <axis xyz="0 -1 0" />
      <limit effort="100" lower="-3.107" upper="3.107" velocity="1" />
    </joint>
    <link name="${name}_link4">
      <inertial>
        <origin rpy="0 0 0" xyz="5.0444E-06 0.010569 0.059593" />
        <mass value="0.28963" />
        <inertia ixx="0.00063737" ixy="-3.8666E-08" ixz="7.0522E-08" iyy="0.00061418"
          iyz="0.00014461" izz="0.00015648" />
      </inertial>
      <visual>
        <origin rpy="0 0 0" xyz="0 0 0" />
        <geometry>
          <mesh filename="package://galbot_description/meshes/arm/realman_rm75_6f_link4.stl" />
        </geometry>
        <material name="">
          <color rgba="1 1 1 1" />
        </material>
      </visual>
      <collision>
        <origin rpy="0 0 0" xyz="0 0 0" />
        <geometry>
          <mesh filename="package://galbot_description/meshes/arm/realman_rm75_6f_link4.stl" />
        </geometry>
      </collision>
    </link>
    <joint name="${name}_joint4" type="revolute">
      <origin rpy="1.5708 0 0" xyz="0 0 0" />
      <parent link="${name}_link3" />
      <child link="${name}_link4" />
      <axis xyz="0 1 0" />
      <limit effort="100" lower="-2.356" upper="2.356" velocity="1" />
    </joint>
    <link name="${name}_link5">
      <inertial>
        <origin rpy="0 0 0" xyz="1.1466E-06 0.021541 -0.018041" />
        <mass value="0.23941" />
        <inertia ixx="0.00028594" ixy="1.8435E-09" ixz="2.6611E-09" iyy="0.00011989"
          iyz="-4.4238E-05" izz="0.00026273" />
      </inertial>
      <visual>
        <origin rpy="0 0 0" xyz="0 0 0" />
        <geometry>
          <mesh filename="package://galbot_description/meshes/arm/realman_rm75_6f_link5.stl" />
        </geometry>
        <material name="">
          <color rgba="1 1 1 1" />
        </material>
      </visual>
      <collision>
        <origin rpy="0 0 0" xyz="0 0 0" />
        <geometry>
          <mesh filename="package://galbot_description/meshes/arm/realman_rm75_6f_link5.stl" />
        </geometry>
      </collision>
    </link>
    <joint name="${name}_joint5" type="revolute">
      <origin rpy="-1.5708 0 0" xyz="0 0 0.21" />
      <parent link="${name}_link4" />
      <child link="${name}_link5" />
      <axis xyz="0 -1 0" />
      <limit effort="100" lower="-3.107" upper="3.107" velocity="1" />
    </joint>
    <link name="${name}_link6">
      <inertial>
        <origin rpy="0 0 0" xyz="4.5754E-06 0.0073681 0.059382" />
        <mass value="0.21879" />
        <inertia ixx="0.00035053" ixy="-1.7437E-08" ixz="3.1653E-08" iyy="0.00033447"
          iyz="7.824E-05" izz="0.00010492" />
      </inertial>
      <visual>
        <origin rpy="0 0 0" xyz="0 0 0" />
        <geometry>
          <mesh filename="package://galbot_description/meshes/arm/realman_rm75_6f_link6.stl" />
        </geometry>
        <material name="">
          <color rgba="1 1 1 1" />
        </material>
      </visual>
      <collision>
        <origin rpy="0 0 0" xyz="0 0 0" />
        <geometry>
          <mesh filename="package://galbot_description/meshes/arm/realman_rm75_6f_link6.stl" />
        </geometry>
      </collision>
    </link>
    <joint name="${name}_joint6" type="revolute">
      <origin rpy="1.5708 0 0" xyz="0 0 0" />
      <parent link="${name}_link5" />
      <child link="${name}_link6" />
      <axis xyz="0 1 0" />
      <limit effort="100" lower="-2.234" upper="2.234" velocity="1" />
    </joint>
    <link name="${name}_link7">
      <inertial>
        <origin rpy="0 0 ${M_PI/6}" xyz="0.00032231 -0.0001782 -0.028676" />
        <mass value="0.14433" />
        <inertia ixx="3.6119E-05" ixy="-1.3242E-06" ixz="-3.2733E-08" iyy="3.4626E-05"
          iyz="7.6694E-09" izz="6.1463E-05" />
      </inertial>
      <visual>
        <origin rpy="0 0 ${M_PI/6}" xyz="0 0 0" />
        <geometry>
          <mesh filename="package://galbot_description/meshes/arm/realman_rm75_6f_link7.stl" />
        </geometry>
        <material name="">
          <color rgba="1 1 1 1" />
        </material>
      </visual>
      <collision>
        <origin rpy="0 0 ${M_PI/6}" xyz="0 0 0" />
        <geometry>
          <mesh filename="package://galbot_description/meshes/arm/realman_rm75_6f_link7.stl" />
        </geometry>
      </collision>
    </link>
    <joint name="${name}_joint7" type="revolute">
      <origin rpy="0 0 0" xyz="0 0 0.1725" />
      <parent link="${name}_link6" />
      <child link="${name}_link7" />
      <axis xyz="0 0 1" />
      <limit effort="100" lower="-6.28" upper="6.28" velocity="1" />
    </joint>
  </xacro:macro>
</robot>