<?xml version="1.0" ?>
<robot name="mano">
  <link name="link0">
    <inertial>
      <origin xyz="0 0 0" rpy="0 0 0"/>
      <mass value="0"/>
      <inertia ixx="0" ixy="0" ixz="0" iyy="0" iyz="0" izz="0"/>
    </inertial>
  </link>
  <link name="link1">
    <inertial>
      <origin xyz="0 0 0" rpy="0 0 0"/>
      <mass value="0"/>
      <inertia ixx="0" ixy="0" ixz="0" iyy="0" iyz="0" izz="0"/>
    </inertial>
  </link>
  <joint name="joint1" type="prismatic">
    <origin xyz="0 0 0" rpy="0 0 0"/>
    <parent link="link0"/>
    <child link="link1"/>
    <axis xyz="1 0 0"/>
    <limit lower="-1000" upper="1000"/>
  </joint>
  <link name="link2">
    <inertial>
      <origin xyz="0 0 0" rpy="0 0 0"/>
      <mass value="0"/>
      <inertia ixx="0" ixy="0" ixz="0" iyy="0" iyz="0" izz="0"/>
    </inertial>
  </link>
  <joint name="joint2" type="prismatic">
    <origin xyz="0 0 0" rpy="0 0 0"/>
    <parent link="link1"/>
    <child link="link2"/>
    <axis xyz="0 1 0"/>
    <limit lower="-1000" upper="1000"/>
  </joint>
  <link name="link3">
    <inertial>
      <origin xyz="0 0 0" rpy="0 0 0"/>
      <mass value="0"/>
      <inertia ixx="0" ixy="0" ixz="0" iyy="0" iyz="0" izz="0"/>
    </inertial>
  </link>
  <joint name="joint3" type="prismatic">
    <origin xyz="0 0 0" rpy="0 0 0"/>
    <parent link="link2"/>
    <child link="link3"/>
    <axis xyz="0 0 1"/>
    <limit lower="-1000" upper="1000"/>
  </joint>
  <link name="link4">
    <inertial>
      <origin xyz="0 0 0" rpy="0 0 0"/>
      <mass value="0"/>
      <inertia ixx="0" ixy="0" ixz="0" iyy="0" iyz="0" izz="0"/>
    </inertial>
  </link>
  <joint name="joint4" type="continuous">
    <origin xyz="0 0 0" rpy="0 0 0"/>
    <parent link="link3"/>
    <child link="link4"/>
    <axis xyz="1 0 0"/>
    <limit lower="1" upper="-1"/>
  </joint>
  <link name="link5">
    <inertial>
      <origin xyz="0 0 0" rpy="0 0 0"/>
      <mass value="0"/>
      <inertia ixx="0" ixy="0" ixz="0" iyy="0" iyz="0" izz="0"/>
    </inertial>
  </link>
  <joint name="joint5" type="continuous">
    <origin xyz="0 0 0" rpy="0 0 0"/>
    <parent link="link4"/>
    <child link="link5"/>
    <axis xyz="0 1 0"/>
    <limit lower="1" upper="-1"/>
  </joint>
  <link name="link6">
    <inertial>
      <origin xyz="0 0 0" rpy="0 0 0"/>
      <mass value="0"/>
      <inertia ixx="0" ixy="0" ixz="0" iyy="0" iyz="0" izz="0"/>
    </inertial>
  </link>
  <joint name="joint6" type="continuous">
    <origin xyz="0 0 0" rpy="0 0 0"/>
    <parent link="link5"/>
    <child link="link6"/>
    <axis xyz="0 0 1"/>
    <limit lower="1" upper="-1"/>
  </joint>
  <link name="link7">
    <inertial>
      <origin xyz="0 0 0" rpy="0 0 0"/>
      <mass value="0.2000000000000000111022302462515654042363166809082031250000000000"/>
      <inertia ixx="1" ixy="0" ixz="0" iyy="1" iyz="0" izz="1"/>
    </inertial>
    <visual>
      <origin xyz="0 0 0" rpy="0 0 0"/>
      <geometry>
        <mesh filename="meshes/visual/mesh1.obj"/>
      </geometry>
    </visual>
    <collision>
      <origin xyz="0 0 0" rpy="0 0 0"/>
      <geometry>
        <mesh filename="meshes/collision/mesh1.obj"/>
      </geometry>
    </collision>
  </link>
  <joint name="joint7" type="fixed">
    <origin xyz="-0.0950640786131548287674064567909226752817630767822265625000000000 0.0064112711564677394432409940350225951988250017166137695312500000 0.0063292432875021072125054644175179419107735157012939453125000000" rpy="0 0 0"/>
    <parent link="link6"/>
    <child link="link7"/>
    <axis xyz="0 0 0"/>
    <limit lower="1" upper="-1"/>
  </joint>
  <link name="link8">
    <inertial>
      <origin xyz="0 0 0" rpy="0 0 0"/>
      <mass value="0"/>
      <inertia ixx="0" ixy="0" ixz="0" iyy="0" iyz="0" izz="0"/>
    </inertial>
  </link>
  <joint name="joint8" type="revolute">
    <origin xyz="0.0881672335476166024736954796026111580431461334228515625000000000 -0.0049731270812174953321882497903061448596417903900146484375000000 0.0201858718492928662646690440851671155542135238647460937500000000" rpy="0 0 0"/>
    <parent link="link7"/>
    <child link="link8"/>
    <axis xyz="1 0 0"/>
    <limit lower="-3.1415926535897931159979634685441851615905761718750000000000000000" upper="3.1415926535897931159979634685441851615905761718750000000000000000"/>
  </joint>
  <link name="link9">
    <inertial>
      <origin xyz="0 0 0" rpy="0 0 0"/>
      <mass value="0"/>
      <inertia ixx="0" ixy="0" ixz="0" iyy="0" iyz="0" izz="0"/>
    </inertial>
  </link>
  <joint name="joint9" type="revolute">
    <origin xyz="0 0 0" rpy="0 0 0"/>
    <parent link="link8"/>
    <child link="link9"/>
    <axis xyz="0 1 0"/>
    <limit lower="-1.5707963267948965579989817342720925807952880859375000000000000000" upper="1.5707963267948965579989817342720925807952880859375000000000000000"/>
  </joint>
  <link name="link10">
    <inertial>
      <origin xyz="0 0 0" rpy="0 0 0"/>
      <mass value="0.0200000000000000004163336342344337026588618755340576171875000000"/>
      <inertia ixx="1" ixy="0" ixz="0" iyy="1" iyz="0" izz="1"/>
    </inertial>
    <visual>
      <origin xyz="0 0 0" rpy="0 0 0"/>
      <geometry>
        <mesh filename="meshes/visual/mesh2.obj"/>
      </geometry>
    </visual>
    <collision>
      <origin xyz="0 0 0" rpy="0 0 0"/>
      <geometry>
        <mesh filename="meshes/collision/mesh2.obj"/>
      </geometry>
    </collision>
  </link>
  <joint name="joint10" type="revolute">
    <origin xyz="0 0 0" rpy="0 0 0"/>
    <parent link="link9"/>
    <child link="link10"/>
    <axis xyz="0 0 1"/>
    <limit lower="-3.1415926535897931159979634685441851615905761718750000000000000000" upper="3.1415926535897931159979634685441851615905761718750000000000000000"/>
  </joint>
  <link name="link11">
    <inertial>
      <origin xyz="0 0 0" rpy="0 0 0"/>
      <mass value="0"/>
      <inertia ixx="0" ixy="0" ixz="0" iyy="0" iyz="0" izz="0"/>
    </inertial>
  </link>
  <joint name="joint11" type="revolute">
    <origin xyz="0.0318679209729850337895484813088842201977968215942382812500000000 0.0043851113043909401012498960881202947348356246948242187500000000 0.0021677742286801450488642473146683187223970890045166015625000000" rpy="0 0 0"/>
    <parent link="link10"/>
    <child link="link11"/>
    <axis xyz="1 0 0"/>
    <limit lower="-3.1415926535897931159979634685441851615905761718750000000000000000" upper="3.1415926535897931159979634685441851615905761718750000000000000000"/>
  </joint>
  <link name="link12">
    <inertial>
      <origin xyz="0 0 0" rpy="0 0 0"/>
      <mass value="0"/>
      <inertia ixx="0" ixy="0" ixz="0" iyy="0" iyz="0" izz="0"/>
    </inertial>
  </link>
  <joint name="joint12" type="revolute">
    <origin xyz="0 0 0" rpy="0 0 0"/>
    <parent link="link11"/>
    <child link="link12"/>
    <axis xyz="0 1 0"/>
    <limit lower="-1.5707963267948965579989817342720925807952880859375000000000000000" upper="1.5707963267948965579989817342720925807952880859375000000000000000"/>
  </joint>
  <link name="link13">
    <inertial>
      <origin xyz="0 0 0" rpy="0 0 0"/>
      <mass value="0.0200000000000000004163336342344337026588618755340576171875000000"/>
      <inertia ixx="1" ixy="0" ixz="0" iyy="1" iyz="0" izz="1"/>
    </inertial>
    <visual>
      <origin xyz="0 0 0" rpy="0 0 0"/>
      <geometry>
        <mesh filename="meshes/visual/mesh3.obj"/>
      </geometry>
    </visual>
    <collision>
      <origin xyz="0 0 0" rpy="0 0 0"/>
      <geometry>
        <mesh filename="meshes/collision/mesh3.obj"/>
      </geometry>
    </collision>
  </link>
  <joint name="joint13" type="revolute">
    <origin xyz="0 0 0" rpy="0 0 0"/>
    <parent link="link12"/>
    <child link="link13"/>
    <axis xyz="0 0 1"/>
    <limit lower="-3.1415926535897931159979634685441851615905761718750000000000000000" upper="3.1415926535897931159979634685441851615905761718750000000000000000"/>
  </joint>
  <link name="link14">
    <inertial>
      <origin xyz="0 0 0" rpy="0 0 0"/>
      <mass value="0"/>
      <inertia ixx="0" ixy="0" ixz="0" iyy="0" iyz="0" izz="0"/>
    </inertial>
  </link>
  <joint name="joint14" type="revolute">
    <origin xyz="0.0215674990294674774615746315475917072035372257232666015625000000 -0.0013717007038060889320685298287116893334314227104187011718750000 -0.0003682712171729947414622330370548297651112079620361328125000000" rpy="0 0 0"/>
    <parent link="link13"/>
    <child link="link14"/>
    <axis xyz="1 0 0"/>
    <limit lower="-3.1415926535897931159979634685441851615905761718750000000000000000" upper="3.1415926535897931159979634685441851615905761718750000000000000000"/>
  </joint>
  <link name="link15">
    <inertial>
      <origin xyz="0 0 0" rpy="0 0 0"/>
      <mass value="0"/>
      <inertia ixx="0" ixy="0" ixz="0" iyy="0" iyz="0" izz="0"/>
    </inertial>
  </link>
  <joint name="joint15" type="revolute">
    <origin xyz="0 0 0" rpy="0 0 0"/>
    <parent link="link14"/>
    <child link="link15"/>
    <axis xyz="0 1 0"/>
    <limit lower="-1.5707963267948965579989817342720925807952880859375000000000000000" upper="1.5707963267948965579989817342720925807952880859375000000000000000"/>
  </joint>
  <link name="link16">
    <inertial>
      <origin xyz="0 0 0" rpy="0 0 0"/>
      <mass value="0.0200000000000000004163336342344337026588618755340576171875000000"/>
      <inertia ixx="1" ixy="0" ixz="0" iyy="1" iyz="0" izz="1"/>
    </inertial>
    <visual>
      <origin xyz="0 0 0" rpy="0 0 0"/>
      <geometry>
        <mesh filename="meshes/visual/mesh4.obj"/>
      </geometry>
    </visual>
    <collision>
      <origin xyz="0 0 0" rpy="0 0 0"/>
      <geometry>
        <mesh filename="meshes/collision/mesh4.obj"/>
      </geometry>
    </collision>
  </link>
  <joint name="joint16" type="revolute">
    <origin xyz="0 0 0" rpy="0 0 0"/>
    <parent link="link15"/>
    <child link="link16"/>
    <axis xyz="0 0 1"/>
    <limit lower="-3.1415926535897931159979634685441851615905761718750000000000000000" upper="3.1415926535897931159979634685441851615905761718750000000000000000"/>
  </joint>
  <link name="link17">
    <inertial>
      <origin xyz="0 0 0" rpy="0 0 0"/>
      <mass value="0"/>
      <inertia ixx="0" ixy="0" ixz="0" iyy="0" iyz="0" izz="0"/>
    </inertial>
  </link>
  <joint name="joint17" type="revolute">
    <origin xyz="0.0950076822399776171890195541891444008797407150268554687500000000 -0.0017274084841173249424417512898344284621998667716979980468750000 -0.0031491194790783825704916232268715248210355639457702636718750000" rpy="0 0 0"/>
    <parent link="link7"/>
    <child link="link17"/>
    <axis xyz="1 0 0"/>
    <limit lower="-3.1415926535897931159979634685441851615905761718750000000000000000" upper="3.1415926535897931159979634685441851615905761718750000000000000000"/>
  </joint>
  <link name="link18">
    <inertial>
      <origin xyz="0 0 0" rpy="0 0 0"/>
      <mass value="0"/>
      <inertia ixx="0" ixy="0" ixz="0" iyy="0" iyz="0" izz="0"/>
    </inertial>
  </link>
  <joint name="joint18" type="revolute">
    <origin xyz="0 0 0" rpy="0 0 0"/>
    <parent link="link17"/>
    <child link="link18"/>
    <axis xyz="0 1 0"/>
    <limit lower="-1.5707963267948965579989817342720925807952880859375000000000000000" upper="1.5707963267948965579989817342720925807952880859375000000000000000"/>
  </joint>
  <link name="link19">
    <inertial>
      <origin xyz="0 0 0" rpy="0 0 0"/>
      <mass value="0.0200000000000000004163336342344337026588618755340576171875000000"/>
      <inertia ixx="1" ixy="0" ixz="0" iyy="1" iyz="0" izz="1"/>
    </inertial>
    <visual>
      <origin xyz="0 0 0" rpy="0 0 0"/>
      <geometry>
        <mesh filename="meshes/visual/mesh5.obj"/>
      </geometry>
    </visual>
    <collision>
      <origin xyz="0 0 0" rpy="0 0 0"/>
      <geometry>
        <mesh filename="meshes/collision/mesh5.obj"/>
      </geometry>
    </collision>
  </link>
  <joint name="joint19" type="revolute">
    <origin xyz="0 0 0" rpy="0 0 0"/>
    <parent link="link18"/>
    <child link="link19"/>
    <axis xyz="0 0 1"/>
    <limit lower="-3.1415926535897931159979634685441851615905761718750000000000000000" upper="3.1415926535897931159979634685441851615905761718750000000000000000"/>
  </joint>
  <link name="link20">
    <inertial>
      <origin xyz="0 0 0" rpy="0 0 0"/>
      <mass value="0"/>
      <inertia ixx="0" ixy="0" ixz="0" iyy="0" iyz="0" izz="0"/>
    </inertial>
  </link>
  <joint name="joint20" type="revolute">
    <origin xyz="0.0305227124847545841501705865539406659081578254699707031250000000 0.0016668700514936444015412497776651434833183884620666503906250000 -0.0059820449777177233524616539739326981361955404281616210937500000" rpy="0 0 0"/>
    <parent link="link19"/>
    <child link="link20"/>
    <axis xyz="1 0 0"/>
    <limit lower="-3.1415926535897931159979634685441851615905761718750000000000000000" upper="3.1415926535897931159979634685441851615905761718750000000000000000"/>
  </joint>
  <link name="link21">
    <inertial>
      <origin xyz="0 0 0" rpy="0 0 0"/>
      <mass value="0"/>
      <inertia ixx="0" ixy="0" ixz="0" iyy="0" iyz="0" izz="0"/>
    </inertial>
  </link>
  <joint name="joint21" type="revolute">
    <origin xyz="0 0 0" rpy="0 0 0"/>
    <parent link="link20"/>
    <child link="link21"/>
    <axis xyz="0 1 0"/>
    <limit lower="-1.5707963267948965579989817342720925807952880859375000000000000000" upper="1.5707963267948965579989817342720925807952880859375000000000000000"/>
  </joint>
  <link name="link22">
    <inertial>
      <origin xyz="0 0 0" rpy="0 0 0"/>
      <mass value="0.0200000000000000004163336342344337026588618755340576171875000000"/>
      <inertia ixx="1" ixy="0" ixz="0" iyy="1" iyz="0" izz="1"/>
    </inertial>
    <visual>
      <origin xyz="0 0 0" rpy="0 0 0"/>
      <geometry>
        <mesh filename="meshes/visual/mesh6.obj"/>
      </geometry>
    </visual>
    <collision>
      <origin xyz="0 0 0" rpy="0 0 0"/>
      <geometry>
        <mesh filename="meshes/collision/mesh6.obj"/>
      </geometry>
    </collision>
  </link>
  <joint name="joint22" type="revolute">
    <origin xyz="0 0 0" rpy="0 0 0"/>
    <parent link="link21"/>
    <child link="link22"/>
    <axis xyz="0 0 1"/>
    <limit lower="-3.1415926535897931159979634685441851615905761718750000000000000000" upper="3.1415926535897931159979634685441851615905761718750000000000000000"/>
  </joint>
  <link name="link23">
    <inertial>
      <origin xyz="0 0 0" rpy="0 0 0"/>
      <mass value="0"/>
      <inertia ixx="0" ixy="0" ixz="0" iyy="0" iyz="0" izz="0"/>
    </inertial>
  </link>
  <joint name="joint23" type="revolute">
    <origin xyz="0.0223994328470045120371700875239184824749827384948730468750000000 -0.0012405562594466077244725887851473089540377259254455566406250000 -0.0041767143686214898770647785397613915847614407539367675781250000" rpy="0 0 0"/>
    <parent link="link22"/>
    <child link="link23"/>
    <axis xyz="1 0 0"/>
    <limit lower="-3.1415926535897931159979634685441851615905761718750000000000000000" upper="3.1415926535897931159979634685441851615905761718750000000000000000"/>
  </joint>
  <link name="link24">
    <inertial>
      <origin xyz="0 0 0" rpy="0 0 0"/>
      <mass value="0"/>
      <inertia ixx="0" ixy="0" ixz="0" iyy="0" iyz="0" izz="0"/>
    </inertial>
  </link>
  <joint name="joint24" type="revolute">
    <origin xyz="0 0 0" rpy="0 0 0"/>
    <parent link="link23"/>
    <child link="link24"/>
    <axis xyz="0 1 0"/>
    <limit lower="-1.5707963267948965579989817342720925807952880859375000000000000000" upper="1.5707963267948965579989817342720925807952880859375000000000000000"/>
  </joint>
  <link name="link25">
    <inertial>
      <origin xyz="0 0 0" rpy="0 0 0"/>
      <mass value="0.0200000000000000004163336342344337026588618755340576171875000000"/>
      <inertia ixx="1" ixy="0" ixz="0" iyy="1" iyz="0" izz="1"/>
    </inertial>
    <visual>
      <origin xyz="0 0 0" rpy="0 0 0"/>
      <geometry>
        <mesh filename="meshes/visual/mesh7.obj"/>
      </geometry>
    </visual>
    <collision>
      <origin xyz="0 0 0" rpy="0 0 0"/>
      <geometry>
        <mesh filename="meshes/collision/mesh7.obj"/>
      </geometry>
    </collision>
  </link>
  <joint name="joint25" type="revolute">
    <origin xyz="0 0 0" rpy="0 0 0"/>
    <parent link="link24"/>
    <child link="link25"/>
    <axis xyz="0 0 1"/>
    <limit lower="-3.1415926535897931159979634685441851615905761718750000000000000000" upper="3.1415926535897931159979634685441851615905761718750000000000000000"/>
  </joint>
  <link name="link26">
    <inertial>
      <origin xyz="0 0 0" rpy="0 0 0"/>
      <mass value="0"/>
      <inertia ixx="0" ixy="0" ixz="0" iyy="0" iyz="0" izz="0"/>
    </inertial>
  </link>
  <joint name="joint26" type="revolute">
    <origin xyz="0.0688733214248248015731945770312449894845485687255859375000000000 -0.0097525653314289636325318255671845690812915563583374023437500000 -0.0413482121351073095283368274976965039968490600585937500000000000" rpy="0 0 0"/>
    <parent link="link7"/>
    <child link="link26"/>
    <axis xyz="1 0 0"/>
    <limit lower="-3.1415926535897931159979634685441851615905761718750000000000000000" upper="3.1415926535897931159979634685441851615905761718750000000000000000"/>
  </joint>
  <link name="link27">
    <inertial>
      <origin xyz="0 0 0" rpy="0 0 0"/>
      <mass value="0"/>
      <inertia ixx="0" ixy="0" ixz="0" iyy="0" iyz="0" izz="0"/>
    </inertial>
  </link>
  <joint name="joint27" type="revolute">
    <origin xyz="0 0 0" rpy="0 0 0"/>
    <parent link="link26"/>
    <child link="link27"/>
    <axis xyz="0 1 0"/>
    <limit lower="-1.5707963267948965579989817342720925807952880859375000000000000000" upper="1.5707963267948965579989817342720925807952880859375000000000000000"/>
  </joint>
  <link name="link28">
    <inertial>
      <origin xyz="0 0 0" rpy="0 0 0"/>
      <mass value="0.0200000000000000004163336342344337026588618755340576171875000000"/>
      <inertia ixx="1" ixy="0" ixz="0" iyy="1" iyz="0" izz="1"/>
    </inertial>
    <visual>
      <origin xyz="0 0 0" rpy="0 0 0"/>
      <geometry>
        <mesh filename="meshes/visual/mesh8.obj"/>
      </geometry>
    </visual>
    <collision>
      <origin xyz="0 0 0" rpy="0 0 0"/>
      <geometry>
        <mesh filename="meshes/collision/mesh8.obj"/>
      </geometry>
    </collision>
  </link>
  <joint name="joint28" type="revolute">
    <origin xyz="0 0 0" rpy="0 0 0"/>
    <parent link="link27"/>
    <child link="link28"/>
    <axis xyz="0 0 1"/>
    <limit lower="-3.1415926535897931159979634685441851615905761718750000000000000000" upper="3.1415926535897931159979634685441851615905761718750000000000000000"/>
  </joint>
  <link name="link29">
    <inertial>
      <origin xyz="0 0 0" rpy="0 0 0"/>
      <mass value="0"/>
      <inertia ixx="0" ixy="0" ixz="0" iyy="0" iyz="0" izz="0"/>
    </inertial>
  </link>
  <joint name="joint29" type="revolute">
    <origin xyz="0.0173171239494146061987933649106707889586687088012695312500000000 0.0004177803793820288047466959824305376969277858734130859375000000 -0.0129362815346500750757208209051896119490265846252441406250000000" rpy="0 0 0"/>
    <parent link="link28"/>
    <child link="link29"/>
    <axis xyz="1 0 0"/>
    <limit lower="-3.1415926535897931159979634685441851615905761718750000000000000000" upper="3.1415926535897931159979634685441851615905761718750000000000000000"/>
  </joint>
  <link name="link30">
    <inertial>
      <origin xyz="0 0 0" rpy="0 0 0"/>
      <mass value="0"/>
      <inertia ixx="0" ixy="0" ixz="0" iyy="0" iyz="0" izz="0"/>
    </inertial>
  </link>
  <joint name="joint30" type="revolute">
    <origin xyz="0 0 0" rpy="0 0 0"/>
    <parent link="link29"/>
    <child link="link30"/>
    <axis xyz="0 1 0"/>
    <limit lower="-1.5707963267948965579989817342720925807952880859375000000000000000" upper="1.5707963267948965579989817342720925807952880859375000000000000000"/>
  </joint>
  <link name="link31">
    <inertial>
      <origin xyz="0 0 0" rpy="0 0 0"/>
      <mass value="0.0200000000000000004163336342344337026588618755340576171875000000"/>
      <inertia ixx="1" ixy="0" ixz="0" iyy="1" iyz="0" izz="1"/>
    </inertial>
    <visual>
      <origin xyz="0 0 0" rpy="0 0 0"/>
      <geometry>
        <mesh filename="meshes/visual/mesh9.obj"/>
      </geometry>
    </visual>
    <collision>
      <origin xyz="0 0 0" rpy="0 0 0"/>
      <geometry>
        <mesh filename="meshes/collision/mesh9.obj"/>
      </geometry>
    </collision>
  </link>
  <joint name="joint31" type="revolute">
    <origin xyz="0 0 0" rpy="0 0 0"/>
    <parent link="link30"/>
    <child link="link31"/>
    <axis xyz="0 0 1"/>
    <limit lower="-3.1415926535897931159979634685441851615905761718750000000000000000" upper="3.1415926535897931159979634685441851615905761718750000000000000000"/>
  </joint>
  <link name="link32">
    <inertial>
      <origin xyz="0 0 0" rpy="0 0 0"/>
      <mass value="0"/>
      <inertia ixx="0" ixy="0" ixz="0" iyy="0" iyz="0" izz="0"/>
    </inertial>
  </link>
  <joint name="joint32" type="revolute">
    <origin xyz="0.0158900012608923814350081471502562635578215122222900390625000000 -0.0009505369974889487337532667510231476626358926296234130859375000 -0.0109499400564878335284646482250536791980266571044921875000000000" rpy="0 0 0"/>
    <parent link="link31"/>
    <child link="link32"/>
    <axis xyz="1 0 0"/>
    <limit lower="-3.1415926535897931159979634685441851615905761718750000000000000000" upper="3.1415926535897931159979634685441851615905761718750000000000000000"/>
  </joint>
  <link name="link33">
    <inertial>
      <origin xyz="0 0 0" rpy="0 0 0"/>
      <mass value="0"/>
      <inertia ixx="0" ixy="0" ixz="0" iyy="0" iyz="0" izz="0"/>
    </inertial>
  </link>
  <joint name="joint33" type="revolute">
    <origin xyz="0 0 0" rpy="0 0 0"/>
    <parent link="link32"/>
    <child link="link33"/>
    <axis xyz="0 1 0"/>
    <limit lower="-1.5707963267948965579989817342720925807952880859375000000000000000" upper="1.5707963267948965579989817342720925807952880859375000000000000000"/>
  </joint>
  <link name="link34">
    <inertial>
      <origin xyz="0 0 0" rpy="0 0 0"/>
      <mass value="0.0200000000000000004163336342344337026588618755340576171875000000"/>
      <inertia ixx="1" ixy="0" ixz="0" iyy="1" iyz="0" izz="1"/>
    </inertial>
    <visual>
      <origin xyz="0 0 0" rpy="0 0 0"/>
      <geometry>
        <mesh filename="meshes/visual/mesh10.obj"/>
      </geometry>
    </visual>
    <collision>
      <origin xyz="0 0 0" rpy="0 0 0"/>
      <geometry>
        <mesh filename="meshes/collision/mesh10.obj"/>
      </geometry>
    </collision>
  </link>
  <joint name="joint34" type="revolute">
    <origin xyz="0 0 0" rpy="0 0 0"/>
    <parent link="link33"/>
    <child link="link34"/>
    <axis xyz="0 0 1"/>
    <limit lower="-3.1415926535897931159979634685441851615905761718750000000000000000" upper="3.1415926535897931159979634685441851615905761718750000000000000000"/>
  </joint>
  <link name="link35">
    <inertial>
      <origin xyz="0 0 0" rpy="0 0 0"/>
      <mass value="0"/>
      <inertia ixx="0" ixy="0" ixz="0" iyy="0" iyz="0" izz="0"/>
    </inertial>
  </link>
  <joint name="joint35" type="revolute">
    <origin xyz="0.0820389527647941013688281941540481057018041610717773437500000000 -0.0041725669570076883221898533804505859734490513801574707031250000 -0.0253771148418023041737345835144878947176039218902587890625000000" rpy="0 0 0"/>
    <parent link="link7"/>
    <child link="link35"/>
    <axis xyz="1 0 0"/>
    <limit lower="-3.1415926535897931159979634685441851615905761718750000000000000000" upper="3.1415926535897931159979634685441851615905761718750000000000000000"/>
  </joint>
  <link name="link36">
    <inertial>
      <origin xyz="0 0 0" rpy="0 0 0"/>
      <mass value="0"/>
      <inertia ixx="0" ixy="0" ixz="0" iyy="0" iyz="0" izz="0"/>
    </inertial>
  </link>
  <joint name="joint36" type="revolute">
    <origin xyz="0 0 0" rpy="0 0 0"/>
    <parent link="link35"/>
    <child link="link36"/>
    <axis xyz="0 1 0"/>
    <limit lower="-1.5707963267948965579989817342720925807952880859375000000000000000" upper="1.5707963267948965579989817342720925807952880859375000000000000000"/>
  </joint>
  <link name="link37">
    <inertial>
      <origin xyz="0 0 0" rpy="0 0 0"/>
      <mass value="0.0200000000000000004163336342344337026588618755340576171875000000"/>
      <inertia ixx="1" ixy="0" ixz="0" iyy="1" iyz="0" izz="1"/>
    </inertial>
    <visual>
      <origin xyz="0 0 0" rpy="0 0 0"/>
      <geometry>
        <mesh filename="meshes/visual/mesh11.obj"/>
      </geometry>
    </visual>
    <collision>
      <origin xyz="0 0 0" rpy="0 0 0"/>
      <geometry>
        <mesh filename="meshes/collision/mesh11.obj"/>
      </geometry>
    </collision>
  </link>
  <joint name="joint37" type="revolute">
    <origin xyz="0 0 0" rpy="0 0 0"/>
    <parent link="link36"/>
    <child link="link37"/>
    <axis xyz="0 0 1"/>
    <limit lower="-3.1415926535897931159979634685441851615905761718750000000000000000" upper="3.1415926535897931159979634685441851615905761718750000000000000000"/>
  </joint>
  <link name="link38">
    <inertial>
      <origin xyz="0 0 0" rpy="0 0 0"/>
      <mass value="0"/>
      <inertia ixx="0" ixy="0" ixz="0" iyy="0" iyz="0" izz="0"/>
    </inertial>
  </link>
  <joint name="joint38" type="revolute">
    <origin xyz="0.0275568835411656651301903764306189259514212608337402343750000000 0.0018697049120749058628843108920136728556826710700988769531250000 -0.0059639750873688099352953884135786211118102073669433593750000000" rpy="0 0 0"/>
    <parent link="link37"/>
    <child link="link38"/>
    <axis xyz="1 0 0"/>
    <limit lower="-3.1415926535897931159979634685441851615905761718750000000000000000" upper="3.1415926535897931159979634685441851615905761718750000000000000000"/>
  </joint>
  <link name="link39">
    <inertial>
      <origin xyz="0 0 0" rpy="0 0 0"/>
      <mass value="0"/>
      <inertia ixx="0" ixy="0" ixz="0" iyy="0" iyz="0" izz="0"/>
    </inertial>
  </link>
  <joint name="joint39" type="revolute">
    <origin xyz="0 0 0" rpy="0 0 0"/>
    <parent link="link38"/>
    <child link="link39"/>
    <axis xyz="0 1 0"/>
    <limit lower="-1.5707963267948965579989817342720925807952880859375000000000000000" upper="1.5707963267948965579989817342720925807952880859375000000000000000"/>
  </joint>
  <link name="link40">
    <inertial>
      <origin xyz="0 0 0" rpy="0 0 0"/>
      <mass value="0.0200000000000000004163336342344337026588618755340576171875000000"/>
      <inertia ixx="1" ixy="0" ixz="0" iyy="1" iyz="0" izz="1"/>
    </inertial>
    <visual>
      <origin xyz="0 0 0" rpy="0 0 0"/>
      <geometry>
        <mesh filename="meshes/visual/mesh12.obj"/>
      </geometry>
    </visual>
    <collision>
      <origin xyz="0 0 0" rpy="0 0 0"/>
      <geometry>
        <mesh filename="meshes/collision/mesh12.obj"/>
      </geometry>
    </collision>
  </link>
  <joint name="joint40" type="revolute">
    <origin xyz="0 0 0" rpy="0 0 0"/>
    <parent link="link39"/>
    <child link="link40"/>
    <axis xyz="0 0 1"/>
    <limit lower="-3.1415926535897931159979634685441851615905761718750000000000000000" upper="3.1415926535897931159979634685441851615905761718750000000000000000"/>
  </joint>
  <link name="link41">
    <inertial>
      <origin xyz="0 0 0" rpy="0 0 0"/>
      <mass value="0"/>
      <inertia ixx="0" ixy="0" ixz="0" iyy="0" iyz="0" izz="0"/>
    </inertial>
  </link>
  <joint name="joint41" type="revolute">
    <origin xyz="0.0228151784266544810364507611666340380907058715820312500000000000 -0.0020357633709340737168669299705925368471071124076843261718750000 -0.0081061449192366269445031434770498890429735183715820312500000000" rpy="0 0 0"/>
    <parent link="link40"/>
    <child link="link41"/>
    <axis xyz="1 0 0"/>
    <limit lower="-3.1415926535897931159979634685441851615905761718750000000000000000" upper="3.1415926535897931159979634685441851615905761718750000000000000000"/>
  </joint>
  <link name="link42">
    <inertial>
      <origin xyz="0 0 0" rpy="0 0 0"/>
      <mass value="0"/>
      <inertia ixx="0" ixy="0" ixz="0" iyy="0" iyz="0" izz="0"/>
    </inertial>
  </link>
  <joint name="joint42" type="revolute">
    <origin xyz="0 0 0" rpy="0 0 0"/>
    <parent link="link41"/>
    <child link="link42"/>
    <axis xyz="0 1 0"/>
    <limit lower="-1.5707963267948965579989817342720925807952880859375000000000000000" upper="1.5707963267948965579989817342720925807952880859375000000000000000"/>
  </joint>
  <link name="link43">
    <inertial>
      <origin xyz="0 0 0" rpy="0 0 0"/>
      <mass value="0.0200000000000000004163336342344337026588618755340576171875000000"/>
      <inertia ixx="1" ixy="0" ixz="0" iyy="1" iyz="0" izz="1"/>
    </inertial>
    <visual>
      <origin xyz="0 0 0" rpy="0 0 0"/>
      <geometry>
        <mesh filename="meshes/visual/mesh13.obj"/>
      </geometry>
    </visual>
    <collision>
      <origin xyz="0 0 0" rpy="0 0 0"/>
      <geometry>
        <mesh filename="meshes/collision/mesh13.obj"/>
      </geometry>
    </collision>
  </link>
  <joint name="joint43" type="revolute">
    <origin xyz="0 0 0" rpy="0 0 0"/>
    <parent link="link42"/>
    <child link="link43"/>
    <axis xyz="0 0 1"/>
    <limit lower="-3.1415926535897931159979634685441851615905761718750000000000000000" upper="3.1415926535897931159979634685441851615905761718750000000000000000"/>
  </joint>
  <link name="link44">
    <inertial>
      <origin xyz="0 0 0" rpy="0 0 0"/>
      <mass value="0"/>
      <inertia ixx="0" ixy="0" ixz="0" iyy="0" iyz="0" izz="0"/>
    </inertial>
  </link>
  <joint name="joint44" type="revolute">
    <origin xyz="0.0233971014189950921036142972297966480255126953125000000000000000 -0.0143364938577155275750696361569680448155850172042846679687500000 0.0246636240330942967113880825991145684383809566497802734375000000" rpy="0 0 0"/>
    <parent link="link7"/>
    <child link="link44"/>
    <axis xyz="1 0 0"/>
    <limit lower="-3.1415926535897931159979634685441851615905761718750000000000000000" upper="3.1415926535897931159979634685441851615905761718750000000000000000"/>
  </joint>
  <link name="link45">
    <inertial>
      <origin xyz="0 0 0" rpy="0 0 0"/>
      <mass value="0"/>
      <inertia ixx="0" ixy="0" ixz="0" iyy="0" iyz="0" izz="0"/>
    </inertial>
  </link>
  <joint name="joint45" type="revolute">
    <origin xyz="0 0 0" rpy="0 0 0"/>
    <parent link="link44"/>
    <child link="link45"/>
    <axis xyz="0 1 0"/>
    <limit lower="-1.5707963267948965579989817342720925807952880859375000000000000000" upper="1.5707963267948965579989817342720925807952880859375000000000000000"/>
  </joint>
  <link name="link46">
    <inertial>
      <origin xyz="0 0 0" rpy="0 0 0"/>
      <mass value="0.0200000000000000004163336342344337026588618755340576171875000000"/>
      <inertia ixx="1" ixy="0" ixz="0" iyy="1" iyz="0" izz="1"/>
    </inertial>
    <visual>
      <origin xyz="0 0 0" rpy="0 0 0"/>
      <geometry>
        <mesh filename="meshes/visual/mesh14.obj"/>
      </geometry>
    </visual>
    <collision>
      <origin xyz="0 0 0" rpy="0 0 0"/>
      <geometry>
        <mesh filename="meshes/collision/mesh14.obj"/>
      </geometry>
    </collision>
  </link>
  <joint name="joint46" type="revolute">
    <origin xyz="0 0 0" rpy="0 0 0"/>
    <parent link="link45"/>
    <child link="link46"/>
    <axis xyz="0 0 1"/>
    <limit lower="-3.1415926535897931159979634685441851615905761718750000000000000000" upper="3.1415926535897931159979634685441851615905761718750000000000000000"/>
  </joint>
  <link name="link47">
    <inertial>
      <origin xyz="0 0 0" rpy="0 0 0"/>
      <mass value="0"/>
      <inertia ixx="0" ixy="0" ixz="0" iyy="0" iyz="0" izz="0"/>
    </inertial>
  </link>
  <joint name="joint47" type="revolute">
    <origin xyz="0.0188594244160669027854382306941261049360036849975585937500000000 0.0001703217351446467339726176248859701445326209068298339843750000 0.0231920430382549849768203387156972894445061683654785156250000000" rpy="0 0 0"/>
    <parent link="link46"/>
    <child link="link47"/>
    <axis xyz="1 0 0"/>
    <limit lower="-3.1415926535897931159979634685441851615905761718750000000000000000" upper="3.1415926535897931159979634685441851615905761718750000000000000000"/>
  </joint>
  <link name="link48">
    <inertial>
      <origin xyz="0 0 0" rpy="0 0 0"/>
      <mass value="0"/>
      <inertia ixx="0" ixy="0" ixz="0" iyy="0" iyz="0" izz="0"/>
    </inertial>
  </link>
  <joint name="joint48" type="revolute">
    <origin xyz="0 0 0" rpy="0 0 0"/>
    <parent link="link47"/>
    <child link="link48"/>
    <axis xyz="0 1 0"/>
    <limit lower="-1.5707963267948965579989817342720925807952880859375000000000000000" upper="1.5707963267948965579989817342720925807952880859375000000000000000"/>
  </joint>
  <link name="link49">
    <inertial>
      <origin xyz="0 0 0" rpy="0 0 0"/>
      <mass value="0.0200000000000000004163336342344337026588618755340576171875000000"/>
      <inertia ixx="1" ixy="0" ixz="0" iyy="1" iyz="0" izz="1"/>
    </inertial>
    <visual>
      <origin xyz="0 0 0" rpy="0 0 0"/>
      <geometry>
        <mesh filename="meshes/visual/mesh15.obj"/>
      </geometry>
    </visual>
    <collision>
      <origin xyz="0 0 0" rpy="0 0 0"/>
      <geometry>
        <mesh filename="meshes/collision/mesh15.obj"/>
      </geometry>
    </collision>
  </link>
  <joint name="joint49" type="revolute">
    <origin xyz="0 0 0" rpy="0 0 0"/>
    <parent link="link48"/>
    <child link="link49"/>
    <axis xyz="0 0 1"/>
    <limit lower="-3.1415926535897931159979634685441851615905761718750000000000000000" upper="3.1415926535897931159979634685441851615905761718750000000000000000"/>
  </joint>
  <link name="link50">
    <inertial>
      <origin xyz="0 0 0" rpy="0 0 0"/>
      <mass value="0"/>
      <inertia ixx="0" ixy="0" ixz="0" iyy="0" iyz="0" izz="0"/>
    </inertial>
  </link>
  <joint name="joint50" type="revolute">
    <origin xyz="0.0219480661364065965379666067747166380286216735839843750000000000 -0.0056978615655929347114105887328605604125186800956726074218750000 0.0146705340290789534862803122905461350455880165100097656250000000" rpy="0 0 0"/>
    <parent link="link49"/>
    <child link="link50"/>
    <axis xyz="1 0 0"/>
    <limit lower="-3.1415926535897931159979634685441851615905761718750000000000000000" upper="3.1415926535897931159979634685441851615905761718750000000000000000"/>
  </joint>
  <link name="link51">
    <inertial>
      <origin xyz="0 0 0" rpy="0 0 0"/>
      <mass value="0"/>
      <inertia ixx="0" ixy="0" ixz="0" iyy="0" iyz="0" izz="0"/>
    </inertial>
  </link>
  <joint name="joint51" type="revolute">
    <origin xyz="0 0 0" rpy="0 0 0"/>
    <parent link="link50"/>
    <child link="link51"/>
    <axis xyz="0 1 0"/>
    <limit lower="-1.5707963267948965579989817342720925807952880859375000000000000000" upper="1.5707963267948965579989817342720925807952880859375000000000000000"/>
  </joint>
  <link name="link52">
    <inertial>
      <origin xyz="0 0 0" rpy="0 0 0"/>
      <mass value="0.0200000000000000004163336342344337026588618755340576171875000000"/>
      <inertia ixx="1" ixy="0" ixz="0" iyy="1" iyz="0" izz="1"/>
    </inertial>
    <visual>
      <origin xyz="0 0 0" rpy="0 0 0"/>
      <geometry>
        <mesh filename="meshes/visual/mesh16.obj"/>
      </geometry>
    </visual>
    <collision>
      <origin xyz="0 0 0" rpy="0 0 0"/>
      <geometry>
        <mesh filename="meshes/collision/mesh16.obj"/>
      </geometry>
    </collision>
  </link>
  <joint name="joint52" type="revolute">
    <origin xyz="0 0 0" rpy="0 0 0"/>
    <parent link="link51"/>
    <child link="link52"/>
    <axis xyz="0 0 1"/>
    <limit lower="-3.1415926535897931159979634685441851615905761718750000000000000000" upper="3.1415926535897931159979634685441851615905761718750000000000000000"/>
  </joint>
</robot>
